2024-06-03 00:03:47,882 [INFO] app.main User None logged out
2024-06-03 00:03:47,887 [WARNING] app.main Failed login attempt for username: s
2024-06-03 00:03:49,510 [WARNING] app.main Login page has arrived
2024-06-03 00:04:01,714 [INFO] app.main User None logged out
2024-06-03 00:04:01,718 [WARNING] app.main Failed login attempt for username: m
2024-06-03 00:04:55,046 [WARNING] app.main Login page has arrived
2024-06-03 00:06:28,959 [WARNING] app.main Login page has arrived
2024-06-03 00:15:05,246 [WARNING] app.main Login page has arrived
2024-06-03 00:19:40,872 [WARNING] app.main Login page has arrived
2024-06-03 00:19:44,577 [WARNING] app.main Login page has arrived
2024-06-03 00:19:48,716 [WARNING] app.main Login page has arrived
2024-06-03 00:19:55,991 [WARNING] app.main Login page has arrived
2024-06-03 00:21:31,212 [WARNING] app.main Login page has arrived
2024-06-03 00:34:14,621 [WARNING] app.main Login page has arrived
2024-06-03 00:34:18,018 [WARNING] app.main Login page has arrived
2024-06-03 00:34:20,665 [WARNING] app.main Login page has arrived
2024-06-03 00:34:24,906 [INFO] app.main User None logged out
2024-06-03 00:34:24,914 [INFO] app.main User admin logged in for the first time
2024-06-03 00:34:26,191 [INFO] app.main Admin admin accessed admin dashboard
2024-06-03 00:34:26,192 [ERROR] app.main Exception admin_dashboard.html occurred while rendering admin_dashboard for admin
Traceback (most recent call last):
  File "C:\Users\g_and\Desktop\inventory management system\app\main.py", line 31, in admin_dashboard
    return render_template('admin_dashboard.html', items=items_list, employees=employees_list)
           ^^^^^^^^^^^^^^^^^^^^^^^^^^^^^^^^^^^^^^^^^^^^^^^^^^^^^^^^^^^^^^^^^^^^^^^^^^^^^^^^^^^
  File "C:\Users\g_and\AppData\Local\Programs\Python\Python311\Lib\site-packages\flask\templating.py", line 151, in render_template
    template = app.jinja_env.get_or_select_template(template_name_or_list)
               ^^^^^^^^^^^^^^^^^^^^^^^^^^^^^^^^^^^^^^^^^^^^^^^^^^^^^^^^^^^
  File "C:\Users\g_and\AppData\Local\Programs\Python\Python311\Lib\site-packages\jinja2\environment.py", line 1081, in get_or_select_template
    return self.get_template(template_name_or_list, parent, globals)
           ^^^^^^^^^^^^^^^^^^^^^^^^^^^^^^^^^^^^^^^^^^^^^^^^^^^^^^^^^
  File "C:\Users\g_and\AppData\Local\Programs\Python\Python311\Lib\site-packages\jinja2\environment.py", line 1010, in get_template
    return self._load_template(name, globals)
           ^^^^^^^^^^^^^^^^^^^^^^^^^^^^^^^^^^
  File "C:\Users\g_and\AppData\Local\Programs\Python\Python311\Lib\site-packages\jinja2\environment.py", line 969, in _load_template
    template = self.loader.load(self, name, self.make_globals(globals))
               ^^^^^^^^^^^^^^^^^^^^^^^^^^^^^^^^^^^^^^^^^^^^^^^^^^^^^^^^
  File "C:\Users\g_and\AppData\Local\Programs\Python\Python311\Lib\site-packages\jinja2\loaders.py", line 126, in load
    source, filename, uptodate = self.get_source(environment, name)
                                 ^^^^^^^^^^^^^^^^^^^^^^^^^^^^^^^^^^
  File "C:\Users\g_and\AppData\Local\Programs\Python\Python311\Lib\site-packages\flask\templating.py", line 65, in get_source
    return self._get_source_fast(environment, template)
           ^^^^^^^^^^^^^^^^^^^^^^^^^^^^^^^^^^^^^^^^^^^^
  File "C:\Users\g_and\AppData\Local\Programs\Python\Python311\Lib\site-packages\flask\templating.py", line 99, in _get_source_fast
    raise TemplateNotFound(template)
jinja2.exceptions.TemplateNotFound: admin_dashboard.html
2024-06-03 00:35:29,837 [WARNING] app.main Attempt to add user with invalid email: None
2024-06-03 00:38:08,890 [WARNING] app.main Attempt to add user with invalid email: None
2024-06-03 00:39:35,611 [WARNING] app.main Attempt to add user with invalid email: None
2024-06-03 00:42:38,139 [INFO] app.main User hello added by admin admin
2024-06-03 00:42:38,140 [ERROR] app.main Exception admin_dashboard.html occurred while adding user hello
Traceback (most recent call last):
  File "C:\Users\g_and\Desktop\inventory management system\app\main.py", line 126, in add_user
    return render_template("admin_dashboard.html", message="User added successfully!"), 200
           ^^^^^^^^^^^^^^^^^^^^^^^^^^^^^^^^^^^^^^^^^^^^^^^^^^^^^^^^^^^^^^^^^^^^^^^^^^^
  File "C:\Users\g_and\AppData\Local\Programs\Python\Python311\Lib\site-packages\flask\templating.py", line 151, in render_template
    template = app.jinja_env.get_or_select_template(template_name_or_list)
               ^^^^^^^^^^^^^^^^^^^^^^^^^^^^^^^^^^^^^^^^^^^^^^^^^^^^^^^^^^^
  File "C:\Users\g_and\AppData\Local\Programs\Python\Python311\Lib\site-packages\jinja2\environment.py", line 1081, in get_or_select_template
    return self.get_template(template_name_or_list, parent, globals)
           ^^^^^^^^^^^^^^^^^^^^^^^^^^^^^^^^^^^^^^^^^^^^^^^^^^^^^^^^^
  File "C:\Users\g_and\AppData\Local\Programs\Python\Python311\Lib\site-packages\jinja2\environment.py", line 1010, in get_template
    return self._load_template(name, globals)
           ^^^^^^^^^^^^^^^^^^^^^^^^^^^^^^^^^^
  File "C:\Users\g_and\AppData\Local\Programs\Python\Python311\Lib\site-packages\jinja2\environment.py", line 969, in _load_template
    template = self.loader.load(self, name, self.make_globals(globals))
               ^^^^^^^^^^^^^^^^^^^^^^^^^^^^^^^^^^^^^^^^^^^^^^^^^^^^^^^^
  File "C:\Users\g_and\AppData\Local\Programs\Python\Python311\Lib\site-packages\jinja2\loaders.py", line 126, in load
    source, filename, uptodate = self.get_source(environment, name)
                                 ^^^^^^^^^^^^^^^^^^^^^^^^^^^^^^^^^^
  File "C:\Users\g_and\AppData\Local\Programs\Python\Python311\Lib\site-packages\flask\templating.py", line 65, in get_source
    return self._get_source_fast(environment, template)
           ^^^^^^^^^^^^^^^^^^^^^^^^^^^^^^^^^^^^^^^^^^^^
  File "C:\Users\g_and\AppData\Local\Programs\Python\Python311\Lib\site-packages\flask\templating.py", line 99, in _get_source_fast
    raise TemplateNotFound(template)
jinja2.exceptions.TemplateNotFound: admin_dashboard.html
2024-06-03 00:48:21,789 [WARNING] app.main Login page has arrived
2024-06-03 00:48:38,412 [INFO] app.main User hi added by admin admin
2024-06-03 00:48:38,413 [ERROR] app.main Exception admin_dashboard.html occurred while adding user hi
Traceback (most recent call last):
  File "C:\Users\g_and\Desktop\inventory management system\app\main.py", line 126, in add_user
    return render_template("admin_dashboard.html", message="User added successfully!"), 200
       ^^^^^^^^^^^^^^^^^^^^^^^^^^^^^^^^^^^^^^^^^^^^^^^^^^^^^^^^^^^^^^^^^^^^^^^^^^^
  File "C:\Users\g_and\AppData\Local\Programs\Python\Python311\Lib\site-packages\flask\templating.py", line 151, in render_template
    template = app.jinja_env.get_or_select_template(template_name_or_list)
               ^^^^^^^^^^^^^^^^^^^^^^^^^^^^^^^^^^^^^^^^^^^^^^^^^^^^^^^^^^^
  File "C:\Users\g_and\AppData\Local\Programs\Python\Python311\Lib\site-packages\jinja2\environment.py", line 1081, in get_or_select_template
    return self.get_template(template_name_or_list, parent, globals)
           ^^^^^^^^^^^^^^^^^^^^^^^^^^^^^^^^^^^^^^^^^^^^^^^^^^^^^^^^^
  File "C:\Users\g_and\AppData\Local\Programs\Python\Python311\Lib\site-packages\jinja2\environment.py", line 1010, in get_template
    return self._load_template(name, globals)
           ^^^^^^^^^^^^^^^^^^^^^^^^^^^^^^^^^^
  File "C:\Users\g_and\AppData\Local\Programs\Python\Python311\Lib\site-packages\jinja2\environment.py", line 969, in _load_template
    template = self.loader.load(self, name, self.make_globals(globals))
               ^^^^^^^^^^^^^^^^^^^^^^^^^^^^^^^^^^^^^^^^^^^^^^^^^^^^^^^^
  File "C:\Users\g_and\AppData\Local\Programs\Python\Python311\Lib\site-packages\jinja2\loaders.py", line 126, in load
    source, filename, uptodate = self.get_source(environment, name)
                                 ^^^^^^^^^^^^^^^^^^^^^^^^^^^^^^^^^^
  File "C:\Users\g_and\AppData\Local\Programs\Python\Python311\Lib\site-packages\flask\templating.py", line 65, in get_source
    return self._get_source_fast(environment, template)
           ^^^^^^^^^^^^^^^^^^^^^^^^^^^^^^^^^^^^^^^^^^^^
  File "C:\Users\g_and\AppData\Local\Programs\Python\Python311\Lib\site-packages\flask\templating.py", line 99, in _get_source_fast
    raise TemplateNotFound(template)
jinja2.exceptions.TemplateNotFound: admin_dashboard.html
2024-06-03 00:49:22,139 [WARNING] app.main Login page has arrived
2024-06-03 00:49:27,780 [INFO] app.main User None logged out
2024-06-03 00:49:27,783 [WARNING] app.main Failed login attempt for username: d
2024-06-03 00:49:50,507 [WARNING] app.main Attempt to add user with invalid email: hh@nucleuseq.com
2024-06-03 00:49:59,465 [INFO] app.main User hh added by None
2024-06-03 00:49:59,465 [WARNING] app.main Login page has arrived
2024-06-03 00:54:35,799 [WARNING] app.main Login page has arrived
2024-06-03 00:54:37,317 [WARNING] app.main Login page has arrived
2024-06-03 00:54:52,520 [INFO] app.main User new added by None
2024-06-03 00:54:52,533 [WARNING] app.main Login page has arrived
2024-06-03 00:54:55,221 [ERROR] app.main Exception (MySQLdb.IntegrityError) (1062, "Duplicate entry 'new' for key 'user.PRIMARY'")
[SQL: INSERT INTO user (username, password, email, is_admin, first_login) VALUES (%s, %s, %s, %s, %s)]
[parameters: ('new', 'mew', 'new@nucleusteq.com', False, True)]
(Background on this error at: https://sqlalche.me/e/20/gkpj) occurred while adding user new
Traceback (most recent call last):
  File "C:\Users\g_and\AppData\Local\Programs\Python\Python311\Lib\site-packages\sqlalchemy\engine\base.py", line 1971, in _exec_single_context
    self.dialect.do_execute(
  File "C:\Users\g_and\AppData\Local\Programs\Python\Python311\Lib\site-packages\sqlalchemy\engine\default.py", line 919, in do_execute
    cursor.execute(statement, parameters)
  File "C:\Users\g_and\AppData\Local\Programs\Python\Python311\Lib\site-packages\MySQLdb\cursors.py", line 179, in execute
    res = self._query(mogrified_query)
          ^^^^^^^^^^^^^^^^^^^^^^^^^^^^
  File "C:\Users\g_and\AppData\Local\Programs\Python\Python311\Lib\site-packages\MySQLdb\cursors.py", line 330, in _query
    db.query(q)
  File "C:\Users\g_and\AppData\Local\Programs\Python\Python311\Lib\site-packages\MySQLdb\connections.py", line 257, in query
    _mysql.connection.query(self, query)
MySQLdb.IntegrityError: (1062, "Duplicate entry 'new' for key 'user.PRIMARY'")

The above exception was the direct cause of the following exception:

Traceback (most recent call last):
  File "C:\Users\g_and\Desktop\inventory management system\app\main.py", line 123, in add_user
    db.session.commit()
  File "C:\Users\g_and\AppData\Local\Programs\Python\Python311\Lib\site-packages\sqlalchemy\orm\scoping.py", line 597, in commit
    return self._proxied.commit()
           ^^^^^^^^^^^^^^^^^^^^^^
  File "C:\Users\g_and\AppData\Local\Programs\Python\Python311\Lib\site-packages\sqlalchemy\orm\session.py", line 1972, in commit
    trans.commit(_to_root=True)
  File "<string>", line 2, in commit
  File "C:\Users\g_and\AppData\Local\Programs\Python\Python311\Lib\site-packages\sqlalchemy\orm\state_changes.py", line 139, in _go
    ret_value = fn(self, *arg, **kw)
                ^^^^^^^^^^^^^^^^^^^^
  File "C:\Users\g_and\AppData\Local\Programs\Python\Python311\Lib\site-packages\sqlalchemy\orm\session.py", line 1257, in commit
    self._prepare_impl()
  File "<string>", line 2, in _prepare_impl
  File "C:\Users\g_and\AppData\Local\Programs\Python\Python311\Lib\site-packages\sqlalchemy\orm\state_changes.py", line 139, in _go
    ret_value = fn(self, *arg, **kw)
                ^^^^^^^^^^^^^^^^^^^^
  File "C:\Users\g_and\AppData\Local\Programs\Python\Python311\Lib\site-packages\sqlalchemy\orm\session.py", line 1232, in _prepare_impl
    self.session.flush()
  File "C:\Users\g_and\AppData\Local\Programs\Python\Python311\Lib\site-packages\sqlalchemy\orm\session.py", line 4296, in flush
    self._flush(objects)
  File "C:\Users\g_and\AppData\Local\Programs\Python\Python311\Lib\site-packages\sqlalchemy\orm\session.py", line 4431, in _flush
    with util.safe_reraise():
  File "C:\Users\g_and\AppData\Local\Programs\Python\Python311\Lib\site-packages\sqlalchemy\util\langhelpers.py", line 146, in __exit__
    raise exc_value.with_traceback(exc_tb)
  File "C:\Users\g_and\AppData\Local\Programs\Python\Python311\Lib\site-packages\sqlalchemy\orm\session.py", line 4392, in _flush
    flush_context.execute()
  File "C:\Users\g_and\AppData\Local\Programs\Python\Python311\Lib\site-packages\sqlalchemy\orm\unitofwork.py", line 466, in execute
    rec.execute(self)
  File "C:\Users\g_and\AppData\Local\Programs\Python\Python311\Lib\site-packages\sqlalchemy\orm\unitofwork.py", line 642, in execute
    util.preloaded.orm_persistence.save_obj(
  File "C:\Users\g_and\AppData\Local\Programs\Python\Python311\Lib\site-packages\sqlalchemy\orm\persistence.py", line 93, in save_obj
    _emit_insert_statements(
  File "C:\Users\g_and\AppData\Local\Programs\Python\Python311\Lib\site-packages\sqlalchemy\orm\persistence.py", line 1048, in _emit_insert_statements
    result = connection.execute(
             ^^^^^^^^^^^^^^^^^^^
  File "C:\Users\g_and\AppData\Local\Programs\Python\Python311\Lib\site-packages\sqlalchemy\engine\base.py", line 1422, in execute
    return meth(
           ^^^^^
  File "C:\Users\g_and\AppData\Local\Programs\Python\Python311\Lib\site-packages\sqlalchemy\sql\elements.py", line 514, in _execute_on_connection
    return connection._execute_clauseelement(
           ^^^^^^^^^^^^^^^^^^^^^^^^^^^^^^^^^^
  File "C:\Users\g_and\AppData\Local\Programs\Python\Python311\Lib\site-packages\sqlalchemy\engine\base.py", line 1644, in _execute_clauseelement
    ret = self._execute_context(
          ^^^^^^^^^^^^^^^^^^^^^^
  File "C:\Users\g_and\AppData\Local\Programs\Python\Python311\Lib\site-packages\sqlalchemy\engine\base.py", line 1850, in _execute_context
    return self._exec_single_context(
           ^^^^^^^^^^^^^^^^^^^^^^^^^^
  File "C:\Users\g_and\AppData\Local\Programs\Python\Python311\Lib\site-packages\sqlalchemy\engine\base.py", line 1990, in _exec_single_context
    self._handle_dbapi_exception(
  File "C:\Users\g_and\AppData\Local\Programs\Python\Python311\Lib\site-packages\sqlalchemy\engine\base.py", line 2357, in _handle_dbapi_exception
    raise sqlalchemy_exception.with_traceback(exc_info[2]) from e
  File "C:\Users\g_and\AppData\Local\Programs\Python\Python311\Lib\site-packages\sqlalchemy\engine\base.py", line 1971, in _exec_single_context
    self.dialect.do_execute(
  File "C:\Users\g_and\AppData\Local\Programs\Python\Python311\Lib\site-packages\sqlalchemy\engine\default.py", line 919, in do_execute
    cursor.execute(statement, parameters)
  File "C:\Users\g_and\AppData\Local\Programs\Python\Python311\Lib\site-packages\MySQLdb\cursors.py", line 179, in execute
    res = self._query(mogrified_query)
          ^^^^^^^^^^^^^^^^^^^^^^^^^^^^
  File "C:\Users\g_and\AppData\Local\Programs\Python\Python311\Lib\site-packages\MySQLdb\cursors.py", line 330, in _query
    db.query(q)
  File "C:\Users\g_and\AppData\Local\Programs\Python\Python311\Lib\site-packages\MySQLdb\connections.py", line 257, in query
    _mysql.connection.query(self, query)
sqlalchemy.exc.IntegrityError: (MySQLdb.IntegrityError) (1062, "Duplicate entry 'new' for key 'user.PRIMARY'")
[SQL: INSERT INTO user (username, password, email, is_admin, first_login) VALUES (%s, %s, %s, %s, %s)]
[parameters: ('new', 'mew', 'new@nucleusteq.com', False, True)]
(Background on this error at: https://sqlalche.me/e/20/gkpj)
2024-06-03 00:54:56,157 [ERROR] app.main Exception (MySQLdb.IntegrityError) (1062, "Duplicate entry 'new' for key 'user.PRIMARY'")
[SQL: INSERT INTO user (username, password, email, is_admin, first_login) VALUES (%s, %s, %s, %s, %s)]
[parameters: ('new', 'mew', 'new@nucleusteq.com', False, True)]
(Background on this error at: https://sqlalche.me/e/20/gkpj) occurred while adding user new
Traceback (most recent call last):
  File "C:\Users\g_and\AppData\Local\Programs\Python\Python311\Lib\site-packages\sqlalchemy\engine\base.py", line 1971, in _exec_single_context
    self.dialect.do_execute(
  File "C:\Users\g_and\AppData\Local\Programs\Python\Python311\Lib\site-packages\sqlalchemy\engine\default.py", line 919, in do_execute
    cursor.execute(statement, parameters)
  File "C:\Users\g_and\AppData\Local\Programs\Python\Python311\Lib\site-packages\MySQLdb\cursors.py", line 179, in execute
    res = self._query(mogrified_query)
          ^^^^^^^^^^^^^^^^^^^^^^^^^^^^
  File "C:\Users\g_and\AppData\Local\Programs\Python\Python311\Lib\site-packages\MySQLdb\cursors.py", line 330, in _query
    db.query(q)
  File "C:\Users\g_and\AppData\Local\Programs\Python\Python311\Lib\site-packages\MySQLdb\connections.py", line 257, in query
    _mysql.connection.query(self, query)
MySQLdb.IntegrityError: (1062, "Duplicate entry 'new' for key 'user.PRIMARY'")

The above exception was the direct cause of the following exception:

Traceback (most recent call last):
  File "C:\Users\g_and\Desktop\inventory management system\app\main.py", line 123, in add_user
    db.session.commit()
  File "C:\Users\g_and\AppData\Local\Programs\Python\Python311\Lib\site-packages\sqlalchemy\orm\scoping.py", line 597, in commit
    return self._proxied.commit()
           ^^^^^^^^^^^^^^^^^^^^^^
  File "C:\Users\g_and\AppData\Local\Programs\Python\Python311\Lib\site-packages\sqlalchemy\orm\session.py", line 1972, in commit
    trans.commit(_to_root=True)
  File "<string>", line 2, in commit
  File "C:\Users\g_and\AppData\Local\Programs\Python\Python311\Lib\site-packages\sqlalchemy\orm\state_changes.py", line 139, in _go
    ret_value = fn(self, *arg, **kw)
                ^^^^^^^^^^^^^^^^^^^^
  File "C:\Users\g_and\AppData\Local\Programs\Python\Python311\Lib\site-packages\sqlalchemy\orm\session.py", line 1257, in commit
    self._prepare_impl()
  File "<string>", line 2, in _prepare_impl
  File "C:\Users\g_and\AppData\Local\Programs\Python\Python311\Lib\site-packages\sqlalchemy\orm\state_changes.py", line 139, in _go
    ret_value = fn(self, *arg, **kw)
                ^^^^^^^^^^^^^^^^^^^^
  File "C:\Users\g_and\AppData\Local\Programs\Python\Python311\Lib\site-packages\sqlalchemy\orm\session.py", line 1232, in _prepare_impl
    self.session.flush()
  File "C:\Users\g_and\AppData\Local\Programs\Python\Python311\Lib\site-packages\sqlalchemy\orm\session.py", line 4296, in flush
    self._flush(objects)
  File "C:\Users\g_and\AppData\Local\Programs\Python\Python311\Lib\site-packages\sqlalchemy\orm\session.py", line 4431, in _flush
    with util.safe_reraise():
  File "C:\Users\g_and\AppData\Local\Programs\Python\Python311\Lib\site-packages\sqlalchemy\util\langhelpers.py", line 146, in __exit__
    raise exc_value.with_traceback(exc_tb)
  File "C:\Users\g_and\AppData\Local\Programs\Python\Python311\Lib\site-packages\sqlalchemy\orm\session.py", line 4392, in _flush
    flush_context.execute()
  File "C:\Users\g_and\AppData\Local\Programs\Python\Python311\Lib\site-packages\sqlalchemy\orm\unitofwork.py", line 466, in execute
    rec.execute(self)
  File "C:\Users\g_and\AppData\Local\Programs\Python\Python311\Lib\site-packages\sqlalchemy\orm\unitofwork.py", line 642, in execute
    util.preloaded.orm_persistence.save_obj(
  File "C:\Users\g_and\AppData\Local\Programs\Python\Python311\Lib\site-packages\sqlalchemy\orm\persistence.py", line 93, in save_obj
    _emit_insert_statements(
  File "C:\Users\g_and\AppData\Local\Programs\Python\Python311\Lib\site-packages\sqlalchemy\orm\persistence.py", line 1048, in _emit_insert_statements
    result = connection.execute(
             ^^^^^^^^^^^^^^^^^^^
  File "C:\Users\g_and\AppData\Local\Programs\Python\Python311\Lib\site-packages\sqlalchemy\engine\base.py", line 1422, in execute
    return meth(
           ^^^^^
  File "C:\Users\g_and\AppData\Local\Programs\Python\Python311\Lib\site-packages\sqlalchemy\sql\elements.py", line 514, in _execute_on_connection
    return connection._execute_clauseelement(
           ^^^^^^^^^^^^^^^^^^^^^^^^^^^^^^^^^^
  File "C:\Users\g_and\AppData\Local\Programs\Python\Python311\Lib\site-packages\sqlalchemy\engine\base.py", line 1644, in _execute_clauseelement
    ret = self._execute_context(
          ^^^^^^^^^^^^^^^^^^^^^^
  File "C:\Users\g_and\AppData\Local\Programs\Python\Python311\Lib\site-packages\sqlalchemy\engine\base.py", line 1850, in _execute_context
    return self._exec_single_context(
           ^^^^^^^^^^^^^^^^^^^^^^^^^^
  File "C:\Users\g_and\AppData\Local\Programs\Python\Python311\Lib\site-packages\sqlalchemy\engine\base.py", line 1990, in _exec_single_context
    self._handle_dbapi_exception(
  File "C:\Users\g_and\AppData\Local\Programs\Python\Python311\Lib\site-packages\sqlalchemy\engine\base.py", line 2357, in _handle_dbapi_exception
    raise sqlalchemy_exception.with_traceback(exc_info[2]) from e
  File "C:\Users\g_and\AppData\Local\Programs\Python\Python311\Lib\site-packages\sqlalchemy\engine\base.py", line 1971, in _exec_single_context
    self.dialect.do_execute(
  File "C:\Users\g_and\AppData\Local\Programs\Python\Python311\Lib\site-packages\sqlalchemy\engine\default.py", line 919, in do_execute
    cursor.execute(statement, parameters)
  File "C:\Users\g_and\AppData\Local\Programs\Python\Python311\Lib\site-packages\MySQLdb\cursors.py", line 179, in execute
    res = self._query(mogrified_query)
          ^^^^^^^^^^^^^^^^^^^^^^^^^^^^
  File "C:\Users\g_and\AppData\Local\Programs\Python\Python311\Lib\site-packages\MySQLdb\cursors.py", line 330, in _query
    db.query(q)
  File "C:\Users\g_and\AppData\Local\Programs\Python\Python311\Lib\site-packages\MySQLdb\connections.py", line 257, in query
    _mysql.connection.query(self, query)
sqlalchemy.exc.IntegrityError: (MySQLdb.IntegrityError) (1062, "Duplicate entry 'new' for key 'user.PRIMARY'")
[SQL: INSERT INTO user (username, password, email, is_admin, first_login) VALUES (%s, %s, %s, %s, %s)]
[parameters: ('new', 'mew', 'new@nucleusteq.com', False, True)]
(Background on this error at: https://sqlalche.me/e/20/gkpj)
2024-06-03 00:55:13,462 [WARNING] app.main Attempt to add user with invalid email: new@nucleusteq.coms
2024-06-03 00:55:30,046 [ERROR] app.main Exception (MySQLdb.IntegrityError) (1062, "Duplicate entry 'new' for key 'user.PRIMARY'")
[SQL: INSERT INTO user (username, password, email, is_admin, first_login) VALUES (%s, %s, %s, %s, %s)]
[parameters: ('new', 'mew', 'news@nucleusteq.com', False, True)]
(Background on this error at: https://sqlalche.me/e/20/gkpj) occurred while adding user new
Traceback (most recent call last):
  File "C:\Users\g_and\AppData\Local\Programs\Python\Python311\Lib\site-packages\sqlalchemy\engine\base.py", line 1971, in _exec_single_context
    self.dialect.do_execute(
  File "C:\Users\g_and\AppData\Local\Programs\Python\Python311\Lib\site-packages\sqlalchemy\engine\default.py", line 919, in do_execute
    cursor.execute(statement, parameters)
  File "C:\Users\g_and\AppData\Local\Programs\Python\Python311\Lib\site-packages\MySQLdb\cursors.py", line 179, in execute
    res = self._query(mogrified_query)
          ^^^^^^^^^^^^^^^^^^^^^^^^^^^^
  File "C:\Users\g_and\AppData\Local\Programs\Python\Python311\Lib\site-packages\MySQLdb\cursors.py", line 330, in _query
    db.query(q)
  File "C:\Users\g_and\AppData\Local\Programs\Python\Python311\Lib\site-packages\MySQLdb\connections.py", line 257, in query
    _mysql.connection.query(self, query)
MySQLdb.IntegrityError: (1062, "Duplicate entry 'new' for key 'user.PRIMARY'")

The above exception was the direct cause of the following exception:

Traceback (most recent call last):
  File "C:\Users\g_and\Desktop\inventory management system\app\main.py", line 123, in add_user
    db.session.commit()
  File "C:\Users\g_and\AppData\Local\Programs\Python\Python311\Lib\site-packages\sqlalchemy\orm\scoping.py", line 597, in commit
    return self._proxied.commit()
           ^^^^^^^^^^^^^^^^^^^^^^
  File "C:\Users\g_and\AppData\Local\Programs\Python\Python311\Lib\site-packages\sqlalchemy\orm\session.py", line 1972, in commit
    trans.commit(_to_root=True)
  File "<string>", line 2, in commit
  File "C:\Users\g_and\AppData\Local\Programs\Python\Python311\Lib\site-packages\sqlalchemy\orm\state_changes.py", line 139, in _go
    ret_value = fn(self, *arg, **kw)
                ^^^^^^^^^^^^^^^^^^^^
  File "C:\Users\g_and\AppData\Local\Programs\Python\Python311\Lib\site-packages\sqlalchemy\orm\session.py", line 1257, in commit
    self._prepare_impl()
  File "<string>", line 2, in _prepare_impl
  File "C:\Users\g_and\AppData\Local\Programs\Python\Python311\Lib\site-packages\sqlalchemy\orm\state_changes.py", line 139, in _go
    ret_value = fn(self, *arg, **kw)
                ^^^^^^^^^^^^^^^^^^^^
  File "C:\Users\g_and\AppData\Local\Programs\Python\Python311\Lib\site-packages\sqlalchemy\orm\session.py", line 1232, in _prepare_impl
    self.session.flush()
  File "C:\Users\g_and\AppData\Local\Programs\Python\Python311\Lib\site-packages\sqlalchemy\orm\session.py", line 4296, in flush
    self._flush(objects)
  File "C:\Users\g_and\AppData\Local\Programs\Python\Python311\Lib\site-packages\sqlalchemy\orm\session.py", line 4431, in _flush
    with util.safe_reraise():
  File "C:\Users\g_and\AppData\Local\Programs\Python\Python311\Lib\site-packages\sqlalchemy\util\langhelpers.py", line 146, in __exit__
    raise exc_value.with_traceback(exc_tb)
  File "C:\Users\g_and\AppData\Local\Programs\Python\Python311\Lib\site-packages\sqlalchemy\orm\session.py", line 4392, in _flush
    flush_context.execute()
  File "C:\Users\g_and\AppData\Local\Programs\Python\Python311\Lib\site-packages\sqlalchemy\orm\unitofwork.py", line 466, in execute
    rec.execute(self)
  File "C:\Users\g_and\AppData\Local\Programs\Python\Python311\Lib\site-packages\sqlalchemy\orm\unitofwork.py", line 642, in execute
    util.preloaded.orm_persistence.save_obj(
  File "C:\Users\g_and\AppData\Local\Programs\Python\Python311\Lib\site-packages\sqlalchemy\orm\persistence.py", line 93, in save_obj
    _emit_insert_statements(
  File "C:\Users\g_and\AppData\Local\Programs\Python\Python311\Lib\site-packages\sqlalchemy\orm\persistence.py", line 1048, in _emit_insert_statements
    result = connection.execute(
             ^^^^^^^^^^^^^^^^^^^
  File "C:\Users\g_and\AppData\Local\Programs\Python\Python311\Lib\site-packages\sqlalchemy\engine\base.py", line 1422, in execute
    return meth(
           ^^^^^
  File "C:\Users\g_and\AppData\Local\Programs\Python\Python311\Lib\site-packages\sqlalchemy\sql\elements.py", line 514, in _execute_on_connection
    return connection._execute_clauseelement(
           ^^^^^^^^^^^^^^^^^^^^^^^^^^^^^^^^^^
  File "C:\Users\g_and\AppData\Local\Programs\Python\Python311\Lib\site-packages\sqlalchemy\engine\base.py", line 1644, in _execute_clauseelement
    ret = self._execute_context(
          ^^^^^^^^^^^^^^^^^^^^^^
  File "C:\Users\g_and\AppData\Local\Programs\Python\Python311\Lib\site-packages\sqlalchemy\engine\base.py", line 1850, in _execute_context
    return self._exec_single_context(
           ^^^^^^^^^^^^^^^^^^^^^^^^^^
  File "C:\Users\g_and\AppData\Local\Programs\Python\Python311\Lib\site-packages\sqlalchemy\engine\base.py", line 1990, in _exec_single_context
    self._handle_dbapi_exception(
  File "C:\Users\g_and\AppData\Local\Programs\Python\Python311\Lib\site-packages\sqlalchemy\engine\base.py", line 2357, in _handle_dbapi_exception
    raise sqlalchemy_exception.with_traceback(exc_info[2]) from e
  File "C:\Users\g_and\AppData\Local\Programs\Python\Python311\Lib\site-packages\sqlalchemy\engine\base.py", line 1971, in _exec_single_context
    self.dialect.do_execute(
  File "C:\Users\g_and\AppData\Local\Programs\Python\Python311\Lib\site-packages\sqlalchemy\engine\default.py", line 919, in do_execute
    cursor.execute(statement, parameters)
  File "C:\Users\g_and\AppData\Local\Programs\Python\Python311\Lib\site-packages\MySQLdb\cursors.py", line 179, in execute
    res = self._query(mogrified_query)
          ^^^^^^^^^^^^^^^^^^^^^^^^^^^^
  File "C:\Users\g_and\AppData\Local\Programs\Python\Python311\Lib\site-packages\MySQLdb\cursors.py", line 330, in _query
    db.query(q)
  File "C:\Users\g_and\AppData\Local\Programs\Python\Python311\Lib\site-packages\MySQLdb\connections.py", line 257, in query
    _mysql.connection.query(self, query)
sqlalchemy.exc.IntegrityError: (MySQLdb.IntegrityError) (1062, "Duplicate entry 'new' for key 'user.PRIMARY'")
[SQL: INSERT INTO user (username, password, email, is_admin, first_login) VALUES (%s, %s, %s, %s, %s)]
[parameters: ('new', 'mew', 'news@nucleusteq.com', False, True)]
(Background on this error at: https://sqlalche.me/e/20/gkpj)
2024-06-03 00:55:39,074 [INFO] app.main User news added by None
2024-06-03 00:55:39,082 [WARNING] app.main Login page has arrived
2024-06-03 01:05:47,699 [WARNING] app.main Login page has arrived
2024-06-03 01:06:04,298 [WARNING] app.main Login page has arrived
2024-06-03 01:06:20,867 [WARNING] app.main Login page has arrived
2024-06-03 01:36:50,831 [WARNING] app.main Login page has arrived
2024-06-03 01:37:06,890 [WARNING] app.main Login page has arrived
2024-06-03 01:37:18,788 [WARNING] app.main Login page has arrived
2024-06-03 01:37:22,250 [WARNING] app.main Login page has arrived
2024-06-03 01:37:22,938 [WARNING] app.main Login page has arrived
2024-06-03 01:37:23,145 [WARNING] app.main Login page has arrived
2024-06-03 01:37:23,336 [WARNING] app.main Login page has arrived
2024-06-03 01:37:23,552 [WARNING] app.main Login page has arrived
2024-06-03 01:37:45,156 [WARNING] app.main Login page has arrived
2024-06-03 01:38:06,652 [WARNING] app.main Login page has arrived
2024-06-03 01:38:12,913 [WARNING] app.main Login page has arrived
2024-06-03 01:40:26,756 [WARNING] app.main Login page has arrived
2024-06-03 01:40:28,591 [WARNING] app.main Login page has arrived
2024-06-03 01:40:29,561 [WARNING] app.main Login page has arrived
2024-06-03 01:40:34,629 [INFO] app.main User None logged out
2024-06-03 01:40:34,635 [INFO] app.main User admin logged in for the first time
2024-06-03 01:40:36,104 [INFO] app.main Admin admin accessed admin dashboard
2024-06-03 01:40:36,105 [ERROR] app.main Exception admin_dashboard.html occurred while rendering admin_dashboard for admin
Traceback (most recent call last):
  File "C:\Users\g_and\Desktop\inventory management system\app\main.py", line 32, in admin_dashboard
    return render_template('admin_dashboard.html', items=items_list, employees=employees_list)
           ^^^^^^^^^^^^^^^^^^^^^^^^^^^^^^^^^^^^^^^^^^^^^^^^^^^^^^^^^^^^^^^^^^^^^^^^^^^^^^^^^^^
  File "C:\Users\g_and\AppData\Local\Programs\Python\Python311\Lib\site-packages\flask\templating.py", line 151, in render_template
    template = app.jinja_env.get_or_select_template(template_name_or_list)
               ^^^^^^^^^^^^^^^^^^^^^^^^^^^^^^^^^^^^^^^^^^^^^^^^^^^^^^^^^^^
  File "C:\Users\g_and\AppData\Local\Programs\Python\Python311\Lib\site-packages\jinja2\environment.py", line 1081, in get_or_select_template
    return self.get_template(template_name_or_list, parent, globals)
           ^^^^^^^^^^^^^^^^^^^^^^^^^^^^^^^^^^^^^^^^^^^^^^^^^^^^^^^^^
  File "C:\Users\g_and\AppData\Local\Programs\Python\Python311\Lib\site-packages\jinja2\environment.py", line 1010, in get_template
    return self._load_template(name, globals)
           ^^^^^^^^^^^^^^^^^^^^^^^^^^^^^^^^^^
  File "C:\Users\g_and\AppData\Local\Programs\Python\Python311\Lib\site-packages\jinja2\environment.py", line 969, in _load_template
    template = self.loader.load(self, name, self.make_globals(globals))
               ^^^^^^^^^^^^^^^^^^^^^^^^^^^^^^^^^^^^^^^^^^^^^^^^^^^^^^^^
  File "C:\Users\g_and\AppData\Local\Programs\Python\Python311\Lib\site-packages\jinja2\loaders.py", line 126, in load
    source, filename, uptodate = self.get_source(environment, name)
                                 ^^^^^^^^^^^^^^^^^^^^^^^^^^^^^^^^^^
  File "C:\Users\g_and\AppData\Local\Programs\Python\Python311\Lib\site-packages\flask\templating.py", line 65, in get_source
    return self._get_source_fast(environment, template)
           ^^^^^^^^^^^^^^^^^^^^^^^^^^^^^^^^^^^^^^^^^^^^
  File "C:\Users\g_and\AppData\Local\Programs\Python\Python311\Lib\site-packages\flask\templating.py", line 99, in _get_source_fast
    raise TemplateNotFound(template)
jinja2.exceptions.TemplateNotFound: admin_dashboard.html
2024-06-03 01:40:38,283 [WARNING] app.main Login page has arrived
2024-06-03 01:40:40,199 [WARNING] app.main Login page has arrived
2024-06-03 01:40:40,675 [WARNING] app.main Login page has arrived
2024-06-03 01:41:43,652 [WARNING] app.main Login page has arrived
2024-06-03 01:41:53,328 [WARNING] app.main Login page has arrived
2024-06-03 01:46:50,574 [WARNING] app.main Login page has arrived
2024-06-03 01:46:55,064 [INFO] app.main User None logged out
2024-06-03 01:46:55,072 [INFO] app.main User admin logged in for the first time
2024-06-03 01:46:56,594 [INFO] app.main Admin admin accessed admin dashboard
2024-06-03 01:46:56,595 [ERROR] app.main Exception admin_dashboard.html occurred while rendering admin_dashboard for admin
Traceback (most recent call last):
  File "C:\Users\g_and\Desktop\inventory management system\app\main.py", line 32, in admin_dashboard
    return render_template('admin_dashboard.html', items=items_list, employees=employees_list)
           ^^^^^^^^^^^^^^^^^^^^^^^^^^^^^^^^^^^^^^^^^^^^^^^^^^^^^^^^^^^^^^^^^^^^^^^^^^^^^^^^^^^
  File "C:\Users\g_and\AppData\Local\Programs\Python\Python311\Lib\site-packages\flask\templating.py", line 151, in render_template
    template = app.jinja_env.get_or_select_template(template_name_or_list)
               ^^^^^^^^^^^^^^^^^^^^^^^^^^^^^^^^^^^^^^^^^^^^^^^^^^^^^^^^^^^
  File "C:\Users\g_and\AppData\Local\Programs\Python\Python311\Lib\site-packages\jinja2\environment.py", line 1081, in get_or_select_template
    return self.get_template(template_name_or_list, parent, globals)
           ^^^^^^^^^^^^^^^^^^^^^^^^^^^^^^^^^^^^^^^^^^^^^^^^^^^^^^^^^
  File "C:\Users\g_and\AppData\Local\Programs\Python\Python311\Lib\site-packages\jinja2\environment.py", line 1010, in get_template
    return self._load_template(name, globals)
           ^^^^^^^^^^^^^^^^^^^^^^^^^^^^^^^^^^
  File "C:\Users\g_and\AppData\Local\Programs\Python\Python311\Lib\site-packages\jinja2\environment.py", line 969, in _load_template
    template = self.loader.load(self, name, self.make_globals(globals))
               ^^^^^^^^^^^^^^^^^^^^^^^^^^^^^^^^^^^^^^^^^^^^^^^^^^^^^^^^
  File "C:\Users\g_and\AppData\Local\Programs\Python\Python311\Lib\site-packages\jinja2\loaders.py", line 126, in load
    source, filename, uptodate = self.get_source(environment, name)
                                 ^^^^^^^^^^^^^^^^^^^^^^^^^^^^^^^^^^
  File "C:\Users\g_and\AppData\Local\Programs\Python\Python311\Lib\site-packages\flask\templating.py", line 65, in get_source
    return self._get_source_fast(environment, template)
           ^^^^^^^^^^^^^^^^^^^^^^^^^^^^^^^^^^^^^^^^^^^^
  File "C:\Users\g_and\AppData\Local\Programs\Python\Python311\Lib\site-packages\flask\templating.py", line 99, in _get_source_fast
    raise TemplateNotFound(template)
jinja2.exceptions.TemplateNotFound: admin_dashboard.html
2024-06-03 01:49:37,132 [WARNING] app.main Login page has arrived
2024-06-03 01:49:38,602 [WARNING] app.main Login page has arrived
2024-06-03 01:49:45,413 [INFO] app.main User admin logged in for the first time
2024-06-03 01:51:26,234 [WARNING] app.main Login page has arrived
2024-06-03 01:51:27,597 [WARNING] app.main Login page has arrived
2024-06-03 01:51:39,037 [WARNING] app.main Login page has arrived
2024-06-03 01:51:47,056 [WARNING] app.main Login page has arrived
2024-06-03 01:51:51,961 [INFO] app.main User admin logged in for the first time
2024-06-03 01:52:48,123 [WARNING] app.main Login page has arrived
2024-06-03 01:52:51,168 [WARNING] app.main Login page has arrived
2024-06-03 01:53:07,212 [INFO] app.main User admin logged in
2024-06-03 01:53:07,251 [INFO] app.main Admin admin accessed admin dashboard
2024-06-03 01:53:07,252 [ERROR] app.main Exception admin_dashboard.html occurred while rendering admin_dashboard for admin
Traceback (most recent call last):
  File "C:\Users\g_and\Desktop\inventory management system\app\main.py", line 32, in admin_dashboard
    return render_template('admin_dashboard.html', items=items_list, employees=employees_list)
           ^^^^^^^^^^^^^^^^^^^^^^^^^^^^^^^^^^^^^^^^^^^^^^^^^^^^^^^^^^^^^^^^^^^^^^^^^^^^^^^^^^^
  File "C:\Users\g_and\AppData\Local\Programs\Python\Python311\Lib\site-packages\flask\templating.py", line 151, in render_template
    template = app.jinja_env.get_or_select_template(template_name_or_list)
               ^^^^^^^^^^^^^^^^^^^^^^^^^^^^^^^^^^^^^^^^^^^^^^^^^^^^^^^^^^^
  File "C:\Users\g_and\AppData\Local\Programs\Python\Python311\Lib\site-packages\jinja2\environment.py", line 1081, in get_or_select_template
    return self.get_template(template_name_or_list, parent, globals)
           ^^^^^^^^^^^^^^^^^^^^^^^^^^^^^^^^^^^^^^^^^^^^^^^^^^^^^^^^^
  File "C:\Users\g_and\AppData\Local\Programs\Python\Python311\Lib\site-packages\jinja2\environment.py", line 1010, in get_template
    return self._load_template(name, globals)
           ^^^^^^^^^^^^^^^^^^^^^^^^^^^^^^^^^^
  File "C:\Users\g_and\AppData\Local\Programs\Python\Python311\Lib\site-packages\jinja2\environment.py", line 969, in _load_template
    template = self.loader.load(self, name, self.make_globals(globals))
               ^^^^^^^^^^^^^^^^^^^^^^^^^^^^^^^^^^^^^^^^^^^^^^^^^^^^^^^^
  File "C:\Users\g_and\AppData\Local\Programs\Python\Python311\Lib\site-packages\jinja2\loaders.py", line 126, in load
    source, filename, uptodate = self.get_source(environment, name)
                                 ^^^^^^^^^^^^^^^^^^^^^^^^^^^^^^^^^^
  File "C:\Users\g_and\AppData\Local\Programs\Python\Python311\Lib\site-packages\flask\templating.py", line 65, in get_source
    return self._get_source_fast(environment, template)
           ^^^^^^^^^^^^^^^^^^^^^^^^^^^^^^^^^^^^^^^^^^^^
  File "C:\Users\g_and\AppData\Local\Programs\Python\Python311\Lib\site-packages\flask\templating.py", line 99, in _get_source_fast
    raise TemplateNotFound(template)
jinja2.exceptions.TemplateNotFound: admin_dashboard.html
2024-06-03 01:53:16,049 [WARNING] app.main Login page has arrived
2024-06-03 01:53:19,180 [INFO] app.main User admin logged in
2024-06-03 01:53:19,213 [INFO] app.main Admin admin accessed admin dashboard
2024-06-03 01:53:19,215 [ERROR] app.main Exception admin_dashboard.html occurred while rendering admin_dashboard for admin
Traceback (most recent call last):
  File "C:\Users\g_and\Desktop\inventory management system\app\main.py", line 32, in admin_dashboard
    return render_template('admin_dashboard.html', items=items_list, employees=employees_list)
           ^^^^^^^^^^^^^^^^^^^^^^^^^^^^^^^^^^^^^^^^^^^^^^^^^^^^^^^^^^^^^^^^^^^^^^^^^^^^^^^^^^^
  File "C:\Users\g_and\AppData\Local\Programs\Python\Python311\Lib\site-packages\flask\templating.py", line 151, in render_template
    template = app.jinja_env.get_or_select_template(template_name_or_list)
               ^^^^^^^^^^^^^^^^^^^^^^^^^^^^^^^^^^^^^^^^^^^^^^^^^^^^^^^^^^^
  File "C:\Users\g_and\AppData\Local\Programs\Python\Python311\Lib\site-packages\jinja2\environment.py", line 1081, in get_or_select_template
    return self.get_template(template_name_or_list, parent, globals)
           ^^^^^^^^^^^^^^^^^^^^^^^^^^^^^^^^^^^^^^^^^^^^^^^^^^^^^^^^^
  File "C:\Users\g_and\AppData\Local\Programs\Python\Python311\Lib\site-packages\jinja2\environment.py", line 1010, in get_template
    return self._load_template(name, globals)
           ^^^^^^^^^^^^^^^^^^^^^^^^^^^^^^^^^^
  File "C:\Users\g_and\AppData\Local\Programs\Python\Python311\Lib\site-packages\jinja2\environment.py", line 969, in _load_template
    template = self.loader.load(self, name, self.make_globals(globals))
               ^^^^^^^^^^^^^^^^^^^^^^^^^^^^^^^^^^^^^^^^^^^^^^^^^^^^^^^^
  File "C:\Users\g_and\AppData\Local\Programs\Python\Python311\Lib\site-packages\jinja2\loaders.py", line 126, in load
    source, filename, uptodate = self.get_source(environment, name)
                                 ^^^^^^^^^^^^^^^^^^^^^^^^^^^^^^^^^^
  File "C:\Users\g_and\AppData\Local\Programs\Python\Python311\Lib\site-packages\flask\templating.py", line 65, in get_source
    return self._get_source_fast(environment, template)
           ^^^^^^^^^^^^^^^^^^^^^^^^^^^^^^^^^^^^^^^^^^^^
  File "C:\Users\g_and\AppData\Local\Programs\Python\Python311\Lib\site-packages\flask\templating.py", line 99, in _get_source_fast
    raise TemplateNotFound(template)
jinja2.exceptions.TemplateNotFound: admin_dashboard.html
2024-06-03 01:53:22,450 [WARNING] app.main Login page has arrived
2024-06-03 01:59:57,213 [WARNING] app.main Login page has arrived
2024-06-03 01:59:59,150 [WARNING] app.main Login page has arrived
2024-06-03 02:02:07,872 [INFO] app.main User v added by self
2024-06-03 02:02:16,492 [WARNING] app.main Login page has arrived
2024-06-03 02:02:34,670 [WARNING] app.main Attempt to add user with invalid email: v@nucleusteq.comv
2024-06-03 02:02:47,870 [INFO] app.main User vv added by self
2024-06-03 02:14:51,145 [WARNING] app.main Login page has arrived
2024-06-03 02:14:52,785 [ERROR] app Exception on /register [GET]
Traceback (most recent call last):
  File "C:\Users\g_and\AppData\Local\Programs\Python\Python311\Lib\site-packages\flask\app.py", line 1455, in wsgi_app
    response = self.full_dispatch_request()
               ^^^^^^^^^^^^^^^^^^^^^^^^^^^^
  File "C:\Users\g_and\AppData\Local\Programs\Python\Python311\Lib\site-packages\flask\app.py", line 869, in full_dispatch_request
    rv = self.handle_user_exception(e)
         ^^^^^^^^^^^^^^^^^^^^^^^^^^^^^
  File "C:\Users\g_and\AppData\Local\Programs\Python\Python311\Lib\site-packages\flask\app.py", line 867, in full_dispatch_request
    rv = self.dispatch_request()
         ^^^^^^^^^^^^^^^^^^^^^^^
  File "C:\Users\g_and\AppData\Local\Programs\Python\Python311\Lib\site-packages\flask\app.py", line 852, in dispatch_request
    return self.ensure_sync(self.view_functions[rule.endpoint])(**view_args)
           ^^^^^^^^^^^^^^^^^^^^^^^^^^^^^^^^^^^^^^^^^^^^^^^^^^^^^^^^^^^^^^^^^
  File "C:\Users\g_and\Desktop\inventory management system\app\main.py", line 17, in register
    return render_template("register.html")
           ^^^^^^^^^^^^^^^^^^^^^^^^^^^^^^^^
  File "C:\Users\g_and\AppData\Local\Programs\Python\Python311\Lib\site-packages\flask\templating.py", line 151, in render_template
    template = app.jinja_env.get_or_select_template(template_name_or_list)
               ^^^^^^^^^^^^^^^^^^^^^^^^^^^^^^^^^^^^^^^^^^^^^^^^^^^^^^^^^^^
  File "C:\Users\g_and\AppData\Local\Programs\Python\Python311\Lib\site-packages\jinja2\environment.py", line 1081, in get_or_select_template
    return self.get_template(template_name_or_list, parent, globals)
           ^^^^^^^^^^^^^^^^^^^^^^^^^^^^^^^^^^^^^^^^^^^^^^^^^^^^^^^^^
  File "C:\Users\g_and\AppData\Local\Programs\Python\Python311\Lib\site-packages\jinja2\environment.py", line 1010, in get_template
    return self._load_template(name, globals)
           ^^^^^^^^^^^^^^^^^^^^^^^^^^^^^^^^^^
  File "C:\Users\g_and\AppData\Local\Programs\Python\Python311\Lib\site-packages\jinja2\environment.py", line 969, in _load_template
    template = self.loader.load(self, name, self.make_globals(globals))
               ^^^^^^^^^^^^^^^^^^^^^^^^^^^^^^^^^^^^^^^^^^^^^^^^^^^^^^^^
  File "C:\Users\g_and\AppData\Local\Programs\Python\Python311\Lib\site-packages\jinja2\loaders.py", line 138, in load
    code = environment.compile(source, name, filename)
           ^^^^^^^^^^^^^^^^^^^^^^^^^^^^^^^^^^^^^^^^^^^
  File "C:\Users\g_and\AppData\Local\Programs\Python\Python311\Lib\site-packages\jinja2\environment.py", line 768, in compile
    self.handle_exception(source=source_hint)
  File "C:\Users\g_and\AppData\Local\Programs\Python\Python311\Lib\site-packages\jinja2\environment.py", line 936, in handle_exception
    raise rewrite_traceback_stack(source=source)
  File "C:\Users\g_and\Desktop\inventory management system\templates\register.html", line 11, in template
    <div id="message" class="message" style="display: none;">{{% message %}}</div>
    ^^^^^^^^^^^^^^^^^^^^^^^^^
jinja2.exceptions.TemplateSyntaxError: unexpected '%'
2024-06-03 02:15:36,312 [INFO] app.main User potaot added by self
2024-06-03 02:15:50,804 [WARNING] app.main Login page has arrived
2024-06-03 02:16:08,014 [INFO] app.main User potaot logged in for the first time
2024-06-03 02:16:10,058 [INFO] app.main Admin potaot accessed admin dashboard
2024-06-03 02:16:10,058 [ERROR] app.main Exception admin_dashboard.html occurred while rendering admin_dashboard for potaot
Traceback (most recent call last):
  File "C:\Users\g_and\Desktop\inventory management system\app\main.py", line 32, in admin_dashboard
    return render_template('admin_dashboard.html', items=items_list, employees=employees_list)
           ^^^^^^^^^^^^^^^^^^^^^^^^^^^^^^^^^^^^^^^^^^^^^^^^^^^^^^^^^^^^^^^^^^^^^^^^^^^^^^^^^^^
  File "C:\Users\g_and\AppData\Local\Programs\Python\Python311\Lib\site-packages\flask\templating.py", line 151, in render_template
    template = app.jinja_env.get_or_select_template(template_name_or_list)
               ^^^^^^^^^^^^^^^^^^^^^^^^^^^^^^^^^^^^^^^^^^^^^^^^^^^^^^^^^^^
  File "C:\Users\g_and\AppData\Local\Programs\Python\Python311\Lib\site-packages\jinja2\environment.py", line 1081, in get_or_select_template
    return self.get_template(template_name_or_list, parent, globals)
           ^^^^^^^^^^^^^^^^^^^^^^^^^^^^^^^^^^^^^^^^^^^^^^^^^^^^^^^^^
  File "C:\Users\g_and\AppData\Local\Programs\Python\Python311\Lib\site-packages\jinja2\environment.py", line 1010, in get_template
    return self._load_template(name, globals)
           ^^^^^^^^^^^^^^^^^^^^^^^^^^^^^^^^^^
  File "C:\Users\g_and\AppData\Local\Programs\Python\Python311\Lib\site-packages\jinja2\environment.py", line 969, in _load_template
    template = self.loader.load(self, name, self.make_globals(globals))
               ^^^^^^^^^^^^^^^^^^^^^^^^^^^^^^^^^^^^^^^^^^^^^^^^^^^^^^^^
  File "C:\Users\g_and\AppData\Local\Programs\Python\Python311\Lib\site-packages\jinja2\loaders.py", line 126, in load
    source, filename, uptodate = self.get_source(environment, name)
                                 ^^^^^^^^^^^^^^^^^^^^^^^^^^^^^^^^^^
  File "C:\Users\g_and\AppData\Local\Programs\Python\Python311\Lib\site-packages\flask\templating.py", line 65, in get_source
    return self._get_source_fast(environment, template)
           ^^^^^^^^^^^^^^^^^^^^^^^^^^^^^^^^^^^^^^^^^^^^
  File "C:\Users\g_and\AppData\Local\Programs\Python\Python311\Lib\site-packages\flask\templating.py", line 99, in _get_source_fast
    raise TemplateNotFound(template)
jinja2.exceptions.TemplateNotFound: admin_dashboard.html
2024-06-03 02:16:15,805 [WARNING] app.main Login page has arrived
2024-06-03 02:22:33,791 [WARNING] app.main Login page has arrived
2024-06-03 02:22:45,378 [INFO] app.main User potaot logged in
2024-06-03 02:22:45,410 [INFO] app.main Admin potaot accessed admin dashboard
2024-06-03 02:22:45,412 [ERROR] app.main Exception admin_dashboard.html occurred while rendering admin_dashboard for potaot
Traceback (most recent call last):
  File "C:\Users\g_and\Desktop\inventory management system\app\main.py", line 37, in admin_dashboard
    return render_template('admin_dashboard.html', items=items_list, employees=employees_list)
           ^^^^^^^^^^^^^^^^^^^^^^^^^^^^^^^^^^^^^^^^^^^^^^^^^^^^^^^^^^^^^^^^^^^^^^^^^^^^^^^^^^^
  File "C:\Users\g_and\AppData\Local\Programs\Python\Python311\Lib\site-packages\flask\templating.py", line 151, in render_template
    template = app.jinja_env.get_or_select_template(template_name_or_list)
               ^^^^^^^^^^^^^^^^^^^^^^^^^^^^^^^^^^^^^^^^^^^^^^^^^^^^^^^^^^^
  File "C:\Users\g_and\AppData\Local\Programs\Python\Python311\Lib\site-packages\jinja2\environment.py", line 1081, in get_or_select_template
    return self.get_template(template_name_or_list, parent, globals)
           ^^^^^^^^^^^^^^^^^^^^^^^^^^^^^^^^^^^^^^^^^^^^^^^^^^^^^^^^^
  File "C:\Users\g_and\AppData\Local\Programs\Python\Python311\Lib\site-packages\jinja2\environment.py", line 1010, in get_template
    return self._load_template(name, globals)
           ^^^^^^^^^^^^^^^^^^^^^^^^^^^^^^^^^^
  File "C:\Users\g_and\AppData\Local\Programs\Python\Python311\Lib\site-packages\jinja2\environment.py", line 969, in _load_template
    template = self.loader.load(self, name, self.make_globals(globals))
               ^^^^^^^^^^^^^^^^^^^^^^^^^^^^^^^^^^^^^^^^^^^^^^^^^^^^^^^^
  File "C:\Users\g_and\AppData\Local\Programs\Python\Python311\Lib\site-packages\jinja2\loaders.py", line 126, in load
    source, filename, uptodate = self.get_source(environment, name)
                                 ^^^^^^^^^^^^^^^^^^^^^^^^^^^^^^^^^^
  File "C:\Users\g_and\AppData\Local\Programs\Python\Python311\Lib\site-packages\flask\templating.py", line 65, in get_source
    return self._get_source_fast(environment, template)
           ^^^^^^^^^^^^^^^^^^^^^^^^^^^^^^^^^^^^^^^^^^^^
  File "C:\Users\g_and\AppData\Local\Programs\Python\Python311\Lib\site-packages\flask\templating.py", line 99, in _get_source_fast
    raise TemplateNotFound(template)
jinja2.exceptions.TemplateNotFound: admin_dashboard.html
2024-06-03 02:24:34,421 [WARNING] app.main Login page has arrived
2024-06-03 02:24:35,401 [WARNING] app.main Login page has arrived
2024-06-03 02:24:43,178 [INFO] app.main User potaot logged in
2024-06-03 02:24:43,217 [INFO] app.main Admin potaot accessed admin dashboard
2024-06-03 02:24:43,219 [ERROR] app.main Exception admin_dashboard.html occurred while rendering admin_dashboard for potaot
Traceback (most recent call last):
  File "C:\Users\g_and\Desktop\inventory management system\app\main.py", line 37, in admin_dashboard
    return render_template('admin_dashboard.html', items=items_list, employees=employees_list)
           ^^^^^^^^^^^^^^^^^^^^^^^^^^^^^^^^^^^^^^^^^^^^^^^^^^^^^^^^^^^^^^^^^^^^^^^^^^^^^^^^^^^
  File "C:\Users\g_and\AppData\Local\Programs\Python\Python311\Lib\site-packages\flask\templating.py", line 151, in render_template
    template = app.jinja_env.get_or_select_template(template_name_or_list)
               ^^^^^^^^^^^^^^^^^^^^^^^^^^^^^^^^^^^^^^^^^^^^^^^^^^^^^^^^^^^
  File "C:\Users\g_and\AppData\Local\Programs\Python\Python311\Lib\site-packages\jinja2\environment.py", line 1081, in get_or_select_template
    return self.get_template(template_name_or_list, parent, globals)
           ^^^^^^^^^^^^^^^^^^^^^^^^^^^^^^^^^^^^^^^^^^^^^^^^^^^^^^^^^
  File "C:\Users\g_and\AppData\Local\Programs\Python\Python311\Lib\site-packages\jinja2\environment.py", line 1010, in get_template
    return self._load_template(name, globals)
           ^^^^^^^^^^^^^^^^^^^^^^^^^^^^^^^^^^
  File "C:\Users\g_and\AppData\Local\Programs\Python\Python311\Lib\site-packages\jinja2\environment.py", line 969, in _load_template
    template = self.loader.load(self, name, self.make_globals(globals))
               ^^^^^^^^^^^^^^^^^^^^^^^^^^^^^^^^^^^^^^^^^^^^^^^^^^^^^^^^
  File "C:\Users\g_and\AppData\Local\Programs\Python\Python311\Lib\site-packages\jinja2\loaders.py", line 126, in load
    source, filename, uptodate = self.get_source(environment, name)
                                 ^^^^^^^^^^^^^^^^^^^^^^^^^^^^^^^^^^
  File "C:\Users\g_and\AppData\Local\Programs\Python\Python311\Lib\site-packages\flask\templating.py", line 65, in get_source
    return self._get_source_fast(environment, template)
           ^^^^^^^^^^^^^^^^^^^^^^^^^^^^^^^^^^^^^^^^^^^^
  File "C:\Users\g_and\AppData\Local\Programs\Python\Python311\Lib\site-packages\flask\templating.py", line 99, in _get_source_fast
    raise TemplateNotFound(template)
jinja2.exceptions.TemplateNotFound: admin_dashboard.html
2024-06-03 02:26:29,752 [WARNING] app.main Login page has arrived
2024-06-03 02:26:30,550 [WARNING] app.main Login page has arrived
2024-06-03 02:26:38,995 [WARNING] app.main Failed login attempt for username: potaot
2024-06-03 02:26:56,574 [INFO] app.main User potaot logged in
2024-06-03 02:26:56,602 [INFO] app.main Admin potaot accessed admin dashboard
2024-06-03 02:26:56,603 [ERROR] app.main Exception admin_dashboard.html occurred while rendering admin_dashboard for potaot
Traceback (most recent call last):
  File "C:\Users\g_and\Desktop\inventory management system\app\main.py", line 37, in admin_dashboard
    return render_template('admin_dashboard.html', items=items_list, employees=employees_list)
           ^^^^^^^^^^^^^^^^^^^^^^^^^^^^^^^^^^^^^^^^^^^^^^^^^^^^^^^^^^^^^^^^^^^^^^^^^^^^^^^^^^^
  File "C:\Users\g_and\AppData\Local\Programs\Python\Python311\Lib\site-packages\flask\templating.py", line 151, in render_template
    template = app.jinja_env.get_or_select_template(template_name_or_list)
               ^^^^^^^^^^^^^^^^^^^^^^^^^^^^^^^^^^^^^^^^^^^^^^^^^^^^^^^^^^^
  File "C:\Users\g_and\AppData\Local\Programs\Python\Python311\Lib\site-packages\jinja2\environment.py", line 1081, in get_or_select_template
    return self.get_template(template_name_or_list, parent, globals)
           ^^^^^^^^^^^^^^^^^^^^^^^^^^^^^^^^^^^^^^^^^^^^^^^^^^^^^^^^^
  File "C:\Users\g_and\AppData\Local\Programs\Python\Python311\Lib\site-packages\jinja2\environment.py", line 1010, in get_template
    return self._load_template(name, globals)
           ^^^^^^^^^^^^^^^^^^^^^^^^^^^^^^^^^^
  File "C:\Users\g_and\AppData\Local\Programs\Python\Python311\Lib\site-packages\jinja2\environment.py", line 969, in _load_template
    template = self.loader.load(self, name, self.make_globals(globals))
               ^^^^^^^^^^^^^^^^^^^^^^^^^^^^^^^^^^^^^^^^^^^^^^^^^^^^^^^^
  File "C:\Users\g_and\AppData\Local\Programs\Python\Python311\Lib\site-packages\jinja2\loaders.py", line 126, in load
    source, filename, uptodate = self.get_source(environment, name)
                                 ^^^^^^^^^^^^^^^^^^^^^^^^^^^^^^^^^^
  File "C:\Users\g_and\AppData\Local\Programs\Python\Python311\Lib\site-packages\flask\templating.py", line 65, in get_source
    return self._get_source_fast(environment, template)
           ^^^^^^^^^^^^^^^^^^^^^^^^^^^^^^^^^^^^^^^^^^^^
  File "C:\Users\g_and\AppData\Local\Programs\Python\Python311\Lib\site-packages\flask\templating.py", line 99, in _get_source_fast
    raise TemplateNotFound(template)
jinja2.exceptions.TemplateNotFound: admin_dashboard.html
2024-06-03 02:27:34,999 [WARNING] app.main Login page has arrived
2024-06-03 02:27:47,561 [WARNING] app.main Login page has arrived
2024-06-03 02:27:55,011 [INFO] app.main User potaot logged in
2024-06-03 02:27:55,044 [INFO] app.main Employee potaot accessed employee dashboard
2024-06-03 02:27:55,046 [ERROR] app Exception on /employee_dashboard [GET]
Traceback (most recent call last):
  File "C:\Users\g_and\AppData\Local\Programs\Python\Python311\Lib\site-packages\flask\app.py", line 1455, in wsgi_app
    response = self.full_dispatch_request()
               ^^^^^^^^^^^^^^^^^^^^^^^^^^^^
  File "C:\Users\g_and\AppData\Local\Programs\Python\Python311\Lib\site-packages\flask\app.py", line 869, in full_dispatch_request
    rv = self.handle_user_exception(e)
         ^^^^^^^^^^^^^^^^^^^^^^^^^^^^^
  File "C:\Users\g_and\AppData\Local\Programs\Python\Python311\Lib\site-packages\flask\app.py", line 867, in full_dispatch_request
    rv = self.dispatch_request()
         ^^^^^^^^^^^^^^^^^^^^^^^
  File "C:\Users\g_and\AppData\Local\Programs\Python\Python311\Lib\site-packages\flask\app.py", line 852, in dispatch_request
    return self.ensure_sync(self.view_functions[rule.endpoint])(**view_args)
           ^^^^^^^^^^^^^^^^^^^^^^^^^^^^^^^^^^^^^^^^^^^^^^^^^^^^^^^^^^^^^^^^^
  File "C:\Users\g_and\Desktop\inventory management system\app\main.py", line 70, in employee_dashboard
    return render_template('employee_dashboard.html')
           ^^^^^^^^^^^^^^^^^^^^^^^^^^^^^^^^^^^^^^^^^^
  File "C:\Users\g_and\AppData\Local\Programs\Python\Python311\Lib\site-packages\flask\templating.py", line 151, in render_template
    template = app.jinja_env.get_or_select_template(template_name_or_list)
               ^^^^^^^^^^^^^^^^^^^^^^^^^^^^^^^^^^^^^^^^^^^^^^^^^^^^^^^^^^^
  File "C:\Users\g_and\AppData\Local\Programs\Python\Python311\Lib\site-packages\jinja2\environment.py", line 1081, in get_or_select_template
    return self.get_template(template_name_or_list, parent, globals)
           ^^^^^^^^^^^^^^^^^^^^^^^^^^^^^^^^^^^^^^^^^^^^^^^^^^^^^^^^^
  File "C:\Users\g_and\AppData\Local\Programs\Python\Python311\Lib\site-packages\jinja2\environment.py", line 1010, in get_template
    return self._load_template(name, globals)
           ^^^^^^^^^^^^^^^^^^^^^^^^^^^^^^^^^^
  File "C:\Users\g_and\AppData\Local\Programs\Python\Python311\Lib\site-packages\jinja2\environment.py", line 969, in _load_template
    template = self.loader.load(self, name, self.make_globals(globals))
               ^^^^^^^^^^^^^^^^^^^^^^^^^^^^^^^^^^^^^^^^^^^^^^^^^^^^^^^^
  File "C:\Users\g_and\AppData\Local\Programs\Python\Python311\Lib\site-packages\jinja2\loaders.py", line 126, in load
    source, filename, uptodate = self.get_source(environment, name)
                                 ^^^^^^^^^^^^^^^^^^^^^^^^^^^^^^^^^^
  File "C:\Users\g_and\AppData\Local\Programs\Python\Python311\Lib\site-packages\flask\templating.py", line 65, in get_source
    return self._get_source_fast(environment, template)
           ^^^^^^^^^^^^^^^^^^^^^^^^^^^^^^^^^^^^^^^^^^^^
  File "C:\Users\g_and\AppData\Local\Programs\Python\Python311\Lib\site-packages\flask\templating.py", line 99, in _get_source_fast
    raise TemplateNotFound(template)
jinja2.exceptions.TemplateNotFound: employee_dashboard.html
2024-06-03 02:29:48,100 [WARNING] app.main Login page has arrived
2024-06-03 02:30:38,036 [WARNING] app.main Login page has arrived
2024-06-03 02:30:46,050 [WARNING] app.main Attempt to add user with invalid email: andaniji2@gmail.com
2024-06-03 02:41:06,107 [WARNING] app.main Attempt to add user with invalid email: andaniji2@gmail.com
2024-06-03 03:27:30,122 [WARNING] app.main Login page has arrived
2024-06-03 03:29:15,623 [INFO] app.main User news logged in for the first time
2024-06-03 03:29:16,734 [INFO] app.main Employee news accessed employee dashboard
2024-06-03 03:29:16,735 [ERROR] app Exception on /employee_dashboard [GET]
Traceback (most recent call last):
  File "C:\Users\g_and\AppData\Local\Programs\Python\Python311\Lib\site-packages\flask\app.py", line 1455, in wsgi_app
    response = self.full_dispatch_request()
               ^^^^^^^^^^^^^^^^^^^^^^^^^^^^
  File "C:\Users\g_and\AppData\Local\Programs\Python\Python311\Lib\site-packages\flask\app.py", line 869, in full_dispatch_request
    rv = self.handle_user_exception(e)
         ^^^^^^^^^^^^^^^^^^^^^^^^^^^^^
  File "C:\Users\g_and\AppData\Local\Programs\Python\Python311\Lib\site-packages\flask\app.py", line 867, in full_dispatch_request
    rv = self.dispatch_request()
         ^^^^^^^^^^^^^^^^^^^^^^^
  File "C:\Users\g_and\AppData\Local\Programs\Python\Python311\Lib\site-packages\flask\app.py", line 852, in dispatch_request
    return self.ensure_sync(self.view_functions[rule.endpoint])(**view_args)
           ^^^^^^^^^^^^^^^^^^^^^^^^^^^^^^^^^^^^^^^^^^^^^^^^^^^^^^^^^^^^^^^^^
  File "C:\Users\g_and\Desktop\inventory management system\app\main.py", line 61, in employee_dashboard
    return render_template('employee_dashboard.html')
           ^^^^^^^^^^^^^^^^^^^^^^^^^^^^^^^^^^^^^^^^^^
  File "C:\Users\g_and\AppData\Local\Programs\Python\Python311\Lib\site-packages\flask\templating.py", line 151, in render_template
    template = app.jinja_env.get_or_select_template(template_name_or_list)
               ^^^^^^^^^^^^^^^^^^^^^^^^^^^^^^^^^^^^^^^^^^^^^^^^^^^^^^^^^^^
  File "C:\Users\g_and\AppData\Local\Programs\Python\Python311\Lib\site-packages\jinja2\environment.py", line 1081, in get_or_select_template
    return self.get_template(template_name_or_list, parent, globals)
           ^^^^^^^^^^^^^^^^^^^^^^^^^^^^^^^^^^^^^^^^^^^^^^^^^^^^^^^^^
  File "C:\Users\g_and\AppData\Local\Programs\Python\Python311\Lib\site-packages\jinja2\environment.py", line 1010, in get_template
    return self._load_template(name, globals)
           ^^^^^^^^^^^^^^^^^^^^^^^^^^^^^^^^^^
  File "C:\Users\g_and\AppData\Local\Programs\Python\Python311\Lib\site-packages\jinja2\environment.py", line 969, in _load_template
    template = self.loader.load(self, name, self.make_globals(globals))
               ^^^^^^^^^^^^^^^^^^^^^^^^^^^^^^^^^^^^^^^^^^^^^^^^^^^^^^^^
  File "C:\Users\g_and\AppData\Local\Programs\Python\Python311\Lib\site-packages\jinja2\loaders.py", line 126, in load
    source, filename, uptodate = self.get_source(environment, name)
                                 ^^^^^^^^^^^^^^^^^^^^^^^^^^^^^^^^^^
  File "C:\Users\g_and\AppData\Local\Programs\Python\Python311\Lib\site-packages\flask\templating.py", line 65, in get_source
    return self._get_source_fast(environment, template)
           ^^^^^^^^^^^^^^^^^^^^^^^^^^^^^^^^^^^^^^^^^^^^
  File "C:\Users\g_and\AppData\Local\Programs\Python\Python311\Lib\site-packages\flask\templating.py", line 99, in _get_source_fast
    raise TemplateNotFound(template)
jinja2.exceptions.TemplateNotFound: employee_dashboard.html
2024-06-03 04:04:36,279 [WARNING] app.main Login page has arrived
2024-06-03 04:04:37,830 [WARNING] app.main Login page has arrived
2024-06-03 04:04:41,744 [WARNING] app.main Login page has arrived
2024-06-03 04:04:57,135 [INFO] app.main User abc logged in for the first time
2024-06-03 04:04:58,801 [INFO] app.main Employee abc accessed employee dashboard
2024-06-03 04:04:58,873 [ERROR] app Exception on /employee_dashboard [GET]
Traceback (most recent call last):
  File "C:\Users\g_and\AppData\Local\Programs\Python\Python311\Lib\site-packages\flask\app.py", line 1455, in wsgi_app
    response = self.full_dispatch_request()
               ^^^^^^^^^^^^^^^^^^^^^^^^^^^^
  File "C:\Users\g_and\AppData\Local\Programs\Python\Python311\Lib\site-packages\flask\app.py", line 869, in full_dispatch_request
    rv = self.handle_user_exception(e)
         ^^^^^^^^^^^^^^^^^^^^^^^^^^^^^
  File "C:\Users\g_and\AppData\Local\Programs\Python\Python311\Lib\site-packages\flask\app.py", line 867, in full_dispatch_request
    rv = self.dispatch_request()
         ^^^^^^^^^^^^^^^^^^^^^^^
  File "C:\Users\g_and\AppData\Local\Programs\Python\Python311\Lib\site-packages\flask\app.py", line 852, in dispatch_request
    return self.ensure_sync(self.view_functions[rule.endpoint])(**view_args)
           ^^^^^^^^^^^^^^^^^^^^^^^^^^^^^^^^^^^^^^^^^^^^^^^^^^^^^^^^^^^^^^^^^
  File "C:\Users\g_and\Desktop\inventory management system\app\main.py", line 61, in employee_dashboard
    return render_template('employee_dashboard.html')
           ^^^^^^^^^^^^^^^^^^^^^^^^^^^^^^^^^^^^^^^^^^
  File "C:\Users\g_and\AppData\Local\Programs\Python\Python311\Lib\site-packages\flask\templating.py", line 152, in render_template
    return _render(app, template, context)
           ^^^^^^^^^^^^^^^^^^^^^^^^^^^^^^^
  File "C:\Users\g_and\AppData\Local\Programs\Python\Python311\Lib\site-packages\flask\templating.py", line 133, in _render
    rv = template.render(context)
         ^^^^^^^^^^^^^^^^^^^^^^^^
  File "C:\Users\g_and\AppData\Local\Programs\Python\Python311\Lib\site-packages\jinja2\environment.py", line 1301, in render
    self.environment.handle_exception()
  File "C:\Users\g_and\AppData\Local\Programs\Python\Python311\Lib\site-packages\jinja2\environment.py", line 936, in handle_exception
    raise rewrite_traceback_stack(source=source)
  File "C:\Users\g_and\Desktop\inventory management system\templates\employee_dashboard.html", line 124, in top-level template code
    'X-CSRFToken': '{{ csrf_token() }}'
    ^^^^^^^^^^^^^^^^^^^^^^^^^
  File "C:\Users\g_and\AppData\Local\Programs\Python\Python311\Lib\site-packages\jinja2\utils.py", line 83, in from_obj
    if hasattr(obj, "jinja_pass_arg"):
       ^^^^^^^^^^^^^^^^^^^^^^^^^^^^^^
jinja2.exceptions.UndefinedError: 'csrf_token' is undefined
2024-06-03 04:06:14,700 [WARNING] app.main Login page has arrived
2024-06-03 04:06:17,719 [WARNING] app.main Login page has arrived
2024-06-03 04:06:24,941 [INFO] app.main User abc logged in
2024-06-03 04:06:24,976 [INFO] app.main abc accessed the dashboard
2024-06-03 04:06:24,995 [INFO] app.main Employee abc accessed employee dashboard
2024-06-03 04:06:25,004 [ERROR] app Exception on /employee_dashboard [GET]
Traceback (most recent call last):
  File "C:\Users\g_and\AppData\Local\Programs\Python\Python311\Lib\site-packages\flask\app.py", line 1455, in wsgi_app
    response = self.full_dispatch_request()
               ^^^^^^^^^^^^^^^^^^^^^^^^^^^^
  File "C:\Users\g_and\AppData\Local\Programs\Python\Python311\Lib\site-packages\flask\app.py", line 869, in full_dispatch_request
    rv = self.handle_user_exception(e)
         ^^^^^^^^^^^^^^^^^^^^^^^^^^^^^
  File "C:\Users\g_and\AppData\Local\Programs\Python\Python311\Lib\site-packages\flask\app.py", line 867, in full_dispatch_request
    rv = self.dispatch_request()
         ^^^^^^^^^^^^^^^^^^^^^^^
  File "C:\Users\g_and\AppData\Local\Programs\Python\Python311\Lib\site-packages\flask\app.py", line 852, in dispatch_request
    return self.ensure_sync(self.view_functions[rule.endpoint])(**view_args)
           ^^^^^^^^^^^^^^^^^^^^^^^^^^^^^^^^^^^^^^^^^^^^^^^^^^^^^^^^^^^^^^^^^
  File "C:\Users\g_and\Desktop\inventory management system\app\main.py", line 61, in employee_dashboard
    return render_template('employee_dashboard.html')
           ^^^^^^^^^^^^^^^^^^^^^^^^^^^^^^^^^^^^^^^^^^
  File "C:\Users\g_and\AppData\Local\Programs\Python\Python311\Lib\site-packages\flask\templating.py", line 152, in render_template
    return _render(app, template, context)
           ^^^^^^^^^^^^^^^^^^^^^^^^^^^^^^^
  File "C:\Users\g_and\AppData\Local\Programs\Python\Python311\Lib\site-packages\flask\templating.py", line 133, in _render
    rv = template.render(context)
         ^^^^^^^^^^^^^^^^^^^^^^^^
  File "C:\Users\g_and\AppData\Local\Programs\Python\Python311\Lib\site-packages\jinja2\environment.py", line 1301, in render
    self.environment.handle_exception()
  File "C:\Users\g_and\AppData\Local\Programs\Python\Python311\Lib\site-packages\jinja2\environment.py", line 936, in handle_exception
    raise rewrite_traceback_stack(source=source)
  File "C:\Users\g_and\Desktop\inventory management system\templates\employee_dashboard.html", line 124, in top-level template code
    'X-CSRFToken': '{{ csrf_token() }}'
    ^^^^^^^^^^^^^^^^^^^^^^^^^
  File "C:\Users\g_and\AppData\Local\Programs\Python\Python311\Lib\site-packages\jinja2\utils.py", line 83, in from_obj
    if hasattr(obj, "jinja_pass_arg"):
       ^^^^^^^^^^^^^^^^^^^^^^^^^^^^^^
jinja2.exceptions.UndefinedError: 'csrf_token' is undefined
2024-06-03 04:09:20,474 [WARNING] app.main Login page has arrived
2024-06-03 04:09:23,878 [WARNING] app.main Login page has arrived
2024-06-03 04:09:29,969 [INFO] app.main User abc logged in
2024-06-03 04:09:29,998 [INFO] app.main abc accessed the dashboard
2024-06-03 04:09:30,015 [INFO] app.main Employee abc accessed employee dashboard
2024-06-03 04:12:49,984 [INFO] app.main Employee abc accessed employee dashboard
2024-06-03 04:12:50,027 [ERROR] app Exception on /employee_dashboard [GET]
Traceback (most recent call last):
  File "C:\Users\g_and\AppData\Local\Programs\Python\Python311\Lib\site-packages\flask\app.py", line 1455, in wsgi_app
    response = self.full_dispatch_request()
               ^^^^^^^^^^^^^^^^^^^^^^^^^^^^
  File "C:\Users\g_and\AppData\Local\Programs\Python\Python311\Lib\site-packages\flask\app.py", line 869, in full_dispatch_request
    rv = self.handle_user_exception(e)
         ^^^^^^^^^^^^^^^^^^^^^^^^^^^^^
  File "C:\Users\g_and\AppData\Local\Programs\Python\Python311\Lib\site-packages\flask\app.py", line 867, in full_dispatch_request
    rv = self.dispatch_request()
         ^^^^^^^^^^^^^^^^^^^^^^^
  File "C:\Users\g_and\AppData\Local\Programs\Python\Python311\Lib\site-packages\flask\app.py", line 852, in dispatch_request
    return self.ensure_sync(self.view_functions[rule.endpoint])(**view_args)
           ^^^^^^^^^^^^^^^^^^^^^^^^^^^^^^^^^^^^^^^^^^^^^^^^^^^^^^^^^^^^^^^^^
  File "C:\Users\g_and\Desktop\inventory management system\app\main.py", line 61, in employee_dashboard
    return render_template('employee_dashboard.html')
           ^^^^^^^^^^^^^^^^^^^^^^^^^^^^^^^^^^^^^^^^^^
  File "C:\Users\g_and\AppData\Local\Programs\Python\Python311\Lib\site-packages\flask\templating.py", line 152, in render_template
    return _render(app, template, context)
           ^^^^^^^^^^^^^^^^^^^^^^^^^^^^^^^
  File "C:\Users\g_and\AppData\Local\Programs\Python\Python311\Lib\site-packages\flask\templating.py", line 133, in _render
    rv = template.render(context)
         ^^^^^^^^^^^^^^^^^^^^^^^^
  File "C:\Users\g_and\AppData\Local\Programs\Python\Python311\Lib\site-packages\jinja2\environment.py", line 1301, in render
    self.environment.handle_exception()
  File "C:\Users\g_and\AppData\Local\Programs\Python\Python311\Lib\site-packages\jinja2\environment.py", line 936, in handle_exception
    raise rewrite_traceback_stack(source=source)
  File "C:\Users\g_and\Desktop\inventory management system\templates\employee_dashboard.html", line 137, in top-level template code
    'X-CSRFToken': '{{ csrf_token() }}'
    ^^^^^^^^^^^^^^^^^^^^^^^^^
  File "C:\Users\g_and\AppData\Local\Programs\Python\Python311\Lib\site-packages\jinja2\utils.py", line 83, in from_obj
    if hasattr(obj, "jinja_pass_arg"):
       ^^^^^^^^^^^^^^^^^^^^^^^^^^^^^^
jinja2.exceptions.UndefinedError: 'csrf_token' is undefined
2024-06-03 04:12:53,351 [WARNING] app.main Login page has arrived
2024-06-03 04:12:55,573 [WARNING] app.main Login page has arrived
2024-06-03 04:13:01,560 [INFO] app.main User abc logged in
2024-06-03 04:13:01,594 [INFO] app.main abc accessed the dashboard
2024-06-03 04:13:01,635 [INFO] app.main Employee abc accessed employee dashboard
2024-06-03 04:13:01,637 [ERROR] app Exception on /employee_dashboard [GET]
Traceback (most recent call last):
  File "C:\Users\g_and\AppData\Local\Programs\Python\Python311\Lib\site-packages\flask\app.py", line 1455, in wsgi_app
    response = self.full_dispatch_request()
               ^^^^^^^^^^^^^^^^^^^^^^^^^^^^
  File "C:\Users\g_and\AppData\Local\Programs\Python\Python311\Lib\site-packages\flask\app.py", line 869, in full_dispatch_request
    rv = self.handle_user_exception(e)
         ^^^^^^^^^^^^^^^^^^^^^^^^^^^^^
  File "C:\Users\g_and\AppData\Local\Programs\Python\Python311\Lib\site-packages\flask\app.py", line 867, in full_dispatch_request
    rv = self.dispatch_request()
         ^^^^^^^^^^^^^^^^^^^^^^^
  File "C:\Users\g_and\AppData\Local\Programs\Python\Python311\Lib\site-packages\flask\app.py", line 852, in dispatch_request
    return self.ensure_sync(self.view_functions[rule.endpoint])(**view_args)
           ^^^^^^^^^^^^^^^^^^^^^^^^^^^^^^^^^^^^^^^^^^^^^^^^^^^^^^^^^^^^^^^^^
  File "C:\Users\g_and\Desktop\inventory management system\app\main.py", line 61, in employee_dashboard
    return render_template('employee_dashboard.html')
           ^^^^^^^^^^^^^^^^^^^^^^^^^^^^^^^^^^^^^^^^^^
  File "C:\Users\g_and\AppData\Local\Programs\Python\Python311\Lib\site-packages\flask\templating.py", line 152, in render_template
    return _render(app, template, context)
           ^^^^^^^^^^^^^^^^^^^^^^^^^^^^^^^
  File "C:\Users\g_and\AppData\Local\Programs\Python\Python311\Lib\site-packages\flask\templating.py", line 133, in _render
    rv = template.render(context)
         ^^^^^^^^^^^^^^^^^^^^^^^^
  File "C:\Users\g_and\AppData\Local\Programs\Python\Python311\Lib\site-packages\jinja2\environment.py", line 1301, in render
    self.environment.handle_exception()
  File "C:\Users\g_and\AppData\Local\Programs\Python\Python311\Lib\site-packages\jinja2\environment.py", line 936, in handle_exception
    raise rewrite_traceback_stack(source=source)
  File "C:\Users\g_and\Desktop\inventory management system\templates\employee_dashboard.html", line 137, in top-level template code
    'X-CSRFToken': '{{ csrf_token() }}'
    ^^^^^^^^^^^^^^^^^^^^^^^^^
  File "C:\Users\g_and\AppData\Local\Programs\Python\Python311\Lib\site-packages\jinja2\utils.py", line 83, in from_obj
    if hasattr(obj, "jinja_pass_arg"):
       ^^^^^^^^^^^^^^^^^^^^^^^^^^^^^^
jinja2.exceptions.UndefinedError: 'csrf_token' is undefined
2024-06-03 04:13:56,872 [INFO] app.main Employee abc accessed employee dashboard
2024-06-03 04:14:00,050 [INFO] app.main User abc logged out
2024-06-03 04:14:00,100 [WARNING] app.main Login page has arrived
2024-06-03 04:14:05,565 [INFO] app.main User abc logged in
2024-06-03 04:14:05,610 [INFO] app.main abc accessed the dashboard
2024-06-03 04:14:05,645 [INFO] app.main Employee abc accessed employee dashboard
2024-06-03 04:15:26,459 [WARNING] app.main Login page has arrived
2024-06-03 04:15:27,492 [INFO] app.main Employee None accessed employee dashboard
2024-06-03 04:21:39,508 [INFO] app.main Employee None accessed employee dashboard
2024-06-03 04:21:43,534 [INFO] app.main User None logged out
2024-06-03 04:21:43,577 [WARNING] app.main Login page has arrived
2024-06-03 04:21:49,311 [INFO] app.main User abc logged in
2024-06-03 04:21:49,348 [INFO] app.main abc accessed the dashboard
2024-06-03 04:21:49,369 [INFO] app.main Employee abc accessed employee dashboard
2024-06-03 04:23:34,349 [INFO] app.main User abc accessed password change form
2024-06-03 04:23:34,350 [ERROR] app Exception on /change_password [GET]
Traceback (most recent call last):
  File "C:\Users\g_and\AppData\Local\Programs\Python\Python311\Lib\site-packages\flask\app.py", line 1455, in wsgi_app
    response = self.full_dispatch_request()
               ^^^^^^^^^^^^^^^^^^^^^^^^^^^^
  File "C:\Users\g_and\AppData\Local\Programs\Python\Python311\Lib\site-packages\flask\app.py", line 869, in full_dispatch_request
    rv = self.handle_user_exception(e)
         ^^^^^^^^^^^^^^^^^^^^^^^^^^^^^
  File "C:\Users\g_and\AppData\Local\Programs\Python\Python311\Lib\site-packages\flask\app.py", line 867, in full_dispatch_request
    rv = self.dispatch_request()
         ^^^^^^^^^^^^^^^^^^^^^^^
  File "C:\Users\g_and\AppData\Local\Programs\Python\Python311\Lib\site-packages\flask\app.py", line 852, in dispatch_request
    return self.ensure_sync(self.view_functions[rule.endpoint])(**view_args)
           ^^^^^^^^^^^^^^^^^^^^^^^^^^^^^^^^^^^^^^^^^^^^^^^^^^^^^^^^^^^^^^^^^
  File "C:\Users\g_and\Desktop\inventory management system\app\main.py", line 108, in password_form
    return render_template('password_change_form.html')
           ^^^^^^^^^^^^^^^^^^^^^^^^^^^^^^^^^^^^^^^^^^^^
  File "C:\Users\g_and\AppData\Local\Programs\Python\Python311\Lib\site-packages\flask\templating.py", line 151, in render_template
    template = app.jinja_env.get_or_select_template(template_name_or_list)
               ^^^^^^^^^^^^^^^^^^^^^^^^^^^^^^^^^^^^^^^^^^^^^^^^^^^^^^^^^^^
  File "C:\Users\g_and\AppData\Local\Programs\Python\Python311\Lib\site-packages\jinja2\environment.py", line 1081, in get_or_select_template
    return self.get_template(template_name_or_list, parent, globals)
           ^^^^^^^^^^^^^^^^^^^^^^^^^^^^^^^^^^^^^^^^^^^^^^^^^^^^^^^^^
  File "C:\Users\g_and\AppData\Local\Programs\Python\Python311\Lib\site-packages\jinja2\environment.py", line 1010, in get_template
    return self._load_template(name, globals)
           ^^^^^^^^^^^^^^^^^^^^^^^^^^^^^^^^^^
  File "C:\Users\g_and\AppData\Local\Programs\Python\Python311\Lib\site-packages\jinja2\environment.py", line 969, in _load_template
    template = self.loader.load(self, name, self.make_globals(globals))
               ^^^^^^^^^^^^^^^^^^^^^^^^^^^^^^^^^^^^^^^^^^^^^^^^^^^^^^^^
  File "C:\Users\g_and\AppData\Local\Programs\Python\Python311\Lib\site-packages\jinja2\loaders.py", line 126, in load
    source, filename, uptodate = self.get_source(environment, name)
                                 ^^^^^^^^^^^^^^^^^^^^^^^^^^^^^^^^^^
  File "C:\Users\g_and\AppData\Local\Programs\Python\Python311\Lib\site-packages\flask\templating.py", line 65, in get_source
    return self._get_source_fast(environment, template)
           ^^^^^^^^^^^^^^^^^^^^^^^^^^^^^^^^^^^^^^^^^^^^
  File "C:\Users\g_and\AppData\Local\Programs\Python\Python311\Lib\site-packages\flask\templating.py", line 99, in _get_source_fast
    raise TemplateNotFound(template)
jinja2.exceptions.TemplateNotFound: password_change_form.html
2024-06-03 04:24:09,045 [INFO] app.main User abc accessed password change form
2024-06-03 04:29:50,678 [INFO] app.main User abc accessed password change form
2024-06-03 04:29:50,738 [ERROR] app Exception on /change_password [GET]
Traceback (most recent call last):
  File "C:\Users\g_and\AppData\Local\Programs\Python\Python311\Lib\site-packages\flask\app.py", line 1455, in wsgi_app
    response = self.full_dispatch_request()
               ^^^^^^^^^^^^^^^^^^^^^^^^^^^^
  File "C:\Users\g_and\AppData\Local\Programs\Python\Python311\Lib\site-packages\flask\app.py", line 869, in full_dispatch_request
    rv = self.handle_user_exception(e)
         ^^^^^^^^^^^^^^^^^^^^^^^^^^^^^
  File "C:\Users\g_and\AppData\Local\Programs\Python\Python311\Lib\site-packages\flask\app.py", line 867, in full_dispatch_request
    rv = self.dispatch_request()
         ^^^^^^^^^^^^^^^^^^^^^^^
  File "C:\Users\g_and\AppData\Local\Programs\Python\Python311\Lib\site-packages\flask\app.py", line 852, in dispatch_request
    return self.ensure_sync(self.view_functions[rule.endpoint])(**view_args)
           ^^^^^^^^^^^^^^^^^^^^^^^^^^^^^^^^^^^^^^^^^^^^^^^^^^^^^^^^^^^^^^^^^
  File "C:\Users\g_and\Desktop\inventory management system\app\main.py", line 108, in password_form
    return render_template('password_change_form.html')
           ^^^^^^^^^^^^^^^^^^^^^^^^^^^^^^^^^^^^^^^^^^^^
  File "C:\Users\g_and\AppData\Local\Programs\Python\Python311\Lib\site-packages\flask\templating.py", line 152, in render_template
    return _render(app, template, context)
           ^^^^^^^^^^^^^^^^^^^^^^^^^^^^^^^
  File "C:\Users\g_and\AppData\Local\Programs\Python\Python311\Lib\site-packages\flask\templating.py", line 133, in _render
    rv = template.render(context)
         ^^^^^^^^^^^^^^^^^^^^^^^^
  File "C:\Users\g_and\AppData\Local\Programs\Python\Python311\Lib\site-packages\jinja2\environment.py", line 1301, in render
    self.environment.handle_exception()
  File "C:\Users\g_and\AppData\Local\Programs\Python\Python311\Lib\site-packages\jinja2\environment.py", line 936, in handle_exception
    raise rewrite_traceback_stack(source=source)
  File "C:\Users\g_and\Desktop\inventory management system\templates\password_change_form.html", line 11, in top-level template code
    <form class="form" id="changePasswordForm" action="{{ url_for('api.change_password') }}" method="post">
    ^^^^^^^^^^^^^^^^^^^^^^^^^
  File "C:\Users\g_and\AppData\Local\Programs\Python\Python311\Lib\site-packages\flask\app.py", line 1071, in url_for
    return self.handle_url_build_error(error, endpoint, values)
           ^^^^^^^^^^^^^^^^^^^^^^^^^^^^^^^^^^^^^^^^^^^^^^^^^^^^
  File "C:\Users\g_and\AppData\Local\Programs\Python\Python311\Lib\site-packages\flask\app.py", line 1060, in url_for
    rv = url_adapter.build(  # type: ignore[union-attr]
         ^^^^^^^^^^^^^^^^^^^^^^^^^^^^^^^^^^^^^^^^^^^^^^
  File "C:\Users\g_and\AppData\Local\Programs\Python\Python311\Lib\site-packages\werkzeug\routing\map.py", line 919, in build
    raise BuildError(endpoint, values, method, self)
werkzeug.routing.exceptions.BuildError: Could not build url for endpoint 'api.change_password'. Did you mean 'change_password' instead?
2024-06-03 04:29:54,456 [INFO] app.main User abc logged out
2024-06-03 04:29:54,509 [WARNING] app.main Login page has arrived
2024-06-03 04:29:58,934 [INFO] app.main User abc logged in
2024-06-03 04:29:58,969 [INFO] app.main abc accessed the dashboard
2024-06-03 04:29:58,984 [INFO] app.main Employee abc accessed employee dashboard
2024-06-03 04:30:02,320 [INFO] app.main User abc accessed password change form
2024-06-03 04:30:02,323 [ERROR] app Exception on /change_password [GET]
Traceback (most recent call last):
  File "C:\Users\g_and\AppData\Local\Programs\Python\Python311\Lib\site-packages\flask\app.py", line 1455, in wsgi_app
    response = self.full_dispatch_request()
               ^^^^^^^^^^^^^^^^^^^^^^^^^^^^
  File "C:\Users\g_and\AppData\Local\Programs\Python\Python311\Lib\site-packages\flask\app.py", line 869, in full_dispatch_request
    rv = self.handle_user_exception(e)
         ^^^^^^^^^^^^^^^^^^^^^^^^^^^^^
  File "C:\Users\g_and\AppData\Local\Programs\Python\Python311\Lib\site-packages\flask\app.py", line 867, in full_dispatch_request
    rv = self.dispatch_request()
         ^^^^^^^^^^^^^^^^^^^^^^^
  File "C:\Users\g_and\AppData\Local\Programs\Python\Python311\Lib\site-packages\flask\app.py", line 852, in dispatch_request
    return self.ensure_sync(self.view_functions[rule.endpoint])(**view_args)
           ^^^^^^^^^^^^^^^^^^^^^^^^^^^^^^^^^^^^^^^^^^^^^^^^^^^^^^^^^^^^^^^^^
  File "C:\Users\g_and\Desktop\inventory management system\app\main.py", line 108, in password_form
    return render_template('password_change_form.html')
           ^^^^^^^^^^^^^^^^^^^^^^^^^^^^^^^^^^^^^^^^^^^^
  File "C:\Users\g_and\AppData\Local\Programs\Python\Python311\Lib\site-packages\flask\templating.py", line 152, in render_template
    return _render(app, template, context)
           ^^^^^^^^^^^^^^^^^^^^^^^^^^^^^^^
  File "C:\Users\g_and\AppData\Local\Programs\Python\Python311\Lib\site-packages\flask\templating.py", line 133, in _render
    rv = template.render(context)
         ^^^^^^^^^^^^^^^^^^^^^^^^
  File "C:\Users\g_and\AppData\Local\Programs\Python\Python311\Lib\site-packages\jinja2\environment.py", line 1301, in render
    self.environment.handle_exception()
  File "C:\Users\g_and\AppData\Local\Programs\Python\Python311\Lib\site-packages\jinja2\environment.py", line 936, in handle_exception
    raise rewrite_traceback_stack(source=source)
  File "C:\Users\g_and\Desktop\inventory management system\templates\password_change_form.html", line 11, in top-level template code
    <form class="form" id="changePasswordForm" action="{{ url_for('api.change_password') }}" method="post">
    ^^^^^^^^^^^^^^^^^^^^^^^^^
  File "C:\Users\g_and\AppData\Local\Programs\Python\Python311\Lib\site-packages\flask\app.py", line 1071, in url_for
    return self.handle_url_build_error(error, endpoint, values)
           ^^^^^^^^^^^^^^^^^^^^^^^^^^^^^^^^^^^^^^^^^^^^^^^^^^^^
  File "C:\Users\g_and\AppData\Local\Programs\Python\Python311\Lib\site-packages\flask\app.py", line 1060, in url_for
    rv = url_adapter.build(  # type: ignore[union-attr]
         ^^^^^^^^^^^^^^^^^^^^^^^^^^^^^^^^^^^^^^^^^^^^^^
  File "C:\Users\g_and\AppData\Local\Programs\Python\Python311\Lib\site-packages\werkzeug\routing\map.py", line 919, in build
    raise BuildError(endpoint, values, method, self)
werkzeug.routing.exceptions.BuildError: Could not build url for endpoint 'api.change_password'. Did you mean 'change_password' instead?
2024-06-03 04:30:50,753 [INFO] app.main User abc accessed password change form
2024-06-03 04:39:50,631 [INFO] app.main User abc accessed password change form
2024-06-03 04:39:58,304 [INFO] app.main Password changed for user: abc
2024-06-03 04:41:04,216 [INFO] app.main User abc accessed password change form
2024-06-03 04:41:08,692 [INFO] app.main Password changed for user: abc
2024-06-03 04:41:11,319 [INFO] app.main abc accessed the dashboard
2024-06-03 04:41:11,336 [INFO] app.main Employee abc accessed employee dashboard
2024-06-03 04:41:32,490 [INFO] app.main User abc logged out
2024-06-03 04:41:32,533 [WARNING] app.main Login page has arrived
2024-06-03 04:43:50,041 [INFO] app.main User abc logged in
2024-06-03 04:43:50,073 [INFO] app.main abc accessed the dashboard
2024-06-03 04:43:50,091 [INFO] app.main Employee abc accessed employee dashboard
2024-06-03 04:43:55,063 [INFO] app.main User abc logged out
2024-06-03 04:43:55,111 [WARNING] app.main Login page has arrived
2024-06-03 12:18:43,049 [INFO] app.main User abc logged in
2024-06-03 12:18:43,076 [INFO] app.main abc accessed the dashboard
2024-06-03 12:18:43,090 [INFO] app.main Employee abc accessed employee dashboard
2024-06-03 12:19:59,160 [WARNING] app.main Login page has arrived
2024-06-03 12:20:05,825 [INFO] app.main Employee None accessed employee dashboard
2024-06-03 12:20:06,713 [WARNING] app.main Login page has arrived
2024-06-03 12:36:03,693 [INFO] app.main Employee None accessed employee dashboard
2024-06-03 12:36:06,316 [INFO] app.main User None logged out
2024-06-03 12:36:06,348 [WARNING] app.main Login page has arrived
2024-06-03 12:36:25,789 [INFO] app.main User admin logged in
2024-06-03 12:36:25,827 [INFO] app.main admin accessed the dashboard
2024-06-03 12:36:25,843 [INFO] app.main Admin admin accessed admin dashboard
2024-06-03 12:36:25,869 [ERROR] app.main Exception Could not build url for endpoint 'admin_users'. Did you mean 'add_user' instead? occurred while rendering admin_dashboard for admin
Traceback (most recent call last):
  File "C:\Users\g_and\Desktop\inventory management system\app\main.py", line 32, in admin_dashboard
    return render_template('admin_dashboard.html', items=items_list, employees=employees_list)
           ^^^^^^^^^^^^^^^^^^^^^^^^^^^^^^^^^^^^^^^^^^^^^^^^^^^^^^^^^^^^^^^^^^^^^^^^^^^^^^^^^^^
  File "C:\Users\g_and\AppData\Local\Programs\Python\Python311\Lib\site-packages\flask\templating.py", line 152, in render_template
    return _render(app, template, context)
           ^^^^^^^^^^^^^^^^^^^^^^^^^^^^^^^
  File "C:\Users\g_and\AppData\Local\Programs\Python\Python311\Lib\site-packages\flask\templating.py", line 133, in _render
    rv = template.render(context)
         ^^^^^^^^^^^^^^^^^^^^^^^^
  File "C:\Users\g_and\AppData\Local\Programs\Python\Python311\Lib\site-packages\jinja2\environment.py", line 1301, in render
    self.environment.handle_exception()
  File "C:\Users\g_and\AppData\Local\Programs\Python\Python311\Lib\site-packages\jinja2\environment.py", line 936, in handle_exception
    raise rewrite_traceback_stack(source=source)
  File "C:\Users\g_and\Desktop\inventory management system\templates\admin_dashboard.html", line 166, in top-level template code
    <div class="card" onclick="window.location.href='{{ url_for('admin_users') }}'">
    ^^^^^^^^^^^^^^^^^^^^^^^^^
  File "C:\Users\g_and\AppData\Local\Programs\Python\Python311\Lib\site-packages\flask\app.py", line 1071, in url_for
    return self.handle_url_build_error(error, endpoint, values)
           ^^^^^^^^^^^^^^^^^^^^^^^^^^^^^^^^^^^^^^^^^^^^^^^^^^^^
  File "C:\Users\g_and\AppData\Local\Programs\Python\Python311\Lib\site-packages\flask\app.py", line 1060, in url_for
    rv = url_adapter.build(  # type: ignore[union-attr]
         ^^^^^^^^^^^^^^^^^^^^^^^^^^^^^^^^^^^^^^^^^^^^^^
  File "C:\Users\g_and\AppData\Local\Programs\Python\Python311\Lib\site-packages\werkzeug\routing\map.py", line 919, in build
    raise BuildError(endpoint, values, method, self)
werkzeug.routing.exceptions.BuildError: Could not build url for endpoint 'admin_users'. Did you mean 'add_user' instead?
2024-06-03 12:48:59,668 [INFO] app.main Admin admin accessed admin dashboard
2024-06-03 12:49:40,181 [INFO] app.main User admin accessed password change form
2024-06-03 12:49:45,656 [INFO] app.main admin accessed the dashboard
2024-06-03 12:49:45,670 [INFO] app.main Admin admin accessed admin dashboard
2024-06-03 12:49:48,227 [INFO] app.main User admin logged out
2024-06-03 12:49:48,258 [WARNING] app.main Login page has arrived
2024-06-03 12:50:03,522 [INFO] app.main Admin None accessed admin dashboard
2024-06-03 12:50:05,678 [INFO] app.main Admin None accessed admin dashboard
2024-06-03 12:52:45,555 [WARNING] app.main Unauthorized access attempt by None
2024-06-03 13:15:40,142 [INFO] app.main User None accessed password change form
2024-06-03 13:15:42,870 [INFO] app.main None accessed the dashboard
2024-06-03 13:15:42,871 [ERROR] app Exception on /dashboard [GET]
Traceback (most recent call last):
  File "C:\Users\g_and\AppData\Local\Programs\Python\Python311\Lib\site-packages\flask\app.py", line 1455, in wsgi_app
    response = self.full_dispatch_request()
               ^^^^^^^^^^^^^^^^^^^^^^^^^^^^
  File "C:\Users\g_and\AppData\Local\Programs\Python\Python311\Lib\site-packages\flask\app.py", line 869, in full_dispatch_request
    rv = self.handle_user_exception(e)
         ^^^^^^^^^^^^^^^^^^^^^^^^^^^^^
  File "C:\Users\g_and\AppData\Local\Programs\Python\Python311\Lib\site-packages\flask\app.py", line 867, in full_dispatch_request
    rv = self.dispatch_request()
         ^^^^^^^^^^^^^^^^^^^^^^^
  File "C:\Users\g_and\AppData\Local\Programs\Python\Python311\Lib\site-packages\flask\app.py", line 852, in dispatch_request
    return self.ensure_sync(self.view_functions[rule.endpoint])(**view_args)
           ^^^^^^^^^^^^^^^^^^^^^^^^^^^^^^^^^^^^^^^^^^^^^^^^^^^^^^^^^^^^^^^^^
  File "C:\Users\g_and\Desktop\inventory management system\app\main.py", line 31, in dashboard
    return redirect('/admin_dashboard' if session['is_admin'] else '/employee_dashboard')
                                          ~~~~~~~^^^^^^^^^^^^
  File "C:\Users\g_and\AppData\Local\Programs\Python\Python311\Lib\site-packages\flask\sessions.py", line 79, in __getitem__
    return super().__getitem__(key)
           ^^^^^^^^^^^^^^^^^^^^^^^^
KeyError: 'is_admin'
2024-06-03 13:17:14,193 [WARNING] app.main Login page has arrived
2024-06-03 13:19:57,175 [INFO] app.main User abc logged in
2024-06-03 13:19:57,208 [INFO] app.main abc accessed the dashboard
2024-06-03 13:19:57,219 [INFO] app.main Employee abc accessed employee dashboard
2024-06-03 13:20:02,948 [INFO] app.main User abc logged out
2024-06-03 13:20:02,977 [WARNING] app.main Login page has arrived
2024-06-03 13:20:09,514 [INFO] app.main User admin logged in
2024-06-03 13:20:09,547 [INFO] app.main admin accessed the dashboard
2024-06-03 13:20:09,562 [INFO] app.main Admin admin accessed admin dashboard
2024-06-03 13:20:15,520 [WARNING] app.main Login page has arrived
2024-06-03 13:23:45,510 [WARNING] app.main Login page has arrived
2024-06-03 13:24:03,521 [INFO] app.main User admin logged in
2024-06-03 13:24:03,554 [INFO] app.main admin accessed the dashboard
2024-06-03 13:24:03,571 [INFO] app.main Admin admin accessed admin dashboard
2024-06-03 13:24:15,829 [INFO] app.main User admin logged out
2024-06-03 13:24:15,859 [WARNING] app.main Login page has arrived
2024-06-03 13:24:17,789 [WARNING] app.main Unauthorized access attempt by None
2024-06-03 13:24:50,381 [WARNING] app.main Login page has arrived
2024-06-03 13:25:05,870 [WARNING] app.main Login page has arrived
2024-06-03 13:25:16,221 [WARNING] app.main Login page has arrived
2024-06-03 13:25:26,892 [INFO] app.main User admin logged in
2024-06-03 13:25:26,927 [INFO] app.main admin accessed the dashboard
2024-06-03 13:25:26,942 [INFO] app.main Admin admin accessed admin dashboard
2024-06-03 14:53:27,075 [WARNING] app.main Login page has arrived
2024-06-03 14:53:32,776 [INFO] app.main User admin logged in
2024-06-03 14:53:32,807 [INFO] app.main admin accessed the dashboard
2024-06-03 14:53:32,829 [INFO] app.main Admin admin accessed admin dashboard
2024-06-03 14:53:34,856 [ERROR] app Exception on /admin/users [GET]
Traceback (most recent call last):
  File "C:\Users\g_and\AppData\Local\Programs\Python\Python311\Lib\site-packages\flask\app.py", line 1455, in wsgi_app
    response = self.full_dispatch_request()
               ^^^^^^^^^^^^^^^^^^^^^^^^^^^^
  File "C:\Users\g_and\AppData\Local\Programs\Python\Python311\Lib\site-packages\flask\app.py", line 869, in full_dispatch_request
    rv = self.handle_user_exception(e)
         ^^^^^^^^^^^^^^^^^^^^^^^^^^^^^
  File "C:\Users\g_and\AppData\Local\Programs\Python\Python311\Lib\site-packages\flask\app.py", line 867, in full_dispatch_request
    rv = self.dispatch_request()
         ^^^^^^^^^^^^^^^^^^^^^^^
  File "C:\Users\g_and\AppData\Local\Programs\Python\Python311\Lib\site-packages\flask\app.py", line 852, in dispatch_request
    return self.ensure_sync(self.view_functions[rule.endpoint])(**view_args)
           ^^^^^^^^^^^^^^^^^^^^^^^^^^^^^^^^^^^^^^^^^^^^^^^^^^^^^^^^^^^^^^^^^
  File "C:\Users\g_and\Desktop\inventory management system\app\main.py", line 15, in decorated_function
    return f(*args, **kwargs)
           ^^^^^^^^^^^^^^^^^^
  File "C:\Users\g_and\Desktop\inventory management system\app\main.py", line 206, in admin_users
    return render_template('admin_users.html', users=users)
           ^^^^^^^^^^^^^^^^^^^^^^^^^^^^^^^^^^^^^^^^^^^^^^^^
  File "C:\Users\g_and\AppData\Local\Programs\Python\Python311\Lib\site-packages\flask\templating.py", line 152, in render_template
    return _render(app, template, context)
           ^^^^^^^^^^^^^^^^^^^^^^^^^^^^^^^
  File "C:\Users\g_and\AppData\Local\Programs\Python\Python311\Lib\site-packages\flask\templating.py", line 133, in _render
    rv = template.render(context)
         ^^^^^^^^^^^^^^^^^^^^^^^^
  File "C:\Users\g_and\AppData\Local\Programs\Python\Python311\Lib\site-packages\jinja2\environment.py", line 1301, in render
    self.environment.handle_exception()
  File "C:\Users\g_and\AppData\Local\Programs\Python\Python311\Lib\site-packages\jinja2\environment.py", line 936, in handle_exception
    raise rewrite_traceback_stack(source=source)
  File "C:\Users\g_and\Desktop\inventory management system\templates\admin_users.html", line 116, in top-level template code
    fetch('{{ url_for("get_users") }}')
    ^^^^^^^^^^^^^^^^^^^^^^^^^
  File "C:\Users\g_and\AppData\Local\Programs\Python\Python311\Lib\site-packages\flask\app.py", line 1071, in url_for
    return self.handle_url_build_error(error, endpoint, values)
           ^^^^^^^^^^^^^^^^^^^^^^^^^^^^^^^^^^^^^^^^^^^^^^^^^^^^
  File "C:\Users\g_and\AppData\Local\Programs\Python\Python311\Lib\site-packages\flask\app.py", line 1060, in url_for
    rv = url_adapter.build(  # type: ignore[union-attr]
         ^^^^^^^^^^^^^^^^^^^^^^^^^^^^^^^^^^^^^^^^^^^^^^
  File "C:\Users\g_and\AppData\Local\Programs\Python\Python311\Lib\site-packages\werkzeug\routing\map.py", line 919, in build
    raise BuildError(endpoint, values, method, self)
werkzeug.routing.exceptions.BuildError: Could not build url for endpoint 'get_users'. Did you mean 'del_user' instead?
2024-06-03 15:02:35,962 [WARNING] app.main Login page has arrived
2024-06-03 15:02:41,750 [INFO] app.main User admin logged in
2024-06-03 15:02:41,784 [INFO] app.main admin accessed the dashboard
2024-06-03 15:02:41,801 [INFO] app.main Admin admin accessed admin dashboard
2024-06-03 15:05:04,120 [ERROR] app.main Exception 'NoneType' object has no attribute 'username' occurred while deleting user None
Traceback (most recent call last):
  File "C:\Users\g_and\Desktop\inventory management system\app\main.py", line 188, in del_user
    if user.username == 'admin':
       ^^^^^^^^^^^^^
AttributeError: 'NoneType' object has no attribute 'username'
2024-06-03 15:09:57,705 [INFO] app.main User hh deleted by admin admin
2024-06-03 15:10:51,303 [ERROR] app.main Exception (MySQLdb.IntegrityError) (1364, "Field 'username' doesn't have a default value")
[SQL: INSERT INTO user (password, email, is_admin, first_login) VALUES (%s, %s, %s, %s)]
[parameters: (None, None, False, True)]
(Background on this error at: https://sqlalche.me/e/20/gkpj) occurred while adding user None
Traceback (most recent call last):
  File "C:\Users\g_and\AppData\Local\Programs\Python\Python311\Lib\site-packages\sqlalchemy\engine\base.py", line 1971, in _exec_single_context
    self.dialect.do_execute(
  File "C:\Users\g_and\AppData\Local\Programs\Python\Python311\Lib\site-packages\sqlalchemy\engine\default.py", line 919, in do_execute
    cursor.execute(statement, parameters)
  File "C:\Users\g_and\AppData\Local\Programs\Python\Python311\Lib\site-packages\MySQLdb\cursors.py", line 179, in execute
    res = self._query(mogrified_query)
          ^^^^^^^^^^^^^^^^^^^^^^^^^^^^
  File "C:\Users\g_and\AppData\Local\Programs\Python\Python311\Lib\site-packages\MySQLdb\cursors.py", line 330, in _query
    db.query(q)
  File "C:\Users\g_and\AppData\Local\Programs\Python\Python311\Lib\site-packages\MySQLdb\connections.py", line 257, in query
    _mysql.connection.query(self, query)
MySQLdb.IntegrityError: (1364, "Field 'username' doesn't have a default value")

The above exception was the direct cause of the following exception:

Traceback (most recent call last):
  File "C:\Users\g_and\Desktop\inventory management system\app\main.py", line 173, in admin_add_user
    db.session.commit()
  File "C:\Users\g_and\AppData\Local\Programs\Python\Python311\Lib\site-packages\sqlalchemy\orm\scoping.py", line 597, in commit
    return self._proxied.commit()
           ^^^^^^^^^^^^^^^^^^^^^^
  File "C:\Users\g_and\AppData\Local\Programs\Python\Python311\Lib\site-packages\sqlalchemy\orm\session.py", line 1972, in commit
    trans.commit(_to_root=True)
  File "<string>", line 2, in commit
  File "C:\Users\g_and\AppData\Local\Programs\Python\Python311\Lib\site-packages\sqlalchemy\orm\state_changes.py", line 139, in _go
    ret_value = fn(self, *arg, **kw)
                ^^^^^^^^^^^^^^^^^^^^
  File "C:\Users\g_and\AppData\Local\Programs\Python\Python311\Lib\site-packages\sqlalchemy\orm\session.py", line 1257, in commit
    self._prepare_impl()
  File "<string>", line 2, in _prepare_impl
  File "C:\Users\g_and\AppData\Local\Programs\Python\Python311\Lib\site-packages\sqlalchemy\orm\state_changes.py", line 139, in _go
    ret_value = fn(self, *arg, **kw)
                ^^^^^^^^^^^^^^^^^^^^
  File "C:\Users\g_and\AppData\Local\Programs\Python\Python311\Lib\site-packages\sqlalchemy\orm\session.py", line 1232, in _prepare_impl
    self.session.flush()
  File "C:\Users\g_and\AppData\Local\Programs\Python\Python311\Lib\site-packages\sqlalchemy\orm\session.py", line 4296, in flush
    self._flush(objects)
  File "C:\Users\g_and\AppData\Local\Programs\Python\Python311\Lib\site-packages\sqlalchemy\orm\session.py", line 4431, in _flush
    with util.safe_reraise():
  File "C:\Users\g_and\AppData\Local\Programs\Python\Python311\Lib\site-packages\sqlalchemy\util\langhelpers.py", line 146, in __exit__
    raise exc_value.with_traceback(exc_tb)
  File "C:\Users\g_and\AppData\Local\Programs\Python\Python311\Lib\site-packages\sqlalchemy\orm\session.py", line 4392, in _flush
    flush_context.execute()
  File "C:\Users\g_and\AppData\Local\Programs\Python\Python311\Lib\site-packages\sqlalchemy\orm\unitofwork.py", line 466, in execute
    rec.execute(self)
  File "C:\Users\g_and\AppData\Local\Programs\Python\Python311\Lib\site-packages\sqlalchemy\orm\unitofwork.py", line 642, in execute
    util.preloaded.orm_persistence.save_obj(
  File "C:\Users\g_and\AppData\Local\Programs\Python\Python311\Lib\site-packages\sqlalchemy\orm\persistence.py", line 93, in save_obj
    _emit_insert_statements(
  File "C:\Users\g_and\AppData\Local\Programs\Python\Python311\Lib\site-packages\sqlalchemy\orm\persistence.py", line 1233, in _emit_insert_statements
    result = connection.execute(
             ^^^^^^^^^^^^^^^^^^^
  File "C:\Users\g_and\AppData\Local\Programs\Python\Python311\Lib\site-packages\sqlalchemy\engine\base.py", line 1422, in execute
    return meth(
           ^^^^^
  File "C:\Users\g_and\AppData\Local\Programs\Python\Python311\Lib\site-packages\sqlalchemy\sql\elements.py", line 514, in _execute_on_connection
    return connection._execute_clauseelement(
           ^^^^^^^^^^^^^^^^^^^^^^^^^^^^^^^^^^
  File "C:\Users\g_and\AppData\Local\Programs\Python\Python311\Lib\site-packages\sqlalchemy\engine\base.py", line 1644, in _execute_clauseelement
    ret = self._execute_context(
          ^^^^^^^^^^^^^^^^^^^^^^
  File "C:\Users\g_and\AppData\Local\Programs\Python\Python311\Lib\site-packages\sqlalchemy\engine\base.py", line 1850, in _execute_context
    return self._exec_single_context(
           ^^^^^^^^^^^^^^^^^^^^^^^^^^
  File "C:\Users\g_and\AppData\Local\Programs\Python\Python311\Lib\site-packages\sqlalchemy\engine\base.py", line 1990, in _exec_single_context
    self._handle_dbapi_exception(
  File "C:\Users\g_and\AppData\Local\Programs\Python\Python311\Lib\site-packages\sqlalchemy\engine\base.py", line 2357, in _handle_dbapi_exception
    raise sqlalchemy_exception.with_traceback(exc_info[2]) from e
  File "C:\Users\g_and\AppData\Local\Programs\Python\Python311\Lib\site-packages\sqlalchemy\engine\base.py", line 1971, in _exec_single_context
    self.dialect.do_execute(
  File "C:\Users\g_and\AppData\Local\Programs\Python\Python311\Lib\site-packages\sqlalchemy\engine\default.py", line 919, in do_execute
    cursor.execute(statement, parameters)
  File "C:\Users\g_and\AppData\Local\Programs\Python\Python311\Lib\site-packages\MySQLdb\cursors.py", line 179, in execute
    res = self._query(mogrified_query)
          ^^^^^^^^^^^^^^^^^^^^^^^^^^^^
  File "C:\Users\g_and\AppData\Local\Programs\Python\Python311\Lib\site-packages\MySQLdb\cursors.py", line 330, in _query
    db.query(q)
  File "C:\Users\g_and\AppData\Local\Programs\Python\Python311\Lib\site-packages\MySQLdb\connections.py", line 257, in query
    _mysql.connection.query(self, query)
sqlalchemy.exc.IntegrityError: (MySQLdb.IntegrityError) (1364, "Field 'username' doesn't have a default value")
[SQL: INSERT INTO user (password, email, is_admin, first_login) VALUES (%s, %s, %s, %s)]
[parameters: (None, None, False, True)]
(Background on this error at: https://sqlalche.me/e/20/gkpj)
2024-06-03 15:13:57,334 [INFO] app.main User po added by admin admin
2024-06-03 16:04:49,182 [WARNING] app.main Login page has arrived
2024-06-03 16:04:54,897 [INFO] app.main User admin logged in
2024-06-03 16:04:54,925 [INFO] app.main admin accessed the dashboard
2024-06-03 16:04:54,941 [INFO] app.main Admin admin accessed admin dashboard
2024-06-03 16:10:12,693 [INFO] app.main Admin admin accessed admin dashboard
2024-06-03 16:10:14,284 [ERROR] app Exception on /admin/items [GET]
Traceback (most recent call last):
  File "C:\Users\g_and\AppData\Local\Programs\Python\Python311\Lib\site-packages\flask\app.py", line 1455, in wsgi_app
    response = self.full_dispatch_request()
               ^^^^^^^^^^^^^^^^^^^^^^^^^^^^
  File "C:\Users\g_and\AppData\Local\Programs\Python\Python311\Lib\site-packages\flask\app.py", line 869, in full_dispatch_request
    rv = self.handle_user_exception(e)
         ^^^^^^^^^^^^^^^^^^^^^^^^^^^^^
  File "C:\Users\g_and\AppData\Local\Programs\Python\Python311\Lib\site-packages\flask\app.py", line 867, in full_dispatch_request
    rv = self.dispatch_request()
         ^^^^^^^^^^^^^^^^^^^^^^^
  File "C:\Users\g_and\AppData\Local\Programs\Python\Python311\Lib\site-packages\flask\app.py", line 852, in dispatch_request
    return self.ensure_sync(self.view_functions[rule.endpoint])(**view_args)
           ^^^^^^^^^^^^^^^^^^^^^^^^^^^^^^^^^^^^^^^^^^^^^^^^^^^^^^^^^^^^^^^^^
  File "C:\Users\g_and\Desktop\inventory management system\app\main.py", line 66, in admin_items
    return render_template('admin_items.html')
           ^^^^^^^^^^^^^^^^^^^^^^^^^^^^^^^^^^^
  File "C:\Users\g_and\AppData\Local\Programs\Python\Python311\Lib\site-packages\flask\templating.py", line 152, in render_template
    return _render(app, template, context)
           ^^^^^^^^^^^^^^^^^^^^^^^^^^^^^^^
  File "C:\Users\g_and\AppData\Local\Programs\Python\Python311\Lib\site-packages\flask\templating.py", line 133, in _render
    rv = template.render(context)
         ^^^^^^^^^^^^^^^^^^^^^^^^
  File "C:\Users\g_and\AppData\Local\Programs\Python\Python311\Lib\site-packages\jinja2\environment.py", line 1301, in render
    self.environment.handle_exception()
  File "C:\Users\g_and\AppData\Local\Programs\Python\Python311\Lib\site-packages\jinja2\environment.py", line 936, in handle_exception
    raise rewrite_traceback_stack(source=source)
  File "C:\Users\g_and\Desktop\inventory management system\templates\admin_items.html", line 106, in top-level template code
    <a href="{{ url_for('item_assignment_page') }}">
    ^^^^^^^^^^^^^^^^^^^^^^^^^
  File "C:\Users\g_and\AppData\Local\Programs\Python\Python311\Lib\site-packages\flask\app.py", line 1071, in url_for
    return self.handle_url_build_error(error, endpoint, values)
           ^^^^^^^^^^^^^^^^^^^^^^^^^^^^^^^^^^^^^^^^^^^^^^^^^^^^
  File "C:\Users\g_and\AppData\Local\Programs\Python\Python311\Lib\site-packages\flask\app.py", line 1060, in url_for
    rv = url_adapter.build(  # type: ignore[union-attr]
         ^^^^^^^^^^^^^^^^^^^^^^^^^^^^^^^^^^^^^^^^^^^^^^
  File "C:\Users\g_and\AppData\Local\Programs\Python\Python311\Lib\site-packages\werkzeug\routing\map.py", line 919, in build
    raise BuildError(endpoint, values, method, self)
werkzeug.routing.exceptions.BuildError: Could not build url for endpoint 'item_assignment_page'. Did you mean 'item_assignment' instead?
2024-06-03 16:13:55,746 [ERROR] app.main Exception 'warranty' is an invalid keyword argument for Item occurred while adding item 123123
Traceback (most recent call last):
  File "C:\Users\g_and\Desktop\inventory management system\app\main.py", line 236, in add_item
    new_item = Item(item_name=item_name, serial_number=serial_number, bill_no=bill_no, date_of_purchase=date_of_purchase, assigned_to=assigned_to, warranty=warranty)
               ^^^^^^^^^^^^^^^^^^^^^^^^^^^^^^^^^^^^^^^^^^^^^^^^^^^^^^^^^^^^^^^^^^^^^^^^^^^^^^^^^^^^^^^^^^^^^^^^^^^^^^^^^^^^^^^^^^^^^^^^^^^^^^^^^^^^^^^^^^^^^^^^^^^^^^
  File "<string>", line 4, in __init__
  File "C:\Users\g_and\AppData\Local\Programs\Python\Python311\Lib\site-packages\sqlalchemy\orm\state.py", line 564, in _initialize_instance
    with util.safe_reraise():
  File "C:\Users\g_and\AppData\Local\Programs\Python\Python311\Lib\site-packages\sqlalchemy\util\langhelpers.py", line 146, in __exit__
    raise exc_value.with_traceback(exc_tb)
  File "C:\Users\g_and\AppData\Local\Programs\Python\Python311\Lib\site-packages\sqlalchemy\orm\state.py", line 562, in _initialize_instance
    manager.original_init(*mixed[1:], **kwargs)
  File "C:\Users\g_and\AppData\Local\Programs\Python\Python311\Lib\site-packages\sqlalchemy\orm\decl_base.py", line 2139, in _declarative_constructor
    raise TypeError(
TypeError: 'warranty' is an invalid keyword argument for Item
2024-06-03 16:15:33,813 [INFO] app.main Fetched employee and item list
2024-06-03 16:20:21,341 [ERROR] app.main Exception (MySQLdb.OperationalError) (1366, "Incorrect integer value: '' for column 'serial_number' at row 1")
[SQL: INSERT INTO items (item_name, serial_number, bill_no, date_of_purchase, assigned_to, warranty) VALUES (%s, %s, %s, %s, %s, %s)]
[parameters: ('laptop', '', '', '', '', '')]
(Background on this error at: https://sqlalche.me/e/20/e3q8) occurred while adding item 
Traceback (most recent call last):
  File "C:\Users\g_and\AppData\Local\Programs\Python\Python311\Lib\site-packages\sqlalchemy\engine\base.py", line 1971, in _exec_single_context
    self.dialect.do_execute(
  File "C:\Users\g_and\AppData\Local\Programs\Python\Python311\Lib\site-packages\sqlalchemy\engine\default.py", line 919, in do_execute
    cursor.execute(statement, parameters)
  File "C:\Users\g_and\AppData\Local\Programs\Python\Python311\Lib\site-packages\MySQLdb\cursors.py", line 179, in execute
    res = self._query(mogrified_query)
          ^^^^^^^^^^^^^^^^^^^^^^^^^^^^
  File "C:\Users\g_and\AppData\Local\Programs\Python\Python311\Lib\site-packages\MySQLdb\cursors.py", line 330, in _query
    db.query(q)
  File "C:\Users\g_and\AppData\Local\Programs\Python\Python311\Lib\site-packages\MySQLdb\connections.py", line 257, in query
    _mysql.connection.query(self, query)
MySQLdb.OperationalError: (1366, "Incorrect integer value: '' for column 'serial_number' at row 1")

The above exception was the direct cause of the following exception:

Traceback (most recent call last):
  File "C:\Users\g_and\Desktop\inventory management system\app\main.py", line 238, in add_item
    db.session.commit()
  File "C:\Users\g_and\AppData\Local\Programs\Python\Python311\Lib\site-packages\sqlalchemy\orm\scoping.py", line 597, in commit
    return self._proxied.commit()
           ^^^^^^^^^^^^^^^^^^^^^^
  File "C:\Users\g_and\AppData\Local\Programs\Python\Python311\Lib\site-packages\sqlalchemy\orm\session.py", line 1972, in commit
    trans.commit(_to_root=True)
  File "<string>", line 2, in commit
  File "C:\Users\g_and\AppData\Local\Programs\Python\Python311\Lib\site-packages\sqlalchemy\orm\state_changes.py", line 139, in _go
    ret_value = fn(self, *arg, **kw)
                ^^^^^^^^^^^^^^^^^^^^
  File "C:\Users\g_and\AppData\Local\Programs\Python\Python311\Lib\site-packages\sqlalchemy\orm\session.py", line 1257, in commit
    self._prepare_impl()
  File "<string>", line 2, in _prepare_impl
  File "C:\Users\g_and\AppData\Local\Programs\Python\Python311\Lib\site-packages\sqlalchemy\orm\state_changes.py", line 139, in _go
    ret_value = fn(self, *arg, **kw)
                ^^^^^^^^^^^^^^^^^^^^
  File "C:\Users\g_and\AppData\Local\Programs\Python\Python311\Lib\site-packages\sqlalchemy\orm\session.py", line 1232, in _prepare_impl
    self.session.flush()
  File "C:\Users\g_and\AppData\Local\Programs\Python\Python311\Lib\site-packages\sqlalchemy\orm\session.py", line 4296, in flush
    self._flush(objects)
  File "C:\Users\g_and\AppData\Local\Programs\Python\Python311\Lib\site-packages\sqlalchemy\orm\session.py", line 4431, in _flush
    with util.safe_reraise():
  File "C:\Users\g_and\AppData\Local\Programs\Python\Python311\Lib\site-packages\sqlalchemy\util\langhelpers.py", line 146, in __exit__
    raise exc_value.with_traceback(exc_tb)
  File "C:\Users\g_and\AppData\Local\Programs\Python\Python311\Lib\site-packages\sqlalchemy\orm\session.py", line 4392, in _flush
    flush_context.execute()
  File "C:\Users\g_and\AppData\Local\Programs\Python\Python311\Lib\site-packages\sqlalchemy\orm\unitofwork.py", line 466, in execute
    rec.execute(self)
  File "C:\Users\g_and\AppData\Local\Programs\Python\Python311\Lib\site-packages\sqlalchemy\orm\unitofwork.py", line 642, in execute
    util.preloaded.orm_persistence.save_obj(
  File "C:\Users\g_and\AppData\Local\Programs\Python\Python311\Lib\site-packages\sqlalchemy\orm\persistence.py", line 93, in save_obj
    _emit_insert_statements(
  File "C:\Users\g_and\AppData\Local\Programs\Python\Python311\Lib\site-packages\sqlalchemy\orm\persistence.py", line 1233, in _emit_insert_statements
    result = connection.execute(
             ^^^^^^^^^^^^^^^^^^^
  File "C:\Users\g_and\AppData\Local\Programs\Python\Python311\Lib\site-packages\sqlalchemy\engine\base.py", line 1422, in execute
    return meth(
           ^^^^^
  File "C:\Users\g_and\AppData\Local\Programs\Python\Python311\Lib\site-packages\sqlalchemy\sql\elements.py", line 514, in _execute_on_connection
    return connection._execute_clauseelement(
           ^^^^^^^^^^^^^^^^^^^^^^^^^^^^^^^^^^
  File "C:\Users\g_and\AppData\Local\Programs\Python\Python311\Lib\site-packages\sqlalchemy\engine\base.py", line 1644, in _execute_clauseelement
    ret = self._execute_context(
          ^^^^^^^^^^^^^^^^^^^^^^
  File "C:\Users\g_and\AppData\Local\Programs\Python\Python311\Lib\site-packages\sqlalchemy\engine\base.py", line 1850, in _execute_context
    return self._exec_single_context(
           ^^^^^^^^^^^^^^^^^^^^^^^^^^
  File "C:\Users\g_and\AppData\Local\Programs\Python\Python311\Lib\site-packages\sqlalchemy\engine\base.py", line 1990, in _exec_single_context
    self._handle_dbapi_exception(
  File "C:\Users\g_and\AppData\Local\Programs\Python\Python311\Lib\site-packages\sqlalchemy\engine\base.py", line 2357, in _handle_dbapi_exception
    raise sqlalchemy_exception.with_traceback(exc_info[2]) from e
  File "C:\Users\g_and\AppData\Local\Programs\Python\Python311\Lib\site-packages\sqlalchemy\engine\base.py", line 1971, in _exec_single_context
    self.dialect.do_execute(
  File "C:\Users\g_and\AppData\Local\Programs\Python\Python311\Lib\site-packages\sqlalchemy\engine\default.py", line 919, in do_execute
    cursor.execute(statement, parameters)
  File "C:\Users\g_and\AppData\Local\Programs\Python\Python311\Lib\site-packages\MySQLdb\cursors.py", line 179, in execute
    res = self._query(mogrified_query)
          ^^^^^^^^^^^^^^^^^^^^^^^^^^^^
  File "C:\Users\g_and\AppData\Local\Programs\Python\Python311\Lib\site-packages\MySQLdb\cursors.py", line 330, in _query
    db.query(q)
  File "C:\Users\g_and\AppData\Local\Programs\Python\Python311\Lib\site-packages\MySQLdb\connections.py", line 257, in query
    _mysql.connection.query(self, query)
sqlalchemy.exc.OperationalError: (MySQLdb.OperationalError) (1366, "Incorrect integer value: '' for column 'serial_number' at row 1")
[SQL: INSERT INTO items (item_name, serial_number, bill_no, date_of_purchase, assigned_to, warranty) VALUES (%s, %s, %s, %s, %s, %s)]
[parameters: ('laptop', '', '', '', '', '')]
(Background on this error at: https://sqlalche.me/e/20/e3q8)
2024-06-03 16:22:12,139 [ERROR] app Exception on /item/add [POST]
Traceback (most recent call last):
  File "C:\Users\g_and\AppData\Local\Programs\Python\Python311\Lib\site-packages\flask\app.py", line 1455, in wsgi_app
    response = self.full_dispatch_request()
               ^^^^^^^^^^^^^^^^^^^^^^^^^^^^
  File "C:\Users\g_and\AppData\Local\Programs\Python\Python311\Lib\site-packages\flask\app.py", line 869, in full_dispatch_request
    rv = self.handle_user_exception(e)
         ^^^^^^^^^^^^^^^^^^^^^^^^^^^^^
  File "C:\Users\g_and\AppData\Local\Programs\Python\Python311\Lib\site-packages\flask\app.py", line 867, in full_dispatch_request
    rv = self.dispatch_request()
         ^^^^^^^^^^^^^^^^^^^^^^^
  File "C:\Users\g_and\AppData\Local\Programs\Python\Python311\Lib\site-packages\flask\app.py", line 852, in dispatch_request
    return self.ensure_sync(self.view_functions[rule.endpoint])(**view_args)
           ^^^^^^^^^^^^^^^^^^^^^^^^^^^^^^^^^^^^^^^^^^^^^^^^^^^^^^^^^^^^^^^^^
  File "C:\Users\g_and\Desktop\inventory management system\app\main.py", line 15, in decorated_function
    return f(*args, **kwargs)
           ^^^^^^^^^^^^^^^^^^
  File "C:\Users\g_and\Desktop\inventory management system\app\main.py", line 229, in add_item
    serial_number = int(data.get('serial_number'))
                    ^^^^^^^^^^^^^^^^^^^^^^^^^^^^^^
ValueError: invalid literal for int() with base 10: ''
2024-06-03 16:22:15,490 [ERROR] app Exception on /item/add [POST]
Traceback (most recent call last):
  File "C:\Users\g_and\AppData\Local\Programs\Python\Python311\Lib\site-packages\flask\app.py", line 1455, in wsgi_app
    response = self.full_dispatch_request()
               ^^^^^^^^^^^^^^^^^^^^^^^^^^^^
  File "C:\Users\g_and\AppData\Local\Programs\Python\Python311\Lib\site-packages\flask\app.py", line 869, in full_dispatch_request
    rv = self.handle_user_exception(e)
         ^^^^^^^^^^^^^^^^^^^^^^^^^^^^^
  File "C:\Users\g_and\AppData\Local\Programs\Python\Python311\Lib\site-packages\flask\app.py", line 867, in full_dispatch_request
    rv = self.dispatch_request()
         ^^^^^^^^^^^^^^^^^^^^^^^
  File "C:\Users\g_and\AppData\Local\Programs\Python\Python311\Lib\site-packages\flask\app.py", line 852, in dispatch_request
    return self.ensure_sync(self.view_functions[rule.endpoint])(**view_args)
           ^^^^^^^^^^^^^^^^^^^^^^^^^^^^^^^^^^^^^^^^^^^^^^^^^^^^^^^^^^^^^^^^^
  File "C:\Users\g_and\Desktop\inventory management system\app\main.py", line 15, in decorated_function
    return f(*args, **kwargs)
           ^^^^^^^^^^^^^^^^^^
  File "C:\Users\g_and\Desktop\inventory management system\app\main.py", line 229, in add_item
    serial_number = int(data.get('serial_number'))
                    ^^^^^^^^^^^^^^^^^^^^^^^^^^^^^^
ValueError: invalid literal for int() with base 10: ''
2024-06-03 16:22:32,802 [ERROR] app Exception on /item/add [POST]
Traceback (most recent call last):
  File "C:\Users\g_and\AppData\Local\Programs\Python\Python311\Lib\site-packages\flask\app.py", line 1455, in wsgi_app
    response = self.full_dispatch_request()
               ^^^^^^^^^^^^^^^^^^^^^^^^^^^^
  File "C:\Users\g_and\AppData\Local\Programs\Python\Python311\Lib\site-packages\flask\app.py", line 869, in full_dispatch_request
    rv = self.handle_user_exception(e)
         ^^^^^^^^^^^^^^^^^^^^^^^^^^^^^
  File "C:\Users\g_and\AppData\Local\Programs\Python\Python311\Lib\site-packages\flask\app.py", line 867, in full_dispatch_request
    rv = self.dispatch_request()
         ^^^^^^^^^^^^^^^^^^^^^^^
  File "C:\Users\g_and\AppData\Local\Programs\Python\Python311\Lib\site-packages\flask\app.py", line 852, in dispatch_request
    return self.ensure_sync(self.view_functions[rule.endpoint])(**view_args)
           ^^^^^^^^^^^^^^^^^^^^^^^^^^^^^^^^^^^^^^^^^^^^^^^^^^^^^^^^^^^^^^^^^
  File "C:\Users\g_and\Desktop\inventory management system\app\main.py", line 15, in decorated_function
    return f(*args, **kwargs)
           ^^^^^^^^^^^^^^^^^^
  File "C:\Users\g_and\Desktop\inventory management system\app\main.py", line 229, in add_item
    serial_number = int(data.get('serial_number'))
                    ^^^^^^^^^^^^^^^^^^^^^^^^^^^^^^
ValueError: invalid literal for int() with base 10: ''
2024-06-03 16:23:42,543 [ERROR] app.main Exception (MySQLdb.IntegrityError) (1452, 'Cannot add or update a child row: a foreign key constraint fails (`world`.`items`, CONSTRAINT `items_ibfk_1` FOREIGN KEY (`assigned_to`) REFERENCES `user` (`username`))')
[SQL: INSERT INTO items (item_name, serial_number, bill_no, date_of_purchase, assigned_to, warranty) VALUES (%s, %s, %s, %s, %s, %s)]
[parameters: ('laptop', 99, 77, '2024-06-02', '', '2024-06-11')]
(Background on this error at: https://sqlalche.me/e/20/gkpj) occurred while adding item 99
Traceback (most recent call last):
  File "C:\Users\g_and\AppData\Local\Programs\Python\Python311\Lib\site-packages\sqlalchemy\engine\base.py", line 1971, in _exec_single_context
    self.dialect.do_execute(
  File "C:\Users\g_and\AppData\Local\Programs\Python\Python311\Lib\site-packages\sqlalchemy\engine\default.py", line 919, in do_execute
    cursor.execute(statement, parameters)
  File "C:\Users\g_and\AppData\Local\Programs\Python\Python311\Lib\site-packages\MySQLdb\cursors.py", line 179, in execute
    res = self._query(mogrified_query)
          ^^^^^^^^^^^^^^^^^^^^^^^^^^^^
  File "C:\Users\g_and\AppData\Local\Programs\Python\Python311\Lib\site-packages\MySQLdb\cursors.py", line 330, in _query
    db.query(q)
  File "C:\Users\g_and\AppData\Local\Programs\Python\Python311\Lib\site-packages\MySQLdb\connections.py", line 257, in query
    _mysql.connection.query(self, query)
MySQLdb.IntegrityError: (1452, 'Cannot add or update a child row: a foreign key constraint fails (`world`.`items`, CONSTRAINT `items_ibfk_1` FOREIGN KEY (`assigned_to`) REFERENCES `user` (`username`))')

The above exception was the direct cause of the following exception:

Traceback (most recent call last):
  File "C:\Users\g_and\Desktop\inventory management system\app\main.py", line 238, in add_item
    db.session.commit()
  File "C:\Users\g_and\AppData\Local\Programs\Python\Python311\Lib\site-packages\sqlalchemy\orm\scoping.py", line 597, in commit
    return self._proxied.commit()
           ^^^^^^^^^^^^^^^^^^^^^^
  File "C:\Users\g_and\AppData\Local\Programs\Python\Python311\Lib\site-packages\sqlalchemy\orm\session.py", line 1972, in commit
    trans.commit(_to_root=True)
  File "<string>", line 2, in commit
  File "C:\Users\g_and\AppData\Local\Programs\Python\Python311\Lib\site-packages\sqlalchemy\orm\state_changes.py", line 139, in _go
    ret_value = fn(self, *arg, **kw)
                ^^^^^^^^^^^^^^^^^^^^
  File "C:\Users\g_and\AppData\Local\Programs\Python\Python311\Lib\site-packages\sqlalchemy\orm\session.py", line 1257, in commit
    self._prepare_impl()
  File "<string>", line 2, in _prepare_impl
  File "C:\Users\g_and\AppData\Local\Programs\Python\Python311\Lib\site-packages\sqlalchemy\orm\state_changes.py", line 139, in _go
    ret_value = fn(self, *arg, **kw)
                ^^^^^^^^^^^^^^^^^^^^
  File "C:\Users\g_and\AppData\Local\Programs\Python\Python311\Lib\site-packages\sqlalchemy\orm\session.py", line 1232, in _prepare_impl
    self.session.flush()
  File "C:\Users\g_and\AppData\Local\Programs\Python\Python311\Lib\site-packages\sqlalchemy\orm\session.py", line 4296, in flush
    self._flush(objects)
  File "C:\Users\g_and\AppData\Local\Programs\Python\Python311\Lib\site-packages\sqlalchemy\orm\session.py", line 4431, in _flush
    with util.safe_reraise():
  File "C:\Users\g_and\AppData\Local\Programs\Python\Python311\Lib\site-packages\sqlalchemy\util\langhelpers.py", line 146, in __exit__
    raise exc_value.with_traceback(exc_tb)
  File "C:\Users\g_and\AppData\Local\Programs\Python\Python311\Lib\site-packages\sqlalchemy\orm\session.py", line 4392, in _flush
    flush_context.execute()
  File "C:\Users\g_and\AppData\Local\Programs\Python\Python311\Lib\site-packages\sqlalchemy\orm\unitofwork.py", line 466, in execute
    rec.execute(self)
  File "C:\Users\g_and\AppData\Local\Programs\Python\Python311\Lib\site-packages\sqlalchemy\orm\unitofwork.py", line 642, in execute
    util.preloaded.orm_persistence.save_obj(
  File "C:\Users\g_and\AppData\Local\Programs\Python\Python311\Lib\site-packages\sqlalchemy\orm\persistence.py", line 93, in save_obj
    _emit_insert_statements(
  File "C:\Users\g_and\AppData\Local\Programs\Python\Python311\Lib\site-packages\sqlalchemy\orm\persistence.py", line 1233, in _emit_insert_statements
    result = connection.execute(
             ^^^^^^^^^^^^^^^^^^^
  File "C:\Users\g_and\AppData\Local\Programs\Python\Python311\Lib\site-packages\sqlalchemy\engine\base.py", line 1422, in execute
    return meth(
           ^^^^^
  File "C:\Users\g_and\AppData\Local\Programs\Python\Python311\Lib\site-packages\sqlalchemy\sql\elements.py", line 514, in _execute_on_connection
    return connection._execute_clauseelement(
           ^^^^^^^^^^^^^^^^^^^^^^^^^^^^^^^^^^
  File "C:\Users\g_and\AppData\Local\Programs\Python\Python311\Lib\site-packages\sqlalchemy\engine\base.py", line 1644, in _execute_clauseelement
    ret = self._execute_context(
          ^^^^^^^^^^^^^^^^^^^^^^
  File "C:\Users\g_and\AppData\Local\Programs\Python\Python311\Lib\site-packages\sqlalchemy\engine\base.py", line 1850, in _execute_context
    return self._exec_single_context(
           ^^^^^^^^^^^^^^^^^^^^^^^^^^
  File "C:\Users\g_and\AppData\Local\Programs\Python\Python311\Lib\site-packages\sqlalchemy\engine\base.py", line 1990, in _exec_single_context
    self._handle_dbapi_exception(
  File "C:\Users\g_and\AppData\Local\Programs\Python\Python311\Lib\site-packages\sqlalchemy\engine\base.py", line 2357, in _handle_dbapi_exception
    raise sqlalchemy_exception.with_traceback(exc_info[2]) from e
  File "C:\Users\g_and\AppData\Local\Programs\Python\Python311\Lib\site-packages\sqlalchemy\engine\base.py", line 1971, in _exec_single_context
    self.dialect.do_execute(
  File "C:\Users\g_and\AppData\Local\Programs\Python\Python311\Lib\site-packages\sqlalchemy\engine\default.py", line 919, in do_execute
    cursor.execute(statement, parameters)
  File "C:\Users\g_and\AppData\Local\Programs\Python\Python311\Lib\site-packages\MySQLdb\cursors.py", line 179, in execute
    res = self._query(mogrified_query)
          ^^^^^^^^^^^^^^^^^^^^^^^^^^^^
  File "C:\Users\g_and\AppData\Local\Programs\Python\Python311\Lib\site-packages\MySQLdb\cursors.py", line 330, in _query
    db.query(q)
  File "C:\Users\g_and\AppData\Local\Programs\Python\Python311\Lib\site-packages\MySQLdb\connections.py", line 257, in query
    _mysql.connection.query(self, query)
sqlalchemy.exc.IntegrityError: (MySQLdb.IntegrityError) (1452, 'Cannot add or update a child row: a foreign key constraint fails (`world`.`items`, CONSTRAINT `items_ibfk_1` FOREIGN KEY (`assigned_to`) REFERENCES `user` (`username`))')
[SQL: INSERT INTO items (item_name, serial_number, bill_no, date_of_purchase, assigned_to, warranty) VALUES (%s, %s, %s, %s, %s, %s)]
[parameters: ('laptop', 99, 77, '2024-06-02', '', '2024-06-11')]
(Background on this error at: https://sqlalche.me/e/20/gkpj)
2024-06-03 16:31:21,379 [INFO] app.main Item 85 added by admin admin
2024-06-03 16:31:22,698 [INFO] app.main Item 85 added by admin admin
2024-06-03 16:34:19,796 [INFO] app.main User admin logged out
2024-06-03 16:34:19,823 [WARNING] app.main Login page has arrived
2024-06-03 16:34:25,603 [INFO] app.main User admin logged in
2024-06-03 16:34:25,636 [INFO] app.main admin accessed the dashboard
2024-06-03 16:34:25,652 [INFO] app.main Admin admin accessed admin dashboard
2024-06-03 16:39:10,283 [INFO] app.main Fetched employee and item list
2024-06-03 16:39:25,086 [INFO] app.main Item 2 assigned to hello by admin admin
2024-06-03 16:39:25,101 [INFO] app.main Fetched employee and item list
2024-06-03 16:49:03,480 [INFO] app.main User admin logged out
2024-06-03 16:49:03,507 [WARNING] app.main Login page has arrived
2024-06-03 16:49:08,581 [INFO] app.main User admin logged in
2024-06-03 16:49:08,612 [INFO] app.main admin accessed the dashboard
2024-06-03 16:49:08,627 [INFO] app.main Admin admin accessed admin dashboard
2024-06-03 16:53:22,323 [INFO] app.main Item 2 deleted by admin admin
2024-06-03 16:53:34,696 [INFO] app.main Fetched employee and item list
2024-06-03 16:54:24,309 [INFO] app.main Fetched employee and item list
2024-06-03 16:54:36,194 [INFO] app.main Item 3 assigned to hello by admin admin
2024-06-03 16:54:36,207 [INFO] app.main Fetched employee and item list
2024-06-03 16:54:50,755 [INFO] app.main Item 3 assigned to None by admin admin
2024-06-03 16:56:30,647 [INFO] app.main User admin logged out
2024-06-03 16:56:30,681 [WARNING] app.main Login page has arrived
2024-06-03 16:56:35,509 [INFO] app.main User admin logged in
2024-06-03 16:56:35,532 [INFO] app.main admin accessed the dashboard
2024-06-03 16:56:35,548 [INFO] app.main Admin admin accessed admin dashboard
2024-06-03 16:56:50,452 [WARNING] app.main Unauthorized access attempt for admin by None
