2024-06-10 03:19:39,287 [WARNING] app.main Login page has arrived
2024-06-10 03:20:03,472 [INFO] app.main User admin logged in
2024-06-10 03:20:03,514 [INFO] app.main admin accessed the dashboard
2024-06-10 03:20:03,535 [INFO] app.main Admin admin accessed admin dashboard
2024-06-10 03:28:43,232 [INFO] app.auth Item 12345 added by admin admins
2024-06-10 03:32:21,867 [INFO] app.auth Item 12345 added by admin admins
2024-06-10 03:38:33,792 [INFO] app.auth Item 12345 added by admin admins
2024-06-10 03:40:22,298 [INFO] app.auth Item 12345 added by admin admins
2024-06-10 03:40:37,497 [INFO] app.auth Item 12345 added by admin admins
2024-06-10 03:41:25,977 [INFO] app.main Admin admins accessed admin dashboard
2024-06-10 03:42:40,432 [INFO] app.main Admin admins accessed admin dashboard
2024-06-10 03:43:15,389 [INFO] app.main Fetched employee and item list
2024-06-10 03:47:01,712 [INFO] app.auth Item 12345 added by admin admins
2024-06-10 03:47:01,873 [INFO] app.main User newuser added by admins
2024-06-10 03:47:01,997 [INFO] app.main User newadminuser added by admin admins
2024-06-10 03:47:02,130 [INFO] app.main Admin admins accessed admin dashboard
2024-06-10 03:47:02,429 [INFO] app.main Password changed for user: testuser
2024-06-10 03:47:02,544 [INFO] app.main testuser accessed the dashboard
2024-06-10 03:47:02,679 [INFO] app.main User deluser deleted by admin admins
2024-06-10 03:47:02,827 [INFO] app.auth Item 1 deleted by admin admins
2024-06-10 03:47:02,944 [INFO] app.main Employee testuser accessed employee dashboard
2024-06-10 03:47:03,733 [WARNING] app.main Login page has arrived
2024-06-10 03:47:03,882 [INFO] app.auth Item 1 assigned to testuser by admin admins
2024-06-10 03:47:04,022 [WARNING] app.main Failed login attempt for username: wronguser
2024-06-10 03:47:04,157 [INFO] app.main User testuser logged in for the first time
2024-06-10 03:47:04,272 [INFO] app.main User testuser logged out
2024-06-10 03:47:04,528 [INFO] app.auth Item 1 updated by admin admins
2024-06-10 03:52:09,088 [INFO] app.auth Item 12345 added by admin admins
2024-06-10 03:52:09,219 [INFO] app.main User newuser added by admins
2024-06-10 03:52:09,353 [INFO] app.main User newadminuser added by admin admins
2024-06-10 03:52:09,468 [INFO] app.main Admin admins accessed admin dashboard
2024-06-10 03:52:09,795 [INFO] app.main Password changed for user: testuser
2024-06-10 03:52:09,971 [INFO] app.main testuser accessed the dashboard
2024-06-10 03:52:10,112 [INFO] app.main User deluser deleted by admin admins
2024-06-10 03:52:10,241 [INFO] app.auth Item 1 deleted by admin admins
2024-06-10 03:52:10,364 [INFO] app.main Employee testuser accessed employee dashboard
2024-06-10 03:52:11,106 [WARNING] app.main Login page has arrived
2024-06-10 03:52:11,240 [INFO] app.auth Item 1 assigned to testuser by admin admins
2024-06-10 03:52:11,352 [WARNING] app.main Failed login attempt for username: wronguser
2024-06-10 03:52:11,480 [INFO] app.main User testuser logged in for the first time
2024-06-10 03:52:11,609 [INFO] app.main User testuser logged out
2024-06-10 03:52:11,860 [INFO] app.auth Item 1 updated by admin admins
2024-06-10 03:53:02,095 [INFO] app.auth Item 12345 added by admin admins
2024-06-10 03:53:02,212 [INFO] app.main User newuser added by admins
2024-06-10 03:53:02,338 [INFO] app.main User newadminuser added by admin admins
2024-06-10 03:53:02,461 [INFO] app.main Admin admins accessed admin dashboard
2024-06-10 03:53:02,720 [INFO] app.main Password changed for user: testuser
2024-06-10 03:53:02,838 [INFO] app.main testuser accessed the dashboard
2024-06-10 03:53:02,970 [INFO] app.main User deluser deleted by admin admins
2024-06-10 03:53:03,271 [INFO] app.auth Item 1 deleted by admin admins
2024-06-10 03:53:03,398 [INFO] app.main Employee testuser accessed employee dashboard
2024-06-10 03:53:04,159 [WARNING] app.main Login page has arrived
2024-06-10 03:53:04,300 [INFO] app.auth Item 1 assigned to testuser by admin admins
2024-06-10 03:53:04,438 [WARNING] app.main Failed login attempt for username: wronguser
2024-06-10 03:53:04,571 [INFO] app.main User testuser logged in for the first time
2024-06-10 03:53:04,700 [INFO] app.main User testuser logged out
2024-06-10 03:53:04,972 [INFO] app.auth Item 1 updated by admin admins
2024-06-10 03:53:59,575 [ERROR] app.auth Exception (builtins.TypeError) SQLite Date type only accepts Python date objects as input.
[SQL: INSERT INTO items (item_name, serial_number, bill_no, date_of_purchase, assigned_to, warranty) VALUES (?, ?, ?, ?, ?, ?)]
[parameters: [{'bill_no': 67890, 'date_of_purchase': '2024-01-01', 'serial_number': 12345, 'item_name': 'item1', 'warranty': '2025-01-01', 'assigned_to': None}]] occurred while adding item 12345
Traceback (most recent call last):
  File "C:\Users\g_and\AppData\Local\Programs\Python\Python312\Lib\site-packages\sqlalchemy\engine\base.py", line 1815, in _execute_context
    context = constructor(
              ^^^^^^^^^^^^
  File "C:\Users\g_and\AppData\Local\Programs\Python\Python312\Lib\site-packages\sqlalchemy\engine\default.py", line 1459, in _init_compiled
    flattened_processors[key](compiled_params[key])
  File "C:\Users\g_and\AppData\Local\Programs\Python\Python312\Lib\site-packages\sqlalchemy\dialects\sqlite\base.py", line 1142, in process
    raise TypeError(
TypeError: SQLite Date type only accepts Python date objects as input.

The above exception was the direct cause of the following exception:

Traceback (most recent call last):
  File "c:\Users\g_and\Desktop\gihub\learning-documentation\capstone-project\inventory management system(flask)\app\items.py", line 21, in add_item
    db.session.commit()
  File "C:\Users\g_and\AppData\Local\Programs\Python\Python312\Lib\site-packages\sqlalchemy\orm\scoping.py", line 597, in commit
    return self._proxied.commit()
           ^^^^^^^^^^^^^^^^^^^^^^
  File "C:\Users\g_and\AppData\Local\Programs\Python\Python312\Lib\site-packages\sqlalchemy\orm\session.py", line 2017, in commit
    trans.commit(_to_root=True)
  File "<string>", line 2, in commit
  File "C:\Users\g_and\AppData\Local\Programs\Python\Python312\Lib\site-packages\sqlalchemy\orm\state_changes.py", line 139, in _go
    ret_value = fn(self, *arg, **kw)
                ^^^^^^^^^^^^^^^^^^^^
  File "C:\Users\g_and\AppData\Local\Programs\Python\Python312\Lib\site-packages\sqlalchemy\orm\session.py", line 1302, in commit
    self._prepare_impl()
  File "<string>", line 2, in _prepare_impl
  File "C:\Users\g_and\AppData\Local\Programs\Python\Python312\Lib\site-packages\sqlalchemy\orm\state_changes.py", line 139, in _go
    ret_value = fn(self, *arg, **kw)
                ^^^^^^^^^^^^^^^^^^^^
  File "C:\Users\g_and\AppData\Local\Programs\Python\Python312\Lib\site-packages\sqlalchemy\orm\session.py", line 1277, in _prepare_impl
    self.session.flush()
  File "C:\Users\g_and\AppData\Local\Programs\Python\Python312\Lib\site-packages\sqlalchemy\orm\session.py", line 4341, in flush
    self._flush(objects)
  File "C:\Users\g_and\AppData\Local\Programs\Python\Python312\Lib\site-packages\sqlalchemy\orm\session.py", line 4476, in _flush
    with util.safe_reraise():
  File "C:\Users\g_and\AppData\Local\Programs\Python\Python312\Lib\site-packages\sqlalchemy\util\langhelpers.py", line 146, in __exit__
    raise exc_value.with_traceback(exc_tb)
  File "C:\Users\g_and\AppData\Local\Programs\Python\Python312\Lib\site-packages\sqlalchemy\orm\session.py", line 4437, in _flush
    flush_context.execute()
  File "C:\Users\g_and\AppData\Local\Programs\Python\Python312\Lib\site-packages\sqlalchemy\orm\unitofwork.py", line 466, in execute
    rec.execute(self)
  File "C:\Users\g_and\AppData\Local\Programs\Python\Python312\Lib\site-packages\sqlalchemy\orm\unitofwork.py", line 642, in execute
    util.preloaded.orm_persistence.save_obj(
  File "C:\Users\g_and\AppData\Local\Programs\Python\Python312\Lib\site-packages\sqlalchemy\orm\persistence.py", line 93, in save_obj
    _emit_insert_statements(
  File "C:\Users\g_and\AppData\Local\Programs\Python\Python312\Lib\site-packages\sqlalchemy\orm\persistence.py", line 1233, in _emit_insert_statements
    result = connection.execute(
             ^^^^^^^^^^^^^^^^^^^
  File "C:\Users\g_and\AppData\Local\Programs\Python\Python312\Lib\site-packages\sqlalchemy\engine\base.py", line 1418, in execute
    return meth(
           ^^^^^
  File "C:\Users\g_and\AppData\Local\Programs\Python\Python312\Lib\site-packages\sqlalchemy\sql\elements.py", line 515, in _execute_on_connection
    return connection._execute_clauseelement(
           ^^^^^^^^^^^^^^^^^^^^^^^^^^^^^^^^^^
  File "C:\Users\g_and\AppData\Local\Programs\Python\Python312\Lib\site-packages\sqlalchemy\engine\base.py", line 1640, in _execute_clauseelement
    ret = self._execute_context(
          ^^^^^^^^^^^^^^^^^^^^^^
  File "C:\Users\g_and\AppData\Local\Programs\Python\Python312\Lib\site-packages\sqlalchemy\engine\base.py", line 1821, in _execute_context
    self._handle_dbapi_exception(
  File "C:\Users\g_and\AppData\Local\Programs\Python\Python312\Lib\site-packages\sqlalchemy\engine\base.py", line 2353, in _handle_dbapi_exception
    raise sqlalchemy_exception.with_traceback(exc_info[2]) from e
  File "C:\Users\g_and\AppData\Local\Programs\Python\Python312\Lib\site-packages\sqlalchemy\engine\base.py", line 1815, in _execute_context
    context = constructor(
              ^^^^^^^^^^^^
  File "C:\Users\g_and\AppData\Local\Programs\Python\Python312\Lib\site-packages\sqlalchemy\engine\default.py", line 1459, in _init_compiled
    flattened_processors[key](compiled_params[key])
  File "C:\Users\g_and\AppData\Local\Programs\Python\Python312\Lib\site-packages\sqlalchemy\dialects\sqlite\base.py", line 1142, in process
    raise TypeError(
sqlalchemy.exc.StatementError: (builtins.TypeError) SQLite Date type only accepts Python date objects as input.
[SQL: INSERT INTO items (item_name, serial_number, bill_no, date_of_purchase, assigned_to, warranty) VALUES (?, ?, ?, ?, ?, ?)]
[parameters: [{'bill_no': 67890, 'date_of_purchase': '2024-01-01', 'serial_number': 12345, 'item_name': 'item1', 'warranty': '2025-01-01', 'assigned_to': None}]]
2024-06-10 03:53:59,626 [INFO] app.main User newuser added by admins
2024-06-10 03:53:59,663 [INFO] app.main User newadminuser added by admin admins
2024-06-10 03:53:59,693 [INFO] app.main Admin admins accessed admin dashboard
2024-06-10 03:53:59,777 [INFO] app.main Password changed for user: testuser
2024-06-10 03:53:59,807 [INFO] app.main testuser accessed the dashboard
2024-06-10 03:53:59,854 [INFO] app.main User deluser deleted by admin admins
2024-06-10 03:53:59,899 [INFO] app.auth Item 1 deleted by admin admins
2024-06-10 03:53:59,928 [INFO] app.main Employee testuser accessed employee dashboard
2024-06-10 03:54:00,112 [WARNING] app.main Login page has arrived
2024-06-10 03:54:00,157 [INFO] app.auth Item 1 assigned to testuser by admin admins
2024-06-10 03:54:00,280 [WARNING] app.main Failed login attempt for username: wronguser
2024-06-10 03:54:00,319 [INFO] app.main User testuser logged in for the first time
2024-06-10 03:54:00,351 [INFO] app.main User testuser logged out
2024-06-10 03:54:00,422 [ERROR] app.auth Exception (builtins.TypeError) SQLite Date type only accepts Python date objects as input.
[SQL: UPDATE items SET serial_number=?, bill_no=?, date_of_purchase=? WHERE items.item_id = ?]
[parameters: [{'bill_no': 67891, 'serial_number': 12346, 'date_of_purchase': '2024-02-01', 'items_item_id': 1}]] occurred while updating item 1
Traceback (most recent call last):
  File "C:\Users\g_and\AppData\Local\Programs\Python\Python312\Lib\site-packages\sqlalchemy\engine\base.py", line 1815, in _execute_context
    context = constructor(
              ^^^^^^^^^^^^
  File "C:\Users\g_and\AppData\Local\Programs\Python\Python312\Lib\site-packages\sqlalchemy\engine\default.py", line 1459, in _init_compiled
    flattened_processors[key](compiled_params[key])
  File "C:\Users\g_and\AppData\Local\Programs\Python\Python312\Lib\site-packages\sqlalchemy\dialects\sqlite\base.py", line 1142, in process
    raise TypeError(
TypeError: SQLite Date type only accepts Python date objects as input.

The above exception was the direct cause of the following exception:

Traceback (most recent call last):
  File "c:\Users\g_and\Desktop\gihub\learning-documentation\capstone-project\inventory management system(flask)\app\items.py", line 44, in update_item
    db.session.commit()
  File "C:\Users\g_and\AppData\Local\Programs\Python\Python312\Lib\site-packages\sqlalchemy\orm\scoping.py", line 597, in commit
    return self._proxied.commit()
           ^^^^^^^^^^^^^^^^^^^^^^
  File "C:\Users\g_and\AppData\Local\Programs\Python\Python312\Lib\site-packages\sqlalchemy\orm\session.py", line 2017, in commit
    trans.commit(_to_root=True)
  File "<string>", line 2, in commit
  File "C:\Users\g_and\AppData\Local\Programs\Python\Python312\Lib\site-packages\sqlalchemy\orm\state_changes.py", line 139, in _go
    ret_value = fn(self, *arg, **kw)
                ^^^^^^^^^^^^^^^^^^^^
  File "C:\Users\g_and\AppData\Local\Programs\Python\Python312\Lib\site-packages\sqlalchemy\orm\session.py", line 1302, in commit
    self._prepare_impl()
  File "<string>", line 2, in _prepare_impl
  File "C:\Users\g_and\AppData\Local\Programs\Python\Python312\Lib\site-packages\sqlalchemy\orm\state_changes.py", line 139, in _go
    ret_value = fn(self, *arg, **kw)
                ^^^^^^^^^^^^^^^^^^^^
  File "C:\Users\g_and\AppData\Local\Programs\Python\Python312\Lib\site-packages\sqlalchemy\orm\session.py", line 1277, in _prepare_impl
    self.session.flush()
  File "C:\Users\g_and\AppData\Local\Programs\Python\Python312\Lib\site-packages\sqlalchemy\orm\session.py", line 4341, in flush
    self._flush(objects)
  File "C:\Users\g_and\AppData\Local\Programs\Python\Python312\Lib\site-packages\sqlalchemy\orm\session.py", line 4476, in _flush
    with util.safe_reraise():
  File "C:\Users\g_and\AppData\Local\Programs\Python\Python312\Lib\site-packages\sqlalchemy\util\langhelpers.py", line 146, in __exit__
    raise exc_value.with_traceback(exc_tb)
  File "C:\Users\g_and\AppData\Local\Programs\Python\Python312\Lib\site-packages\sqlalchemy\orm\session.py", line 4437, in _flush
    flush_context.execute()
  File "C:\Users\g_and\AppData\Local\Programs\Python\Python312\Lib\site-packages\sqlalchemy\orm\unitofwork.py", line 466, in execute
    rec.execute(self)
  File "C:\Users\g_and\AppData\Local\Programs\Python\Python312\Lib\site-packages\sqlalchemy\orm\unitofwork.py", line 642, in execute
    util.preloaded.orm_persistence.save_obj(
  File "C:\Users\g_and\AppData\Local\Programs\Python\Python312\Lib\site-packages\sqlalchemy\orm\persistence.py", line 85, in save_obj
    _emit_update_statements(
  File "C:\Users\g_and\AppData\Local\Programs\Python\Python312\Lib\site-packages\sqlalchemy\orm\persistence.py", line 912, in _emit_update_statements
    c = connection.execute(
        ^^^^^^^^^^^^^^^^^^^
  File "C:\Users\g_and\AppData\Local\Programs\Python\Python312\Lib\site-packages\sqlalchemy\engine\base.py", line 1418, in execute
    return meth(
           ^^^^^
  File "C:\Users\g_and\AppData\Local\Programs\Python\Python312\Lib\site-packages\sqlalchemy\sql\elements.py", line 515, in _execute_on_connection
    return connection._execute_clauseelement(
           ^^^^^^^^^^^^^^^^^^^^^^^^^^^^^^^^^^
  File "C:\Users\g_and\AppData\Local\Programs\Python\Python312\Lib\site-packages\sqlalchemy\engine\base.py", line 1640, in _execute_clauseelement
    ret = self._execute_context(
          ^^^^^^^^^^^^^^^^^^^^^^
  File "C:\Users\g_and\AppData\Local\Programs\Python\Python312\Lib\site-packages\sqlalchemy\engine\base.py", line 1821, in _execute_context
    self._handle_dbapi_exception(
  File "C:\Users\g_and\AppData\Local\Programs\Python\Python312\Lib\site-packages\sqlalchemy\engine\base.py", line 2353, in _handle_dbapi_exception
    raise sqlalchemy_exception.with_traceback(exc_info[2]) from e
  File "C:\Users\g_and\AppData\Local\Programs\Python\Python312\Lib\site-packages\sqlalchemy\engine\base.py", line 1815, in _execute_context
    context = constructor(
              ^^^^^^^^^^^^
  File "C:\Users\g_and\AppData\Local\Programs\Python\Python312\Lib\site-packages\sqlalchemy\engine\default.py", line 1459, in _init_compiled
    flattened_processors[key](compiled_params[key])
  File "C:\Users\g_and\AppData\Local\Programs\Python\Python312\Lib\site-packages\sqlalchemy\dialects\sqlite\base.py", line 1142, in process
    raise TypeError(
sqlalchemy.exc.StatementError: (builtins.TypeError) SQLite Date type only accepts Python date objects as input.
[SQL: UPDATE items SET serial_number=?, bill_no=?, date_of_purchase=? WHERE items.item_id = ?]
[parameters: [{'bill_no': 67891, 'serial_number': 12346, 'date_of_purchase': '2024-02-01', 'items_item_id': 1}]]
2024-06-10 03:54:41,852 [ERROR] app.auth Exception (builtins.TypeError) SQLite Date type only accepts Python date objects as input.
[SQL: INSERT INTO items (item_name, serial_number, bill_no, date_of_purchase, assigned_to, warranty) VALUES (?, ?, ?, ?, ?, ?)]
[parameters: [{'warranty': '2025-01-01', 'bill_no': 67890, 'date_of_purchase': '2024-01-01', 'item_name': 'item1', 'serial_number': 12345, 'assigned_to': None}]] occurred while adding item 12345
Traceback (most recent call last):
  File "C:\Users\g_and\AppData\Local\Programs\Python\Python312\Lib\site-packages\sqlalchemy\engine\base.py", line 1815, in _execute_context
    context = constructor(
              ^^^^^^^^^^^^
  File "C:\Users\g_and\AppData\Local\Programs\Python\Python312\Lib\site-packages\sqlalchemy\engine\default.py", line 1459, in _init_compiled
    flattened_processors[key](compiled_params[key])
  File "C:\Users\g_and\AppData\Local\Programs\Python\Python312\Lib\site-packages\sqlalchemy\dialects\sqlite\base.py", line 1142, in process
    raise TypeError(
TypeError: SQLite Date type only accepts Python date objects as input.

The above exception was the direct cause of the following exception:

Traceback (most recent call last):
  File "c:\Users\g_and\Desktop\gihub\learning-documentation\capstone-project\inventory management system(flask)\app\items.py", line 21, in add_item
    db.session.commit()
  File "C:\Users\g_and\AppData\Local\Programs\Python\Python312\Lib\site-packages\sqlalchemy\orm\scoping.py", line 597, in commit
    return self._proxied.commit()
           ^^^^^^^^^^^^^^^^^^^^^^
  File "C:\Users\g_and\AppData\Local\Programs\Python\Python312\Lib\site-packages\sqlalchemy\orm\session.py", line 2017, in commit
    trans.commit(_to_root=True)
  File "<string>", line 2, in commit
  File "C:\Users\g_and\AppData\Local\Programs\Python\Python312\Lib\site-packages\sqlalchemy\orm\state_changes.py", line 139, in _go
    ret_value = fn(self, *arg, **kw)
                ^^^^^^^^^^^^^^^^^^^^
  File "C:\Users\g_and\AppData\Local\Programs\Python\Python312\Lib\site-packages\sqlalchemy\orm\session.py", line 1302, in commit
    self._prepare_impl()
  File "<string>", line 2, in _prepare_impl
  File "C:\Users\g_and\AppData\Local\Programs\Python\Python312\Lib\site-packages\sqlalchemy\orm\state_changes.py", line 139, in _go
    ret_value = fn(self, *arg, **kw)
                ^^^^^^^^^^^^^^^^^^^^
  File "C:\Users\g_and\AppData\Local\Programs\Python\Python312\Lib\site-packages\sqlalchemy\orm\session.py", line 1277, in _prepare_impl
    self.session.flush()
  File "C:\Users\g_and\AppData\Local\Programs\Python\Python312\Lib\site-packages\sqlalchemy\orm\session.py", line 4341, in flush
    self._flush(objects)
  File "C:\Users\g_and\AppData\Local\Programs\Python\Python312\Lib\site-packages\sqlalchemy\orm\session.py", line 4476, in _flush
    with util.safe_reraise():
  File "C:\Users\g_and\AppData\Local\Programs\Python\Python312\Lib\site-packages\sqlalchemy\util\langhelpers.py", line 146, in __exit__
    raise exc_value.with_traceback(exc_tb)
  File "C:\Users\g_and\AppData\Local\Programs\Python\Python312\Lib\site-packages\sqlalchemy\orm\session.py", line 4437, in _flush
    flush_context.execute()
  File "C:\Users\g_and\AppData\Local\Programs\Python\Python312\Lib\site-packages\sqlalchemy\orm\unitofwork.py", line 466, in execute
    rec.execute(self)
  File "C:\Users\g_and\AppData\Local\Programs\Python\Python312\Lib\site-packages\sqlalchemy\orm\unitofwork.py", line 642, in execute
    util.preloaded.orm_persistence.save_obj(
  File "C:\Users\g_and\AppData\Local\Programs\Python\Python312\Lib\site-packages\sqlalchemy\orm\persistence.py", line 93, in save_obj
    _emit_insert_statements(
  File "C:\Users\g_and\AppData\Local\Programs\Python\Python312\Lib\site-packages\sqlalchemy\orm\persistence.py", line 1233, in _emit_insert_statements
    result = connection.execute(
             ^^^^^^^^^^^^^^^^^^^
  File "C:\Users\g_and\AppData\Local\Programs\Python\Python312\Lib\site-packages\sqlalchemy\engine\base.py", line 1418, in execute
    return meth(
           ^^^^^
  File "C:\Users\g_and\AppData\Local\Programs\Python\Python312\Lib\site-packages\sqlalchemy\sql\elements.py", line 515, in _execute_on_connection
    return connection._execute_clauseelement(
           ^^^^^^^^^^^^^^^^^^^^^^^^^^^^^^^^^^
  File "C:\Users\g_and\AppData\Local\Programs\Python\Python312\Lib\site-packages\sqlalchemy\engine\base.py", line 1640, in _execute_clauseelement
    ret = self._execute_context(
          ^^^^^^^^^^^^^^^^^^^^^^
  File "C:\Users\g_and\AppData\Local\Programs\Python\Python312\Lib\site-packages\sqlalchemy\engine\base.py", line 1821, in _execute_context
    self._handle_dbapi_exception(
  File "C:\Users\g_and\AppData\Local\Programs\Python\Python312\Lib\site-packages\sqlalchemy\engine\base.py", line 2353, in _handle_dbapi_exception
    raise sqlalchemy_exception.with_traceback(exc_info[2]) from e
  File "C:\Users\g_and\AppData\Local\Programs\Python\Python312\Lib\site-packages\sqlalchemy\engine\base.py", line 1815, in _execute_context
    context = constructor(
              ^^^^^^^^^^^^
  File "C:\Users\g_and\AppData\Local\Programs\Python\Python312\Lib\site-packages\sqlalchemy\engine\default.py", line 1459, in _init_compiled
    flattened_processors[key](compiled_params[key])
  File "C:\Users\g_and\AppData\Local\Programs\Python\Python312\Lib\site-packages\sqlalchemy\dialects\sqlite\base.py", line 1142, in process
    raise TypeError(
sqlalchemy.exc.StatementError: (builtins.TypeError) SQLite Date type only accepts Python date objects as input.
[SQL: INSERT INTO items (item_name, serial_number, bill_no, date_of_purchase, assigned_to, warranty) VALUES (?, ?, ?, ?, ?, ?)]
[parameters: [{'warranty': '2025-01-01', 'bill_no': 67890, 'date_of_purchase': '2024-01-01', 'item_name': 'item1', 'serial_number': 12345, 'assigned_to': None}]]
2024-06-10 03:54:41,908 [INFO] app.main User newuser added by admins
2024-06-10 03:54:41,947 [INFO] app.main User newadminuser added by admin admins
2024-06-10 03:54:41,974 [INFO] app.main Admin admins accessed admin dashboard
2024-06-10 03:54:42,062 [INFO] app.main Password changed for user: testuser
2024-06-10 03:54:42,091 [INFO] app.main testuser accessed the dashboard
2024-06-10 03:54:42,138 [INFO] app.main User deluser deleted by admin admins
2024-06-10 03:54:42,184 [INFO] app.auth Item 1 deleted by admin admins
2024-06-10 03:54:42,213 [INFO] app.main Employee testuser accessed employee dashboard
2024-06-10 03:54:42,406 [WARNING] app.main Login page has arrived
2024-06-10 03:54:42,455 [INFO] app.auth Item 1 assigned to testuser by admin admins
2024-06-10 03:54:42,485 [WARNING] app.main Failed login attempt for username: wronguser
2024-06-10 03:54:42,524 [INFO] app.main User testuser logged in for the first time
2024-06-10 03:54:42,550 [INFO] app.main User testuser logged out
2024-06-10 03:54:42,624 [ERROR] app.auth Exception (builtins.TypeError) SQLite Date type only accepts Python date objects as input.
[SQL: UPDATE items SET serial_number=?, bill_no=?, date_of_purchase=? WHERE items.item_id = ?]
[parameters: [{'bill_no': 67891, 'date_of_purchase': '2024-02-01', 'serial_number': 12346, 'items_item_id': 1}]] occurred while updating item 1
Traceback (most recent call last):
  File "C:\Users\g_and\AppData\Local\Programs\Python\Python312\Lib\site-packages\sqlalchemy\engine\base.py", line 1815, in _execute_context
    context = constructor(
              ^^^^^^^^^^^^
  File "C:\Users\g_and\AppData\Local\Programs\Python\Python312\Lib\site-packages\sqlalchemy\engine\default.py", line 1459, in _init_compiled
    flattened_processors[key](compiled_params[key])
  File "C:\Users\g_and\AppData\Local\Programs\Python\Python312\Lib\site-packages\sqlalchemy\dialects\sqlite\base.py", line 1142, in process
    raise TypeError(
TypeError: SQLite Date type only accepts Python date objects as input.

The above exception was the direct cause of the following exception:

Traceback (most recent call last):
  File "c:\Users\g_and\Desktop\gihub\learning-documentation\capstone-project\inventory management system(flask)\app\items.py", line 44, in update_item
    db.session.commit()
  File "C:\Users\g_and\AppData\Local\Programs\Python\Python312\Lib\site-packages\sqlalchemy\orm\scoping.py", line 597, in commit
    return self._proxied.commit()
           ^^^^^^^^^^^^^^^^^^^^^^
  File "C:\Users\g_and\AppData\Local\Programs\Python\Python312\Lib\site-packages\sqlalchemy\orm\session.py", line 2017, in commit
    trans.commit(_to_root=True)
  File "<string>", line 2, in commit
  File "C:\Users\g_and\AppData\Local\Programs\Python\Python312\Lib\site-packages\sqlalchemy\orm\state_changes.py", line 139, in _go
    ret_value = fn(self, *arg, **kw)
                ^^^^^^^^^^^^^^^^^^^^
  File "C:\Users\g_and\AppData\Local\Programs\Python\Python312\Lib\site-packages\sqlalchemy\orm\session.py", line 1302, in commit
    self._prepare_impl()
  File "<string>", line 2, in _prepare_impl
  File "C:\Users\g_and\AppData\Local\Programs\Python\Python312\Lib\site-packages\sqlalchemy\orm\state_changes.py", line 139, in _go
    ret_value = fn(self, *arg, **kw)
                ^^^^^^^^^^^^^^^^^^^^
  File "C:\Users\g_and\AppData\Local\Programs\Python\Python312\Lib\site-packages\sqlalchemy\orm\session.py", line 1277, in _prepare_impl
    self.session.flush()
  File "C:\Users\g_and\AppData\Local\Programs\Python\Python312\Lib\site-packages\sqlalchemy\orm\session.py", line 4341, in flush
    self._flush(objects)
  File "C:\Users\g_and\AppData\Local\Programs\Python\Python312\Lib\site-packages\sqlalchemy\orm\session.py", line 4476, in _flush
    with util.safe_reraise():
  File "C:\Users\g_and\AppData\Local\Programs\Python\Python312\Lib\site-packages\sqlalchemy\util\langhelpers.py", line 146, in __exit__
    raise exc_value.with_traceback(exc_tb)
  File "C:\Users\g_and\AppData\Local\Programs\Python\Python312\Lib\site-packages\sqlalchemy\orm\session.py", line 4437, in _flush
    flush_context.execute()
  File "C:\Users\g_and\AppData\Local\Programs\Python\Python312\Lib\site-packages\sqlalchemy\orm\unitofwork.py", line 466, in execute
    rec.execute(self)
  File "C:\Users\g_and\AppData\Local\Programs\Python\Python312\Lib\site-packages\sqlalchemy\orm\unitofwork.py", line 642, in execute
    util.preloaded.orm_persistence.save_obj(
  File "C:\Users\g_and\AppData\Local\Programs\Python\Python312\Lib\site-packages\sqlalchemy\orm\persistence.py", line 85, in save_obj
    _emit_update_statements(
  File "C:\Users\g_and\AppData\Local\Programs\Python\Python312\Lib\site-packages\sqlalchemy\orm\persistence.py", line 912, in _emit_update_statements
    c = connection.execute(
        ^^^^^^^^^^^^^^^^^^^
  File "C:\Users\g_and\AppData\Local\Programs\Python\Python312\Lib\site-packages\sqlalchemy\engine\base.py", line 1418, in execute
    return meth(
           ^^^^^
  File "C:\Users\g_and\AppData\Local\Programs\Python\Python312\Lib\site-packages\sqlalchemy\sql\elements.py", line 515, in _execute_on_connection
    return connection._execute_clauseelement(
           ^^^^^^^^^^^^^^^^^^^^^^^^^^^^^^^^^^
  File "C:\Users\g_and\AppData\Local\Programs\Python\Python312\Lib\site-packages\sqlalchemy\engine\base.py", line 1640, in _execute_clauseelement
    ret = self._execute_context(
          ^^^^^^^^^^^^^^^^^^^^^^
  File "C:\Users\g_and\AppData\Local\Programs\Python\Python312\Lib\site-packages\sqlalchemy\engine\base.py", line 1821, in _execute_context
    self._handle_dbapi_exception(
  File "C:\Users\g_and\AppData\Local\Programs\Python\Python312\Lib\site-packages\sqlalchemy\engine\base.py", line 2353, in _handle_dbapi_exception
    raise sqlalchemy_exception.with_traceback(exc_info[2]) from e
  File "C:\Users\g_and\AppData\Local\Programs\Python\Python312\Lib\site-packages\sqlalchemy\engine\base.py", line 1815, in _execute_context
    context = constructor(
              ^^^^^^^^^^^^
  File "C:\Users\g_and\AppData\Local\Programs\Python\Python312\Lib\site-packages\sqlalchemy\engine\default.py", line 1459, in _init_compiled
    flattened_processors[key](compiled_params[key])
  File "C:\Users\g_and\AppData\Local\Programs\Python\Python312\Lib\site-packages\sqlalchemy\dialects\sqlite\base.py", line 1142, in process
    raise TypeError(
sqlalchemy.exc.StatementError: (builtins.TypeError) SQLite Date type only accepts Python date objects as input.
[SQL: UPDATE items SET serial_number=?, bill_no=?, date_of_purchase=? WHERE items.item_id = ?]
[parameters: [{'bill_no': 67891, 'date_of_purchase': '2024-02-01', 'serial_number': 12346, 'items_item_id': 1}]]
2024-06-10 03:59:21,558 [ERROR] app.auth Exception (builtins.TypeError) SQLite Date type only accepts Python date objects as input.
[SQL: INSERT INTO items (item_name, serial_number, bill_no, date_of_purchase, assigned_to, warranty) VALUES (?, ?, ?, ?, ?, ?)]
[parameters: [{'bill_no': 67890, 'serial_number': 12345, 'item_name': 'item1', 'warranty': 'Wed, 01 Jan 2025 00:00:00 GMT', 'date_of_purchase': 'Mon, 01 Jan 2024 00:00:00 GMT', 'assigned_to': None}]] occurred while adding item 12345
Traceback (most recent call last):
  File "C:\Users\g_and\AppData\Local\Programs\Python\Python312\Lib\site-packages\sqlalchemy\engine\base.py", line 1815, in _execute_context
    context = constructor(
              ^^^^^^^^^^^^
  File "C:\Users\g_and\AppData\Local\Programs\Python\Python312\Lib\site-packages\sqlalchemy\engine\default.py", line 1459, in _init_compiled
    flattened_processors[key](compiled_params[key])
  File "C:\Users\g_and\AppData\Local\Programs\Python\Python312\Lib\site-packages\sqlalchemy\dialects\sqlite\base.py", line 1142, in process
    raise TypeError(
TypeError: SQLite Date type only accepts Python date objects as input.

The above exception was the direct cause of the following exception:

Traceback (most recent call last):
  File "c:\Users\g_and\Desktop\gihub\learning-documentation\capstone-project\inventory management system(flask)\app\items.py", line 21, in add_item
    db.session.commit()
  File "C:\Users\g_and\AppData\Local\Programs\Python\Python312\Lib\site-packages\sqlalchemy\orm\scoping.py", line 597, in commit
    return self._proxied.commit()
           ^^^^^^^^^^^^^^^^^^^^^^
  File "C:\Users\g_and\AppData\Local\Programs\Python\Python312\Lib\site-packages\sqlalchemy\orm\session.py", line 2017, in commit
    trans.commit(_to_root=True)
  File "<string>", line 2, in commit
  File "C:\Users\g_and\AppData\Local\Programs\Python\Python312\Lib\site-packages\sqlalchemy\orm\state_changes.py", line 139, in _go
    ret_value = fn(self, *arg, **kw)
                ^^^^^^^^^^^^^^^^^^^^
  File "C:\Users\g_and\AppData\Local\Programs\Python\Python312\Lib\site-packages\sqlalchemy\orm\session.py", line 1302, in commit
    self._prepare_impl()
  File "<string>", line 2, in _prepare_impl
  File "C:\Users\g_and\AppData\Local\Programs\Python\Python312\Lib\site-packages\sqlalchemy\orm\state_changes.py", line 139, in _go
    ret_value = fn(self, *arg, **kw)
                ^^^^^^^^^^^^^^^^^^^^
  File "C:\Users\g_and\AppData\Local\Programs\Python\Python312\Lib\site-packages\sqlalchemy\orm\session.py", line 1277, in _prepare_impl
    self.session.flush()
  File "C:\Users\g_and\AppData\Local\Programs\Python\Python312\Lib\site-packages\sqlalchemy\orm\session.py", line 4341, in flush
    self._flush(objects)
  File "C:\Users\g_and\AppData\Local\Programs\Python\Python312\Lib\site-packages\sqlalchemy\orm\session.py", line 4476, in _flush
    with util.safe_reraise():
  File "C:\Users\g_and\AppData\Local\Programs\Python\Python312\Lib\site-packages\sqlalchemy\util\langhelpers.py", line 146, in __exit__
    raise exc_value.with_traceback(exc_tb)
  File "C:\Users\g_and\AppData\Local\Programs\Python\Python312\Lib\site-packages\sqlalchemy\orm\session.py", line 4437, in _flush
    flush_context.execute()
  File "C:\Users\g_and\AppData\Local\Programs\Python\Python312\Lib\site-packages\sqlalchemy\orm\unitofwork.py", line 466, in execute
    rec.execute(self)
  File "C:\Users\g_and\AppData\Local\Programs\Python\Python312\Lib\site-packages\sqlalchemy\orm\unitofwork.py", line 642, in execute
    util.preloaded.orm_persistence.save_obj(
  File "C:\Users\g_and\AppData\Local\Programs\Python\Python312\Lib\site-packages\sqlalchemy\orm\persistence.py", line 93, in save_obj
    _emit_insert_statements(
  File "C:\Users\g_and\AppData\Local\Programs\Python\Python312\Lib\site-packages\sqlalchemy\orm\persistence.py", line 1233, in _emit_insert_statements
    result = connection.execute(
             ^^^^^^^^^^^^^^^^^^^
  File "C:\Users\g_and\AppData\Local\Programs\Python\Python312\Lib\site-packages\sqlalchemy\engine\base.py", line 1418, in execute
    return meth(
           ^^^^^
  File "C:\Users\g_and\AppData\Local\Programs\Python\Python312\Lib\site-packages\sqlalchemy\sql\elements.py", line 515, in _execute_on_connection
    return connection._execute_clauseelement(
           ^^^^^^^^^^^^^^^^^^^^^^^^^^^^^^^^^^
  File "C:\Users\g_and\AppData\Local\Programs\Python\Python312\Lib\site-packages\sqlalchemy\engine\base.py", line 1640, in _execute_clauseelement
    ret = self._execute_context(
          ^^^^^^^^^^^^^^^^^^^^^^
  File "C:\Users\g_and\AppData\Local\Programs\Python\Python312\Lib\site-packages\sqlalchemy\engine\base.py", line 1821, in _execute_context
    self._handle_dbapi_exception(
  File "C:\Users\g_and\AppData\Local\Programs\Python\Python312\Lib\site-packages\sqlalchemy\engine\base.py", line 2353, in _handle_dbapi_exception
    raise sqlalchemy_exception.with_traceback(exc_info[2]) from e
  File "C:\Users\g_and\AppData\Local\Programs\Python\Python312\Lib\site-packages\sqlalchemy\engine\base.py", line 1815, in _execute_context
    context = constructor(
              ^^^^^^^^^^^^
  File "C:\Users\g_and\AppData\Local\Programs\Python\Python312\Lib\site-packages\sqlalchemy\engine\default.py", line 1459, in _init_compiled
    flattened_processors[key](compiled_params[key])
  File "C:\Users\g_and\AppData\Local\Programs\Python\Python312\Lib\site-packages\sqlalchemy\dialects\sqlite\base.py", line 1142, in process
    raise TypeError(
sqlalchemy.exc.StatementError: (builtins.TypeError) SQLite Date type only accepts Python date objects as input.
[SQL: INSERT INTO items (item_name, serial_number, bill_no, date_of_purchase, assigned_to, warranty) VALUES (?, ?, ?, ?, ?, ?)]
[parameters: [{'bill_no': 67890, 'serial_number': 12345, 'item_name': 'item1', 'warranty': 'Wed, 01 Jan 2025 00:00:00 GMT', 'date_of_purchase': 'Mon, 01 Jan 2024 00:00:00 GMT', 'assigned_to': None}]]
2024-06-10 03:59:21,610 [INFO] app.main User newuser added by admins
2024-06-10 03:59:21,644 [INFO] app.main User newadminuser added by admin admins
2024-06-10 03:59:21,675 [INFO] app.main Admin admins accessed admin dashboard
2024-06-10 03:59:21,759 [INFO] app.main Password changed for user: testuser
2024-06-10 03:59:21,788 [INFO] app.main testuser accessed the dashboard
2024-06-10 03:59:21,834 [INFO] app.main User deluser deleted by admin admins
2024-06-10 03:59:21,882 [INFO] app.auth Item 1 deleted by admin admins
2024-06-10 03:59:21,912 [INFO] app.main Employee testuser accessed employee dashboard
2024-06-10 03:59:22,094 [WARNING] app.main Login page has arrived
2024-06-10 03:59:22,138 [INFO] app.auth Item 1 assigned to testuser by admin admins
2024-06-10 03:59:22,170 [WARNING] app.main Failed login attempt for username: wronguser
2024-06-10 03:59:22,210 [INFO] app.main User testuser logged in for the first time
2024-06-10 03:59:22,243 [INFO] app.main User testuser logged out
2024-06-10 03:59:22,310 [ERROR] app.auth Exception (builtins.TypeError) SQLite Date type only accepts Python date objects as input.
[SQL: UPDATE items SET serial_number=?, bill_no=?, date_of_purchase=? WHERE items.item_id = ?]
[parameters: [{'date_of_purchase': 'Thu, 01 Feb 2024 00:00:00 GMT', 'serial_number': 12346, 'bill_no': 67891, 'items_item_id': 1}]] occurred while updating item 1
Traceback (most recent call last):
  File "C:\Users\g_and\AppData\Local\Programs\Python\Python312\Lib\site-packages\sqlalchemy\engine\base.py", line 1815, in _execute_context
    context = constructor(
              ^^^^^^^^^^^^
  File "C:\Users\g_and\AppData\Local\Programs\Python\Python312\Lib\site-packages\sqlalchemy\engine\default.py", line 1459, in _init_compiled
    flattened_processors[key](compiled_params[key])
  File "C:\Users\g_and\AppData\Local\Programs\Python\Python312\Lib\site-packages\sqlalchemy\dialects\sqlite\base.py", line 1142, in process
    raise TypeError(
TypeError: SQLite Date type only accepts Python date objects as input.

The above exception was the direct cause of the following exception:

Traceback (most recent call last):
  File "c:\Users\g_and\Desktop\gihub\learning-documentation\capstone-project\inventory management system(flask)\app\items.py", line 44, in update_item
    db.session.commit()
  File "C:\Users\g_and\AppData\Local\Programs\Python\Python312\Lib\site-packages\sqlalchemy\orm\scoping.py", line 597, in commit
    return self._proxied.commit()
           ^^^^^^^^^^^^^^^^^^^^^^
  File "C:\Users\g_and\AppData\Local\Programs\Python\Python312\Lib\site-packages\sqlalchemy\orm\session.py", line 2017, in commit
    trans.commit(_to_root=True)
  File "<string>", line 2, in commit
  File "C:\Users\g_and\AppData\Local\Programs\Python\Python312\Lib\site-packages\sqlalchemy\orm\state_changes.py", line 139, in _go
    ret_value = fn(self, *arg, **kw)
                ^^^^^^^^^^^^^^^^^^^^
  File "C:\Users\g_and\AppData\Local\Programs\Python\Python312\Lib\site-packages\sqlalchemy\orm\session.py", line 1302, in commit
    self._prepare_impl()
  File "<string>", line 2, in _prepare_impl
  File "C:\Users\g_and\AppData\Local\Programs\Python\Python312\Lib\site-packages\sqlalchemy\orm\state_changes.py", line 139, in _go
    ret_value = fn(self, *arg, **kw)
                ^^^^^^^^^^^^^^^^^^^^
  File "C:\Users\g_and\AppData\Local\Programs\Python\Python312\Lib\site-packages\sqlalchemy\orm\session.py", line 1277, in _prepare_impl
    self.session.flush()
  File "C:\Users\g_and\AppData\Local\Programs\Python\Python312\Lib\site-packages\sqlalchemy\orm\session.py", line 4341, in flush
    self._flush(objects)
  File "C:\Users\g_and\AppData\Local\Programs\Python\Python312\Lib\site-packages\sqlalchemy\orm\session.py", line 4476, in _flush
    with util.safe_reraise():
  File "C:\Users\g_and\AppData\Local\Programs\Python\Python312\Lib\site-packages\sqlalchemy\util\langhelpers.py", line 146, in __exit__
    raise exc_value.with_traceback(exc_tb)
  File "C:\Users\g_and\AppData\Local\Programs\Python\Python312\Lib\site-packages\sqlalchemy\orm\session.py", line 4437, in _flush
    flush_context.execute()
  File "C:\Users\g_and\AppData\Local\Programs\Python\Python312\Lib\site-packages\sqlalchemy\orm\unitofwork.py", line 466, in execute
    rec.execute(self)
  File "C:\Users\g_and\AppData\Local\Programs\Python\Python312\Lib\site-packages\sqlalchemy\orm\unitofwork.py", line 642, in execute
    util.preloaded.orm_persistence.save_obj(
  File "C:\Users\g_and\AppData\Local\Programs\Python\Python312\Lib\site-packages\sqlalchemy\orm\persistence.py", line 85, in save_obj
    _emit_update_statements(
  File "C:\Users\g_and\AppData\Local\Programs\Python\Python312\Lib\site-packages\sqlalchemy\orm\persistence.py", line 912, in _emit_update_statements
    c = connection.execute(
        ^^^^^^^^^^^^^^^^^^^
  File "C:\Users\g_and\AppData\Local\Programs\Python\Python312\Lib\site-packages\sqlalchemy\engine\base.py", line 1418, in execute
    return meth(
           ^^^^^
  File "C:\Users\g_and\AppData\Local\Programs\Python\Python312\Lib\site-packages\sqlalchemy\sql\elements.py", line 515, in _execute_on_connection
    return connection._execute_clauseelement(
           ^^^^^^^^^^^^^^^^^^^^^^^^^^^^^^^^^^
  File "C:\Users\g_and\AppData\Local\Programs\Python\Python312\Lib\site-packages\sqlalchemy\engine\base.py", line 1640, in _execute_clauseelement
    ret = self._execute_context(
          ^^^^^^^^^^^^^^^^^^^^^^
  File "C:\Users\g_and\AppData\Local\Programs\Python\Python312\Lib\site-packages\sqlalchemy\engine\base.py", line 1821, in _execute_context
    self._handle_dbapi_exception(
  File "C:\Users\g_and\AppData\Local\Programs\Python\Python312\Lib\site-packages\sqlalchemy\engine\base.py", line 2353, in _handle_dbapi_exception
    raise sqlalchemy_exception.with_traceback(exc_info[2]) from e
  File "C:\Users\g_and\AppData\Local\Programs\Python\Python312\Lib\site-packages\sqlalchemy\engine\base.py", line 1815, in _execute_context
    context = constructor(
              ^^^^^^^^^^^^
  File "C:\Users\g_and\AppData\Local\Programs\Python\Python312\Lib\site-packages\sqlalchemy\engine\default.py", line 1459, in _init_compiled
    flattened_processors[key](compiled_params[key])
  File "C:\Users\g_and\AppData\Local\Programs\Python\Python312\Lib\site-packages\sqlalchemy\dialects\sqlite\base.py", line 1142, in process
    raise TypeError(
sqlalchemy.exc.StatementError: (builtins.TypeError) SQLite Date type only accepts Python date objects as input.
[SQL: UPDATE items SET serial_number=?, bill_no=?, date_of_purchase=? WHERE items.item_id = ?]
[parameters: [{'date_of_purchase': 'Thu, 01 Feb 2024 00:00:00 GMT', 'serial_number': 12346, 'bill_no': 67891, 'items_item_id': 1}]]
2024-06-10 04:01:38,708 [ERROR] app.auth Exception (builtins.TypeError) SQLite Date type only accepts Python date objects as input.
[SQL: INSERT INTO items (item_name, serial_number, bill_no, date_of_purchase, assigned_to, warranty) VALUES (?, ?, ?, ?, ?, ?)]
[parameters: [{'serial_number': 12345, 'date_of_purchase': 'Mon, 01 Jan 2024 00:00:00 GMT', 'bill_no': 67890, 'warranty': 'Wed, 01 Jan 2025 00:00:00 GMT', 'item_name': 'item1', 'assigned_to': None}]] occurred while adding item 12345
Traceback (most recent call last):
  File "C:\Users\g_and\AppData\Local\Programs\Python\Python312\Lib\site-packages\sqlalchemy\engine\base.py", line 1815, in _execute_context
    context = constructor(
              ^^^^^^^^^^^^
  File "C:\Users\g_and\AppData\Local\Programs\Python\Python312\Lib\site-packages\sqlalchemy\engine\default.py", line 1459, in _init_compiled
    flattened_processors[key](compiled_params[key])
  File "C:\Users\g_and\AppData\Local\Programs\Python\Python312\Lib\site-packages\sqlalchemy\dialects\sqlite\base.py", line 1142, in process
    raise TypeError(
TypeError: SQLite Date type only accepts Python date objects as input.

The above exception was the direct cause of the following exception:

Traceback (most recent call last):
  File "c:\Users\g_and\Desktop\gihub\learning-documentation\capstone-project\inventory management system(flask)\app\items.py", line 21, in add_item
    db.session.commit()
  File "C:\Users\g_and\AppData\Local\Programs\Python\Python312\Lib\site-packages\sqlalchemy\orm\scoping.py", line 597, in commit
    return self._proxied.commit()
           ^^^^^^^^^^^^^^^^^^^^^^
  File "C:\Users\g_and\AppData\Local\Programs\Python\Python312\Lib\site-packages\sqlalchemy\orm\session.py", line 2017, in commit
    trans.commit(_to_root=True)
  File "<string>", line 2, in commit
  File "C:\Users\g_and\AppData\Local\Programs\Python\Python312\Lib\site-packages\sqlalchemy\orm\state_changes.py", line 139, in _go
    ret_value = fn(self, *arg, **kw)
                ^^^^^^^^^^^^^^^^^^^^
  File "C:\Users\g_and\AppData\Local\Programs\Python\Python312\Lib\site-packages\sqlalchemy\orm\session.py", line 1302, in commit
    self._prepare_impl()
  File "<string>", line 2, in _prepare_impl
  File "C:\Users\g_and\AppData\Local\Programs\Python\Python312\Lib\site-packages\sqlalchemy\orm\state_changes.py", line 139, in _go
    ret_value = fn(self, *arg, **kw)
                ^^^^^^^^^^^^^^^^^^^^
  File "C:\Users\g_and\AppData\Local\Programs\Python\Python312\Lib\site-packages\sqlalchemy\orm\session.py", line 1277, in _prepare_impl
    self.session.flush()
  File "C:\Users\g_and\AppData\Local\Programs\Python\Python312\Lib\site-packages\sqlalchemy\orm\session.py", line 4341, in flush
    self._flush(objects)
  File "C:\Users\g_and\AppData\Local\Programs\Python\Python312\Lib\site-packages\sqlalchemy\orm\session.py", line 4476, in _flush
    with util.safe_reraise():
  File "C:\Users\g_and\AppData\Local\Programs\Python\Python312\Lib\site-packages\sqlalchemy\util\langhelpers.py", line 146, in __exit__
    raise exc_value.with_traceback(exc_tb)
  File "C:\Users\g_and\AppData\Local\Programs\Python\Python312\Lib\site-packages\sqlalchemy\orm\session.py", line 4437, in _flush
    flush_context.execute()
  File "C:\Users\g_and\AppData\Local\Programs\Python\Python312\Lib\site-packages\sqlalchemy\orm\unitofwork.py", line 466, in execute
    rec.execute(self)
  File "C:\Users\g_and\AppData\Local\Programs\Python\Python312\Lib\site-packages\sqlalchemy\orm\unitofwork.py", line 642, in execute
    util.preloaded.orm_persistence.save_obj(
  File "C:\Users\g_and\AppData\Local\Programs\Python\Python312\Lib\site-packages\sqlalchemy\orm\persistence.py", line 93, in save_obj
    _emit_insert_statements(
  File "C:\Users\g_and\AppData\Local\Programs\Python\Python312\Lib\site-packages\sqlalchemy\orm\persistence.py", line 1233, in _emit_insert_statements
    result = connection.execute(
             ^^^^^^^^^^^^^^^^^^^
  File "C:\Users\g_and\AppData\Local\Programs\Python\Python312\Lib\site-packages\sqlalchemy\engine\base.py", line 1418, in execute
    return meth(
           ^^^^^
  File "C:\Users\g_and\AppData\Local\Programs\Python\Python312\Lib\site-packages\sqlalchemy\sql\elements.py", line 515, in _execute_on_connection
    return connection._execute_clauseelement(
           ^^^^^^^^^^^^^^^^^^^^^^^^^^^^^^^^^^
  File "C:\Users\g_and\AppData\Local\Programs\Python\Python312\Lib\site-packages\sqlalchemy\engine\base.py", line 1640, in _execute_clauseelement
    ret = self._execute_context(
          ^^^^^^^^^^^^^^^^^^^^^^
  File "C:\Users\g_and\AppData\Local\Programs\Python\Python312\Lib\site-packages\sqlalchemy\engine\base.py", line 1821, in _execute_context
    self._handle_dbapi_exception(
  File "C:\Users\g_and\AppData\Local\Programs\Python\Python312\Lib\site-packages\sqlalchemy\engine\base.py", line 2353, in _handle_dbapi_exception
    raise sqlalchemy_exception.with_traceback(exc_info[2]) from e
  File "C:\Users\g_and\AppData\Local\Programs\Python\Python312\Lib\site-packages\sqlalchemy\engine\base.py", line 1815, in _execute_context
    context = constructor(
              ^^^^^^^^^^^^
  File "C:\Users\g_and\AppData\Local\Programs\Python\Python312\Lib\site-packages\sqlalchemy\engine\default.py", line 1459, in _init_compiled
    flattened_processors[key](compiled_params[key])
  File "C:\Users\g_and\AppData\Local\Programs\Python\Python312\Lib\site-packages\sqlalchemy\dialects\sqlite\base.py", line 1142, in process
    raise TypeError(
sqlalchemy.exc.StatementError: (builtins.TypeError) SQLite Date type only accepts Python date objects as input.
[SQL: INSERT INTO items (item_name, serial_number, bill_no, date_of_purchase, assigned_to, warranty) VALUES (?, ?, ?, ?, ?, ?)]
[parameters: [{'serial_number': 12345, 'date_of_purchase': 'Mon, 01 Jan 2024 00:00:00 GMT', 'bill_no': 67890, 'warranty': 'Wed, 01 Jan 2025 00:00:00 GMT', 'item_name': 'item1', 'assigned_to': None}]]
2024-06-10 04:01:38,760 [INFO] app.main User newuser added by admins
2024-06-10 04:01:38,795 [INFO] app.main User newadminuser added by admin admins
2024-06-10 04:01:38,826 [INFO] app.main Admin admins accessed admin dashboard
2024-06-10 04:01:38,909 [INFO] app.main Password changed for user: testuser
2024-06-10 04:01:38,940 [INFO] app.main testuser accessed the dashboard
2024-06-10 04:01:38,986 [INFO] app.main User deluser deleted by admin admins
2024-06-10 04:01:39,027 [INFO] app.auth Item 1 deleted by admin admins
2024-06-10 04:01:39,058 [INFO] app.main Employee testuser accessed employee dashboard
2024-06-10 04:01:39,237 [WARNING] app.main Login page has arrived
2024-06-10 04:01:39,290 [INFO] app.auth Item 1 assigned to testuser by admin admins
2024-06-10 04:01:39,320 [WARNING] app.main Failed login attempt for username: wronguser
2024-06-10 04:01:39,363 [INFO] app.main User testuser logged in for the first time
2024-06-10 04:01:39,395 [INFO] app.main User testuser logged out
2024-06-10 04:01:39,466 [ERROR] app.auth Exception (builtins.TypeError) SQLite Date type only accepts Python date objects as input.
[SQL: UPDATE items SET serial_number=?, bill_no=?, date_of_purchase=? WHERE items.item_id = ?]
[parameters: [{'date_of_purchase': 'Thu, 01 Feb 2024 00:00:00 GMT', 'serial_number': 12346, 'bill_no': 67891, 'items_item_id': 1}]] occurred while updating item 1
Traceback (most recent call last):
  File "C:\Users\g_and\AppData\Local\Programs\Python\Python312\Lib\site-packages\sqlalchemy\engine\base.py", line 1815, in _execute_context
    context = constructor(
              ^^^^^^^^^^^^
  File "C:\Users\g_and\AppData\Local\Programs\Python\Python312\Lib\site-packages\sqlalchemy\engine\default.py", line 1459, in _init_compiled
    flattened_processors[key](compiled_params[key])
  File "C:\Users\g_and\AppData\Local\Programs\Python\Python312\Lib\site-packages\sqlalchemy\dialects\sqlite\base.py", line 1142, in process
    raise TypeError(
TypeError: SQLite Date type only accepts Python date objects as input.

The above exception was the direct cause of the following exception:

Traceback (most recent call last):
  File "c:\Users\g_and\Desktop\gihub\learning-documentation\capstone-project\inventory management system(flask)\app\items.py", line 44, in update_item
    db.session.commit()
  File "C:\Users\g_and\AppData\Local\Programs\Python\Python312\Lib\site-packages\sqlalchemy\orm\scoping.py", line 597, in commit
    return self._proxied.commit()
           ^^^^^^^^^^^^^^^^^^^^^^
  File "C:\Users\g_and\AppData\Local\Programs\Python\Python312\Lib\site-packages\sqlalchemy\orm\session.py", line 2017, in commit
    trans.commit(_to_root=True)
  File "<string>", line 2, in commit
  File "C:\Users\g_and\AppData\Local\Programs\Python\Python312\Lib\site-packages\sqlalchemy\orm\state_changes.py", line 139, in _go
    ret_value = fn(self, *arg, **kw)
                ^^^^^^^^^^^^^^^^^^^^
  File "C:\Users\g_and\AppData\Local\Programs\Python\Python312\Lib\site-packages\sqlalchemy\orm\session.py", line 1302, in commit
    self._prepare_impl()
  File "<string>", line 2, in _prepare_impl
  File "C:\Users\g_and\AppData\Local\Programs\Python\Python312\Lib\site-packages\sqlalchemy\orm\state_changes.py", line 139, in _go
    ret_value = fn(self, *arg, **kw)
                ^^^^^^^^^^^^^^^^^^^^
  File "C:\Users\g_and\AppData\Local\Programs\Python\Python312\Lib\site-packages\sqlalchemy\orm\session.py", line 1277, in _prepare_impl
    self.session.flush()
  File "C:\Users\g_and\AppData\Local\Programs\Python\Python312\Lib\site-packages\sqlalchemy\orm\session.py", line 4341, in flush
    self._flush(objects)
  File "C:\Users\g_and\AppData\Local\Programs\Python\Python312\Lib\site-packages\sqlalchemy\orm\session.py", line 4476, in _flush
    with util.safe_reraise():
  File "C:\Users\g_and\AppData\Local\Programs\Python\Python312\Lib\site-packages\sqlalchemy\util\langhelpers.py", line 146, in __exit__
    raise exc_value.with_traceback(exc_tb)
  File "C:\Users\g_and\AppData\Local\Programs\Python\Python312\Lib\site-packages\sqlalchemy\orm\session.py", line 4437, in _flush
    flush_context.execute()
  File "C:\Users\g_and\AppData\Local\Programs\Python\Python312\Lib\site-packages\sqlalchemy\orm\unitofwork.py", line 466, in execute
    rec.execute(self)
  File "C:\Users\g_and\AppData\Local\Programs\Python\Python312\Lib\site-packages\sqlalchemy\orm\unitofwork.py", line 642, in execute
    util.preloaded.orm_persistence.save_obj(
  File "C:\Users\g_and\AppData\Local\Programs\Python\Python312\Lib\site-packages\sqlalchemy\orm\persistence.py", line 85, in save_obj
    _emit_update_statements(
  File "C:\Users\g_and\AppData\Local\Programs\Python\Python312\Lib\site-packages\sqlalchemy\orm\persistence.py", line 912, in _emit_update_statements
    c = connection.execute(
        ^^^^^^^^^^^^^^^^^^^
  File "C:\Users\g_and\AppData\Local\Programs\Python\Python312\Lib\site-packages\sqlalchemy\engine\base.py", line 1418, in execute
    return meth(
           ^^^^^
  File "C:\Users\g_and\AppData\Local\Programs\Python\Python312\Lib\site-packages\sqlalchemy\sql\elements.py", line 515, in _execute_on_connection
    return connection._execute_clauseelement(
           ^^^^^^^^^^^^^^^^^^^^^^^^^^^^^^^^^^
  File "C:\Users\g_and\AppData\Local\Programs\Python\Python312\Lib\site-packages\sqlalchemy\engine\base.py", line 1640, in _execute_clauseelement
    ret = self._execute_context(
          ^^^^^^^^^^^^^^^^^^^^^^
  File "C:\Users\g_and\AppData\Local\Programs\Python\Python312\Lib\site-packages\sqlalchemy\engine\base.py", line 1821, in _execute_context
    self._handle_dbapi_exception(
  File "C:\Users\g_and\AppData\Local\Programs\Python\Python312\Lib\site-packages\sqlalchemy\engine\base.py", line 2353, in _handle_dbapi_exception
    raise sqlalchemy_exception.with_traceback(exc_info[2]) from e
  File "C:\Users\g_and\AppData\Local\Programs\Python\Python312\Lib\site-packages\sqlalchemy\engine\base.py", line 1815, in _execute_context
    context = constructor(
              ^^^^^^^^^^^^
  File "C:\Users\g_and\AppData\Local\Programs\Python\Python312\Lib\site-packages\sqlalchemy\engine\default.py", line 1459, in _init_compiled
    flattened_processors[key](compiled_params[key])
  File "C:\Users\g_and\AppData\Local\Programs\Python\Python312\Lib\site-packages\sqlalchemy\dialects\sqlite\base.py", line 1142, in process
    raise TypeError(
sqlalchemy.exc.StatementError: (builtins.TypeError) SQLite Date type only accepts Python date objects as input.
[SQL: UPDATE items SET serial_number=?, bill_no=?, date_of_purchase=? WHERE items.item_id = ?]
[parameters: [{'date_of_purchase': 'Thu, 01 Feb 2024 00:00:00 GMT', 'serial_number': 12346, 'bill_no': 67891, 'items_item_id': 1}]]
2024-06-10 04:02:36,329 [ERROR] app.auth Exception (builtins.TypeError) SQLite Date type only accepts Python date objects as input.
[SQL: INSERT INTO items (item_name, serial_number, bill_no, date_of_purchase, assigned_to, warranty) VALUES (?, ?, ?, ?, ?, ?)]
[parameters: [{'serial_number': 12345, 'date_of_purchase': 'Mon, 01 Jan 2024 00:00:00 GMT', 'warranty': 'Wed, 01 Jan 2025 00:00:00 GMT', 'bill_no': 67890, 'item_name': 'item1', 'assigned_to': None}]] occurred while adding item 12345
Traceback (most recent call last):
  File "C:\Users\g_and\AppData\Local\Programs\Python\Python312\Lib\site-packages\sqlalchemy\engine\base.py", line 1815, in _execute_context
    context = constructor(
              ^^^^^^^^^^^^
  File "C:\Users\g_and\AppData\Local\Programs\Python\Python312\Lib\site-packages\sqlalchemy\engine\default.py", line 1459, in _init_compiled
    flattened_processors[key](compiled_params[key])
  File "C:\Users\g_and\AppData\Local\Programs\Python\Python312\Lib\site-packages\sqlalchemy\dialects\sqlite\base.py", line 1142, in process
    raise TypeError(
TypeError: SQLite Date type only accepts Python date objects as input.

The above exception was the direct cause of the following exception:

Traceback (most recent call last):
  File "c:\Users\g_and\Desktop\gihub\learning-documentation\capstone-project\inventory management system(flask)\app\items.py", line 22, in add_item
    db.session.commit()
  File "C:\Users\g_and\AppData\Local\Programs\Python\Python312\Lib\site-packages\sqlalchemy\orm\scoping.py", line 597, in commit
    return self._proxied.commit()
           ^^^^^^^^^^^^^^^^^^^^^^
  File "C:\Users\g_and\AppData\Local\Programs\Python\Python312\Lib\site-packages\sqlalchemy\orm\session.py", line 2017, in commit
    trans.commit(_to_root=True)
  File "<string>", line 2, in commit
  File "C:\Users\g_and\AppData\Local\Programs\Python\Python312\Lib\site-packages\sqlalchemy\orm\state_changes.py", line 139, in _go
    ret_value = fn(self, *arg, **kw)
                ^^^^^^^^^^^^^^^^^^^^
  File "C:\Users\g_and\AppData\Local\Programs\Python\Python312\Lib\site-packages\sqlalchemy\orm\session.py", line 1302, in commit
    self._prepare_impl()
  File "<string>", line 2, in _prepare_impl
  File "C:\Users\g_and\AppData\Local\Programs\Python\Python312\Lib\site-packages\sqlalchemy\orm\state_changes.py", line 139, in _go
    ret_value = fn(self, *arg, **kw)
                ^^^^^^^^^^^^^^^^^^^^
  File "C:\Users\g_and\AppData\Local\Programs\Python\Python312\Lib\site-packages\sqlalchemy\orm\session.py", line 1277, in _prepare_impl
    self.session.flush()
  File "C:\Users\g_and\AppData\Local\Programs\Python\Python312\Lib\site-packages\sqlalchemy\orm\session.py", line 4341, in flush
    self._flush(objects)
  File "C:\Users\g_and\AppData\Local\Programs\Python\Python312\Lib\site-packages\sqlalchemy\orm\session.py", line 4476, in _flush
    with util.safe_reraise():
  File "C:\Users\g_and\AppData\Local\Programs\Python\Python312\Lib\site-packages\sqlalchemy\util\langhelpers.py", line 146, in __exit__
    raise exc_value.with_traceback(exc_tb)
  File "C:\Users\g_and\AppData\Local\Programs\Python\Python312\Lib\site-packages\sqlalchemy\orm\session.py", line 4437, in _flush
    flush_context.execute()
  File "C:\Users\g_and\AppData\Local\Programs\Python\Python312\Lib\site-packages\sqlalchemy\orm\unitofwork.py", line 466, in execute
    rec.execute(self)
  File "C:\Users\g_and\AppData\Local\Programs\Python\Python312\Lib\site-packages\sqlalchemy\orm\unitofwork.py", line 642, in execute
    util.preloaded.orm_persistence.save_obj(
  File "C:\Users\g_and\AppData\Local\Programs\Python\Python312\Lib\site-packages\sqlalchemy\orm\persistence.py", line 93, in save_obj
    _emit_insert_statements(
  File "C:\Users\g_and\AppData\Local\Programs\Python\Python312\Lib\site-packages\sqlalchemy\orm\persistence.py", line 1233, in _emit_insert_statements
    result = connection.execute(
             ^^^^^^^^^^^^^^^^^^^
  File "C:\Users\g_and\AppData\Local\Programs\Python\Python312\Lib\site-packages\sqlalchemy\engine\base.py", line 1418, in execute
    return meth(
           ^^^^^
  File "C:\Users\g_and\AppData\Local\Programs\Python\Python312\Lib\site-packages\sqlalchemy\sql\elements.py", line 515, in _execute_on_connection
    return connection._execute_clauseelement(
           ^^^^^^^^^^^^^^^^^^^^^^^^^^^^^^^^^^
  File "C:\Users\g_and\AppData\Local\Programs\Python\Python312\Lib\site-packages\sqlalchemy\engine\base.py", line 1640, in _execute_clauseelement
    ret = self._execute_context(
          ^^^^^^^^^^^^^^^^^^^^^^
  File "C:\Users\g_and\AppData\Local\Programs\Python\Python312\Lib\site-packages\sqlalchemy\engine\base.py", line 1821, in _execute_context
    self._handle_dbapi_exception(
  File "C:\Users\g_and\AppData\Local\Programs\Python\Python312\Lib\site-packages\sqlalchemy\engine\base.py", line 2353, in _handle_dbapi_exception
    raise sqlalchemy_exception.with_traceback(exc_info[2]) from e
  File "C:\Users\g_and\AppData\Local\Programs\Python\Python312\Lib\site-packages\sqlalchemy\engine\base.py", line 1815, in _execute_context
    context = constructor(
              ^^^^^^^^^^^^
  File "C:\Users\g_and\AppData\Local\Programs\Python\Python312\Lib\site-packages\sqlalchemy\engine\default.py", line 1459, in _init_compiled
    flattened_processors[key](compiled_params[key])
  File "C:\Users\g_and\AppData\Local\Programs\Python\Python312\Lib\site-packages\sqlalchemy\dialects\sqlite\base.py", line 1142, in process
    raise TypeError(
sqlalchemy.exc.StatementError: (builtins.TypeError) SQLite Date type only accepts Python date objects as input.
[SQL: INSERT INTO items (item_name, serial_number, bill_no, date_of_purchase, assigned_to, warranty) VALUES (?, ?, ?, ?, ?, ?)]
[parameters: [{'serial_number': 12345, 'date_of_purchase': 'Mon, 01 Jan 2024 00:00:00 GMT', 'warranty': 'Wed, 01 Jan 2025 00:00:00 GMT', 'bill_no': 67890, 'item_name': 'item1', 'assigned_to': None}]]
2024-06-10 04:02:36,377 [INFO] app.main User newuser added by admins
2024-06-10 04:02:36,416 [INFO] app.main User newadminuser added by admin admins
2024-06-10 04:02:36,446 [INFO] app.main Admin admins accessed admin dashboard
2024-06-10 04:02:36,532 [INFO] app.main Password changed for user: testuser
2024-06-10 04:02:36,561 [INFO] app.main testuser accessed the dashboard
2024-06-10 04:02:36,608 [INFO] app.main User deluser deleted by admin admins
2024-06-10 04:02:36,654 [INFO] app.auth Item 1 deleted by admin admins
2024-06-10 04:02:36,686 [INFO] app.main Employee testuser accessed employee dashboard
2024-06-10 04:02:36,865 [WARNING] app.main Login page has arrived
2024-06-10 04:02:36,916 [INFO] app.auth Item 1 assigned to testuser by admin admins
2024-06-10 04:02:36,947 [WARNING] app.main Failed login attempt for username: wronguser
2024-06-10 04:02:36,989 [INFO] app.main User testuser logged in for the first time
2024-06-10 04:02:37,024 [INFO] app.main User testuser logged out
2024-06-10 04:02:37,089 [ERROR] app.auth Exception (builtins.TypeError) SQLite Date type only accepts Python date objects as input.
[SQL: UPDATE items SET serial_number=?, bill_no=?, date_of_purchase=? WHERE items.item_id = ?]
[parameters: [{'bill_no': 67891, 'date_of_purchase': 'Thu, 01 Feb 2024 00:00:00 GMT', 'serial_number': 12346, 'items_item_id': 1}]] occurred while updating item 1
Traceback (most recent call last):
  File "C:\Users\g_and\AppData\Local\Programs\Python\Python312\Lib\site-packages\sqlalchemy\engine\base.py", line 1815, in _execute_context
    context = constructor(
              ^^^^^^^^^^^^
  File "C:\Users\g_and\AppData\Local\Programs\Python\Python312\Lib\site-packages\sqlalchemy\engine\default.py", line 1459, in _init_compiled
    flattened_processors[key](compiled_params[key])
  File "C:\Users\g_and\AppData\Local\Programs\Python\Python312\Lib\site-packages\sqlalchemy\dialects\sqlite\base.py", line 1142, in process
    raise TypeError(
TypeError: SQLite Date type only accepts Python date objects as input.

The above exception was the direct cause of the following exception:

Traceback (most recent call last):
  File "c:\Users\g_and\Desktop\gihub\learning-documentation\capstone-project\inventory management system(flask)\app\items.py", line 45, in update_item
    db.session.commit()
  File "C:\Users\g_and\AppData\Local\Programs\Python\Python312\Lib\site-packages\sqlalchemy\orm\scoping.py", line 597, in commit
    return self._proxied.commit()
           ^^^^^^^^^^^^^^^^^^^^^^
  File "C:\Users\g_and\AppData\Local\Programs\Python\Python312\Lib\site-packages\sqlalchemy\orm\session.py", line 2017, in commit
    trans.commit(_to_root=True)
  File "<string>", line 2, in commit
  File "C:\Users\g_and\AppData\Local\Programs\Python\Python312\Lib\site-packages\sqlalchemy\orm\state_changes.py", line 139, in _go
    ret_value = fn(self, *arg, **kw)
                ^^^^^^^^^^^^^^^^^^^^
  File "C:\Users\g_and\AppData\Local\Programs\Python\Python312\Lib\site-packages\sqlalchemy\orm\session.py", line 1302, in commit
    self._prepare_impl()
  File "<string>", line 2, in _prepare_impl
  File "C:\Users\g_and\AppData\Local\Programs\Python\Python312\Lib\site-packages\sqlalchemy\orm\state_changes.py", line 139, in _go
    ret_value = fn(self, *arg, **kw)
                ^^^^^^^^^^^^^^^^^^^^
  File "C:\Users\g_and\AppData\Local\Programs\Python\Python312\Lib\site-packages\sqlalchemy\orm\session.py", line 1277, in _prepare_impl
    self.session.flush()
  File "C:\Users\g_and\AppData\Local\Programs\Python\Python312\Lib\site-packages\sqlalchemy\orm\session.py", line 4341, in flush
    self._flush(objects)
  File "C:\Users\g_and\AppData\Local\Programs\Python\Python312\Lib\site-packages\sqlalchemy\orm\session.py", line 4476, in _flush
    with util.safe_reraise():
  File "C:\Users\g_and\AppData\Local\Programs\Python\Python312\Lib\site-packages\sqlalchemy\util\langhelpers.py", line 146, in __exit__
    raise exc_value.with_traceback(exc_tb)
  File "C:\Users\g_and\AppData\Local\Programs\Python\Python312\Lib\site-packages\sqlalchemy\orm\session.py", line 4437, in _flush
    flush_context.execute()
  File "C:\Users\g_and\AppData\Local\Programs\Python\Python312\Lib\site-packages\sqlalchemy\orm\unitofwork.py", line 466, in execute
    rec.execute(self)
  File "C:\Users\g_and\AppData\Local\Programs\Python\Python312\Lib\site-packages\sqlalchemy\orm\unitofwork.py", line 642, in execute
    util.preloaded.orm_persistence.save_obj(
  File "C:\Users\g_and\AppData\Local\Programs\Python\Python312\Lib\site-packages\sqlalchemy\orm\persistence.py", line 85, in save_obj
    _emit_update_statements(
  File "C:\Users\g_and\AppData\Local\Programs\Python\Python312\Lib\site-packages\sqlalchemy\orm\persistence.py", line 912, in _emit_update_statements
    c = connection.execute(
        ^^^^^^^^^^^^^^^^^^^
  File "C:\Users\g_and\AppData\Local\Programs\Python\Python312\Lib\site-packages\sqlalchemy\engine\base.py", line 1418, in execute
    return meth(
           ^^^^^
  File "C:\Users\g_and\AppData\Local\Programs\Python\Python312\Lib\site-packages\sqlalchemy\sql\elements.py", line 515, in _execute_on_connection
    return connection._execute_clauseelement(
           ^^^^^^^^^^^^^^^^^^^^^^^^^^^^^^^^^^
  File "C:\Users\g_and\AppData\Local\Programs\Python\Python312\Lib\site-packages\sqlalchemy\engine\base.py", line 1640, in _execute_clauseelement
    ret = self._execute_context(
          ^^^^^^^^^^^^^^^^^^^^^^
  File "C:\Users\g_and\AppData\Local\Programs\Python\Python312\Lib\site-packages\sqlalchemy\engine\base.py", line 1821, in _execute_context
    self._handle_dbapi_exception(
  File "C:\Users\g_and\AppData\Local\Programs\Python\Python312\Lib\site-packages\sqlalchemy\engine\base.py", line 2353, in _handle_dbapi_exception
    raise sqlalchemy_exception.with_traceback(exc_info[2]) from e
  File "C:\Users\g_and\AppData\Local\Programs\Python\Python312\Lib\site-packages\sqlalchemy\engine\base.py", line 1815, in _execute_context
    context = constructor(
              ^^^^^^^^^^^^
  File "C:\Users\g_and\AppData\Local\Programs\Python\Python312\Lib\site-packages\sqlalchemy\engine\default.py", line 1459, in _init_compiled
    flattened_processors[key](compiled_params[key])
  File "C:\Users\g_and\AppData\Local\Programs\Python\Python312\Lib\site-packages\sqlalchemy\dialects\sqlite\base.py", line 1142, in process
    raise TypeError(
sqlalchemy.exc.StatementError: (builtins.TypeError) SQLite Date type only accepts Python date objects as input.
[SQL: UPDATE items SET serial_number=?, bill_no=?, date_of_purchase=? WHERE items.item_id = ?]
[parameters: [{'bill_no': 67891, 'date_of_purchase': 'Thu, 01 Feb 2024 00:00:00 GMT', 'serial_number': 12346, 'items_item_id': 1}]]
2024-06-10 04:02:52,821 [ERROR] app.auth Exception (builtins.TypeError) SQLite Date type only accepts Python date objects as input.
[SQL: INSERT INTO items (item_name, serial_number, bill_no, date_of_purchase, assigned_to, warranty) VALUES (?, ?, ?, ?, ?, ?)]
[parameters: [{'warranty': 'Wed, 01 Jan 2025 00:00:00 GMT', 'bill_no': 67890, 'date_of_purchase': 'Mon, 01 Jan 2024 00:00:00 GMT', 'item_name': 'item1', 'serial_number': 12345, 'assigned_to': None}]] occurred while adding item 12345
Traceback (most recent call last):
  File "C:\Users\g_and\AppData\Local\Programs\Python\Python312\Lib\site-packages\sqlalchemy\engine\base.py", line 1815, in _execute_context
    context = constructor(
              ^^^^^^^^^^^^
  File "C:\Users\g_and\AppData\Local\Programs\Python\Python312\Lib\site-packages\sqlalchemy\engine\default.py", line 1459, in _init_compiled
    flattened_processors[key](compiled_params[key])
  File "C:\Users\g_and\AppData\Local\Programs\Python\Python312\Lib\site-packages\sqlalchemy\dialects\sqlite\base.py", line 1142, in process
    raise TypeError(
TypeError: SQLite Date type only accepts Python date objects as input.

The above exception was the direct cause of the following exception:

Traceback (most recent call last):
  File "c:\Users\g_and\Desktop\gihub\learning-documentation\capstone-project\inventory management system(flask)\app\items.py", line 22, in add_item
    db.session.commit()
  File "C:\Users\g_and\AppData\Local\Programs\Python\Python312\Lib\site-packages\sqlalchemy\orm\scoping.py", line 597, in commit
    return self._proxied.commit()
           ^^^^^^^^^^^^^^^^^^^^^^
  File "C:\Users\g_and\AppData\Local\Programs\Python\Python312\Lib\site-packages\sqlalchemy\orm\session.py", line 2017, in commit
    trans.commit(_to_root=True)
  File "<string>", line 2, in commit
  File "C:\Users\g_and\AppData\Local\Programs\Python\Python312\Lib\site-packages\sqlalchemy\orm\state_changes.py", line 139, in _go
    ret_value = fn(self, *arg, **kw)
                ^^^^^^^^^^^^^^^^^^^^
  File "C:\Users\g_and\AppData\Local\Programs\Python\Python312\Lib\site-packages\sqlalchemy\orm\session.py", line 1302, in commit
    self._prepare_impl()
  File "<string>", line 2, in _prepare_impl
  File "C:\Users\g_and\AppData\Local\Programs\Python\Python312\Lib\site-packages\sqlalchemy\orm\state_changes.py", line 139, in _go
    ret_value = fn(self, *arg, **kw)
                ^^^^^^^^^^^^^^^^^^^^
  File "C:\Users\g_and\AppData\Local\Programs\Python\Python312\Lib\site-packages\sqlalchemy\orm\session.py", line 1277, in _prepare_impl
    self.session.flush()
  File "C:\Users\g_and\AppData\Local\Programs\Python\Python312\Lib\site-packages\sqlalchemy\orm\session.py", line 4341, in flush
    self._flush(objects)
  File "C:\Users\g_and\AppData\Local\Programs\Python\Python312\Lib\site-packages\sqlalchemy\orm\session.py", line 4476, in _flush
    with util.safe_reraise():
  File "C:\Users\g_and\AppData\Local\Programs\Python\Python312\Lib\site-packages\sqlalchemy\util\langhelpers.py", line 146, in __exit__
    raise exc_value.with_traceback(exc_tb)
  File "C:\Users\g_and\AppData\Local\Programs\Python\Python312\Lib\site-packages\sqlalchemy\orm\session.py", line 4437, in _flush
    flush_context.execute()
  File "C:\Users\g_and\AppData\Local\Programs\Python\Python312\Lib\site-packages\sqlalchemy\orm\unitofwork.py", line 466, in execute
    rec.execute(self)
  File "C:\Users\g_and\AppData\Local\Programs\Python\Python312\Lib\site-packages\sqlalchemy\orm\unitofwork.py", line 642, in execute
    util.preloaded.orm_persistence.save_obj(
  File "C:\Users\g_and\AppData\Local\Programs\Python\Python312\Lib\site-packages\sqlalchemy\orm\persistence.py", line 93, in save_obj
    _emit_insert_statements(
  File "C:\Users\g_and\AppData\Local\Programs\Python\Python312\Lib\site-packages\sqlalchemy\orm\persistence.py", line 1233, in _emit_insert_statements
    result = connection.execute(
             ^^^^^^^^^^^^^^^^^^^
  File "C:\Users\g_and\AppData\Local\Programs\Python\Python312\Lib\site-packages\sqlalchemy\engine\base.py", line 1418, in execute
    return meth(
           ^^^^^
  File "C:\Users\g_and\AppData\Local\Programs\Python\Python312\Lib\site-packages\sqlalchemy\sql\elements.py", line 515, in _execute_on_connection
    return connection._execute_clauseelement(
           ^^^^^^^^^^^^^^^^^^^^^^^^^^^^^^^^^^
  File "C:\Users\g_and\AppData\Local\Programs\Python\Python312\Lib\site-packages\sqlalchemy\engine\base.py", line 1640, in _execute_clauseelement
    ret = self._execute_context(
          ^^^^^^^^^^^^^^^^^^^^^^
  File "C:\Users\g_and\AppData\Local\Programs\Python\Python312\Lib\site-packages\sqlalchemy\engine\base.py", line 1821, in _execute_context
    self._handle_dbapi_exception(
  File "C:\Users\g_and\AppData\Local\Programs\Python\Python312\Lib\site-packages\sqlalchemy\engine\base.py", line 2353, in _handle_dbapi_exception
    raise sqlalchemy_exception.with_traceback(exc_info[2]) from e
  File "C:\Users\g_and\AppData\Local\Programs\Python\Python312\Lib\site-packages\sqlalchemy\engine\base.py", line 1815, in _execute_context
    context = constructor(
              ^^^^^^^^^^^^
  File "C:\Users\g_and\AppData\Local\Programs\Python\Python312\Lib\site-packages\sqlalchemy\engine\default.py", line 1459, in _init_compiled
    flattened_processors[key](compiled_params[key])
  File "C:\Users\g_and\AppData\Local\Programs\Python\Python312\Lib\site-packages\sqlalchemy\dialects\sqlite\base.py", line 1142, in process
    raise TypeError(
sqlalchemy.exc.StatementError: (builtins.TypeError) SQLite Date type only accepts Python date objects as input.
[SQL: INSERT INTO items (item_name, serial_number, bill_no, date_of_purchase, assigned_to, warranty) VALUES (?, ?, ?, ?, ?, ?)]
[parameters: [{'warranty': 'Wed, 01 Jan 2025 00:00:00 GMT', 'bill_no': 67890, 'date_of_purchase': 'Mon, 01 Jan 2024 00:00:00 GMT', 'item_name': 'item1', 'serial_number': 12345, 'assigned_to': None}]]
2024-06-10 04:02:52,871 [INFO] app.main User newuser added by admins
2024-06-10 04:02:52,912 [INFO] app.main User newadminuser added by admin admins
2024-06-10 04:02:52,941 [INFO] app.main Admin admins accessed admin dashboard
2024-06-10 04:02:53,023 [INFO] app.main Password changed for user: testuser
2024-06-10 04:02:53,053 [INFO] app.main testuser accessed the dashboard
2024-06-10 04:02:53,099 [INFO] app.main User deluser deleted by admin admins
2024-06-10 04:02:53,140 [INFO] app.auth Item 1 deleted by admin admins
2024-06-10 04:02:53,173 [INFO] app.main Employee testuser accessed employee dashboard
2024-06-10 04:02:53,351 [WARNING] app.main Login page has arrived
2024-06-10 04:02:53,409 [INFO] app.auth Item 1 assigned to testuser by admin admins
2024-06-10 04:02:53,444 [WARNING] app.main Failed login attempt for username: wronguser
2024-06-10 04:02:53,486 [INFO] app.main User testuser logged in for the first time
2024-06-10 04:02:53,516 [INFO] app.main User testuser logged out
2024-06-10 04:02:53,583 [ERROR] app.auth Exception (builtins.TypeError) SQLite Date type only accepts Python date objects as input.
[SQL: UPDATE items SET serial_number=?, bill_no=?, date_of_purchase=? WHERE items.item_id = ?]
[parameters: [{'date_of_purchase': 'Thu, 01 Feb 2024 00:00:00 GMT', 'bill_no': 67891, 'serial_number': 12346, 'items_item_id': 1}]] occurred while updating item 1
Traceback (most recent call last):
  File "C:\Users\g_and\AppData\Local\Programs\Python\Python312\Lib\site-packages\sqlalchemy\engine\base.py", line 1815, in _execute_context
    context = constructor(
              ^^^^^^^^^^^^
  File "C:\Users\g_and\AppData\Local\Programs\Python\Python312\Lib\site-packages\sqlalchemy\engine\default.py", line 1459, in _init_compiled
    flattened_processors[key](compiled_params[key])
  File "C:\Users\g_and\AppData\Local\Programs\Python\Python312\Lib\site-packages\sqlalchemy\dialects\sqlite\base.py", line 1142, in process
    raise TypeError(
TypeError: SQLite Date type only accepts Python date objects as input.

The above exception was the direct cause of the following exception:

Traceback (most recent call last):
  File "c:\Users\g_and\Desktop\gihub\learning-documentation\capstone-project\inventory management system(flask)\app\items.py", line 45, in update_item
    db.session.commit()
  File "C:\Users\g_and\AppData\Local\Programs\Python\Python312\Lib\site-packages\sqlalchemy\orm\scoping.py", line 597, in commit
    return self._proxied.commit()
           ^^^^^^^^^^^^^^^^^^^^^^
  File "C:\Users\g_and\AppData\Local\Programs\Python\Python312\Lib\site-packages\sqlalchemy\orm\session.py", line 2017, in commit
    trans.commit(_to_root=True)
  File "<string>", line 2, in commit
  File "C:\Users\g_and\AppData\Local\Programs\Python\Python312\Lib\site-packages\sqlalchemy\orm\state_changes.py", line 139, in _go
    ret_value = fn(self, *arg, **kw)
                ^^^^^^^^^^^^^^^^^^^^
  File "C:\Users\g_and\AppData\Local\Programs\Python\Python312\Lib\site-packages\sqlalchemy\orm\session.py", line 1302, in commit
    self._prepare_impl()
  File "<string>", line 2, in _prepare_impl
  File "C:\Users\g_and\AppData\Local\Programs\Python\Python312\Lib\site-packages\sqlalchemy\orm\state_changes.py", line 139, in _go
    ret_value = fn(self, *arg, **kw)
                ^^^^^^^^^^^^^^^^^^^^
  File "C:\Users\g_and\AppData\Local\Programs\Python\Python312\Lib\site-packages\sqlalchemy\orm\session.py", line 1277, in _prepare_impl
    self.session.flush()
  File "C:\Users\g_and\AppData\Local\Programs\Python\Python312\Lib\site-packages\sqlalchemy\orm\session.py", line 4341, in flush
    self._flush(objects)
  File "C:\Users\g_and\AppData\Local\Programs\Python\Python312\Lib\site-packages\sqlalchemy\orm\session.py", line 4476, in _flush
    with util.safe_reraise():
  File "C:\Users\g_and\AppData\Local\Programs\Python\Python312\Lib\site-packages\sqlalchemy\util\langhelpers.py", line 146, in __exit__
    raise exc_value.with_traceback(exc_tb)
  File "C:\Users\g_and\AppData\Local\Programs\Python\Python312\Lib\site-packages\sqlalchemy\orm\session.py", line 4437, in _flush
    flush_context.execute()
  File "C:\Users\g_and\AppData\Local\Programs\Python\Python312\Lib\site-packages\sqlalchemy\orm\unitofwork.py", line 466, in execute
    rec.execute(self)
  File "C:\Users\g_and\AppData\Local\Programs\Python\Python312\Lib\site-packages\sqlalchemy\orm\unitofwork.py", line 642, in execute
    util.preloaded.orm_persistence.save_obj(
  File "C:\Users\g_and\AppData\Local\Programs\Python\Python312\Lib\site-packages\sqlalchemy\orm\persistence.py", line 85, in save_obj
    _emit_update_statements(
  File "C:\Users\g_and\AppData\Local\Programs\Python\Python312\Lib\site-packages\sqlalchemy\orm\persistence.py", line 912, in _emit_update_statements
    c = connection.execute(
        ^^^^^^^^^^^^^^^^^^^
  File "C:\Users\g_and\AppData\Local\Programs\Python\Python312\Lib\site-packages\sqlalchemy\engine\base.py", line 1418, in execute
    return meth(
           ^^^^^
  File "C:\Users\g_and\AppData\Local\Programs\Python\Python312\Lib\site-packages\sqlalchemy\sql\elements.py", line 515, in _execute_on_connection
    return connection._execute_clauseelement(
           ^^^^^^^^^^^^^^^^^^^^^^^^^^^^^^^^^^
  File "C:\Users\g_and\AppData\Local\Programs\Python\Python312\Lib\site-packages\sqlalchemy\engine\base.py", line 1640, in _execute_clauseelement
    ret = self._execute_context(
          ^^^^^^^^^^^^^^^^^^^^^^
  File "C:\Users\g_and\AppData\Local\Programs\Python\Python312\Lib\site-packages\sqlalchemy\engine\base.py", line 1821, in _execute_context
    self._handle_dbapi_exception(
  File "C:\Users\g_and\AppData\Local\Programs\Python\Python312\Lib\site-packages\sqlalchemy\engine\base.py", line 2353, in _handle_dbapi_exception
    raise sqlalchemy_exception.with_traceback(exc_info[2]) from e
  File "C:\Users\g_and\AppData\Local\Programs\Python\Python312\Lib\site-packages\sqlalchemy\engine\base.py", line 1815, in _execute_context
    context = constructor(
              ^^^^^^^^^^^^
  File "C:\Users\g_and\AppData\Local\Programs\Python\Python312\Lib\site-packages\sqlalchemy\engine\default.py", line 1459, in _init_compiled
    flattened_processors[key](compiled_params[key])
  File "C:\Users\g_and\AppData\Local\Programs\Python\Python312\Lib\site-packages\sqlalchemy\dialects\sqlite\base.py", line 1142, in process
    raise TypeError(
sqlalchemy.exc.StatementError: (builtins.TypeError) SQLite Date type only accepts Python date objects as input.
[SQL: UPDATE items SET serial_number=?, bill_no=?, date_of_purchase=? WHERE items.item_id = ?]
[parameters: [{'date_of_purchase': 'Thu, 01 Feb 2024 00:00:00 GMT', 'bill_no': 67891, 'serial_number': 12346, 'items_item_id': 1}]]
2024-06-10 04:03:39,690 [ERROR] app.auth Exception (builtins.TypeError) SQLite Date type only accepts Python date objects as input.
[SQL: INSERT INTO items (item_name, serial_number, bill_no, date_of_purchase, assigned_to, warranty) VALUES (?, ?, ?, ?, ?, ?)]
[parameters: [{'serial_number': 12345, 'item_name': 'item1', 'date_of_purchase': 'Mon, 01 Jan 2024 00:00:00 GMT', 'warranty': 'Wed, 01 Jan 2025 00:00:00 GMT', 'bill_no': 67890, 'assigned_to': None}]] occurred while adding item 12345
Traceback (most recent call last):
  File "C:\Users\g_and\AppData\Local\Programs\Python\Python312\Lib\site-packages\sqlalchemy\engine\base.py", line 1815, in _execute_context
    context = constructor(
              ^^^^^^^^^^^^
  File "C:\Users\g_and\AppData\Local\Programs\Python\Python312\Lib\site-packages\sqlalchemy\engine\default.py", line 1459, in _init_compiled
    flattened_processors[key](compiled_params[key])
  File "C:\Users\g_and\AppData\Local\Programs\Python\Python312\Lib\site-packages\sqlalchemy\dialects\sqlite\base.py", line 1142, in process
    raise TypeError(
TypeError: SQLite Date type only accepts Python date objects as input.

The above exception was the direct cause of the following exception:

Traceback (most recent call last):
  File "c:\Users\g_and\Desktop\gihub\learning-documentation\capstone-project\inventory management system(flask)\app\items.py", line 22, in add_item
    db.session.commit()
  File "C:\Users\g_and\AppData\Local\Programs\Python\Python312\Lib\site-packages\sqlalchemy\orm\scoping.py", line 597, in commit
    return self._proxied.commit()
           ^^^^^^^^^^^^^^^^^^^^^^
  File "C:\Users\g_and\AppData\Local\Programs\Python\Python312\Lib\site-packages\sqlalchemy\orm\session.py", line 2017, in commit
    trans.commit(_to_root=True)
  File "<string>", line 2, in commit
  File "C:\Users\g_and\AppData\Local\Programs\Python\Python312\Lib\site-packages\sqlalchemy\orm\state_changes.py", line 139, in _go
    ret_value = fn(self, *arg, **kw)
                ^^^^^^^^^^^^^^^^^^^^
  File "C:\Users\g_and\AppData\Local\Programs\Python\Python312\Lib\site-packages\sqlalchemy\orm\session.py", line 1302, in commit
    self._prepare_impl()
  File "<string>", line 2, in _prepare_impl
  File "C:\Users\g_and\AppData\Local\Programs\Python\Python312\Lib\site-packages\sqlalchemy\orm\state_changes.py", line 139, in _go
    ret_value = fn(self, *arg, **kw)
                ^^^^^^^^^^^^^^^^^^^^
  File "C:\Users\g_and\AppData\Local\Programs\Python\Python312\Lib\site-packages\sqlalchemy\orm\session.py", line 1277, in _prepare_impl
    self.session.flush()
  File "C:\Users\g_and\AppData\Local\Programs\Python\Python312\Lib\site-packages\sqlalchemy\orm\session.py", line 4341, in flush
    self._flush(objects)
  File "C:\Users\g_and\AppData\Local\Programs\Python\Python312\Lib\site-packages\sqlalchemy\orm\session.py", line 4476, in _flush
    with util.safe_reraise():
  File "C:\Users\g_and\AppData\Local\Programs\Python\Python312\Lib\site-packages\sqlalchemy\util\langhelpers.py", line 146, in __exit__
    raise exc_value.with_traceback(exc_tb)
  File "C:\Users\g_and\AppData\Local\Programs\Python\Python312\Lib\site-packages\sqlalchemy\orm\session.py", line 4437, in _flush
    flush_context.execute()
  File "C:\Users\g_and\AppData\Local\Programs\Python\Python312\Lib\site-packages\sqlalchemy\orm\unitofwork.py", line 466, in execute
    rec.execute(self)
  File "C:\Users\g_and\AppData\Local\Programs\Python\Python312\Lib\site-packages\sqlalchemy\orm\unitofwork.py", line 642, in execute
    util.preloaded.orm_persistence.save_obj(
  File "C:\Users\g_and\AppData\Local\Programs\Python\Python312\Lib\site-packages\sqlalchemy\orm\persistence.py", line 93, in save_obj
    _emit_insert_statements(
  File "C:\Users\g_and\AppData\Local\Programs\Python\Python312\Lib\site-packages\sqlalchemy\orm\persistence.py", line 1233, in _emit_insert_statements
    result = connection.execute(
             ^^^^^^^^^^^^^^^^^^^
  File "C:\Users\g_and\AppData\Local\Programs\Python\Python312\Lib\site-packages\sqlalchemy\engine\base.py", line 1418, in execute
    return meth(
           ^^^^^
  File "C:\Users\g_and\AppData\Local\Programs\Python\Python312\Lib\site-packages\sqlalchemy\sql\elements.py", line 515, in _execute_on_connection
    return connection._execute_clauseelement(
           ^^^^^^^^^^^^^^^^^^^^^^^^^^^^^^^^^^
  File "C:\Users\g_and\AppData\Local\Programs\Python\Python312\Lib\site-packages\sqlalchemy\engine\base.py", line 1640, in _execute_clauseelement
    ret = self._execute_context(
          ^^^^^^^^^^^^^^^^^^^^^^
  File "C:\Users\g_and\AppData\Local\Programs\Python\Python312\Lib\site-packages\sqlalchemy\engine\base.py", line 1821, in _execute_context
    self._handle_dbapi_exception(
  File "C:\Users\g_and\AppData\Local\Programs\Python\Python312\Lib\site-packages\sqlalchemy\engine\base.py", line 2353, in _handle_dbapi_exception
    raise sqlalchemy_exception.with_traceback(exc_info[2]) from e
  File "C:\Users\g_and\AppData\Local\Programs\Python\Python312\Lib\site-packages\sqlalchemy\engine\base.py", line 1815, in _execute_context
    context = constructor(
              ^^^^^^^^^^^^
  File "C:\Users\g_and\AppData\Local\Programs\Python\Python312\Lib\site-packages\sqlalchemy\engine\default.py", line 1459, in _init_compiled
    flattened_processors[key](compiled_params[key])
  File "C:\Users\g_and\AppData\Local\Programs\Python\Python312\Lib\site-packages\sqlalchemy\dialects\sqlite\base.py", line 1142, in process
    raise TypeError(
sqlalchemy.exc.StatementError: (builtins.TypeError) SQLite Date type only accepts Python date objects as input.
[SQL: INSERT INTO items (item_name, serial_number, bill_no, date_of_purchase, assigned_to, warranty) VALUES (?, ?, ?, ?, ?, ?)]
[parameters: [{'serial_number': 12345, 'item_name': 'item1', 'date_of_purchase': 'Mon, 01 Jan 2024 00:00:00 GMT', 'warranty': 'Wed, 01 Jan 2025 00:00:00 GMT', 'bill_no': 67890, 'assigned_to': None}]]
2024-06-10 04:03:39,741 [INFO] app.main User newuser added by admins
2024-06-10 04:03:39,775 [INFO] app.main User newadminuser added by admin admins
2024-06-10 04:03:39,803 [INFO] app.main Admin admins accessed admin dashboard
2024-06-10 04:03:39,881 [INFO] app.main Password changed for user: testuser
2024-06-10 04:03:39,913 [INFO] app.main testuser accessed the dashboard
2024-06-10 04:03:39,951 [INFO] app.main User deluser deleted by admin admins
2024-06-10 04:03:40,000 [INFO] app.auth Item 1 deleted by admin admins
2024-06-10 04:03:40,029 [INFO] app.main Employee testuser accessed employee dashboard
2024-06-10 04:03:40,211 [WARNING] app.main Login page has arrived
2024-06-10 04:03:40,259 [INFO] app.auth Item 1 assigned to testuser by admin admins
2024-06-10 04:03:40,304 [WARNING] app.main Failed login attempt for username: wronguser
2024-06-10 04:03:40,347 [INFO] app.main User testuser logged in for the first time
2024-06-10 04:03:40,377 [INFO] app.main User testuser logged out
2024-06-10 04:03:40,446 [ERROR] app.auth Exception (builtins.TypeError) SQLite Date type only accepts Python date objects as input.
[SQL: UPDATE items SET serial_number=?, bill_no=?, date_of_purchase=? WHERE items.item_id = ?]
[parameters: [{'serial_number': 12346, 'bill_no': 67891, 'date_of_purchase': 'Thu, 01 Feb 2024 00:00:00 GMT', 'items_item_id': 1}]] occurred while updating item 1
Traceback (most recent call last):
  File "C:\Users\g_and\AppData\Local\Programs\Python\Python312\Lib\site-packages\sqlalchemy\engine\base.py", line 1815, in _execute_context
    context = constructor(
              ^^^^^^^^^^^^
  File "C:\Users\g_and\AppData\Local\Programs\Python\Python312\Lib\site-packages\sqlalchemy\engine\default.py", line 1459, in _init_compiled
    flattened_processors[key](compiled_params[key])
  File "C:\Users\g_and\AppData\Local\Programs\Python\Python312\Lib\site-packages\sqlalchemy\dialects\sqlite\base.py", line 1142, in process
    raise TypeError(
TypeError: SQLite Date type only accepts Python date objects as input.

The above exception was the direct cause of the following exception:

Traceback (most recent call last):
  File "c:\Users\g_and\Desktop\gihub\learning-documentation\capstone-project\inventory management system(flask)\app\items.py", line 45, in update_item
    db.session.commit()
  File "C:\Users\g_and\AppData\Local\Programs\Python\Python312\Lib\site-packages\sqlalchemy\orm\scoping.py", line 597, in commit
    return self._proxied.commit()
           ^^^^^^^^^^^^^^^^^^^^^^
  File "C:\Users\g_and\AppData\Local\Programs\Python\Python312\Lib\site-packages\sqlalchemy\orm\session.py", line 2017, in commit
    trans.commit(_to_root=True)
  File "<string>", line 2, in commit
  File "C:\Users\g_and\AppData\Local\Programs\Python\Python312\Lib\site-packages\sqlalchemy\orm\state_changes.py", line 139, in _go
    ret_value = fn(self, *arg, **kw)
                ^^^^^^^^^^^^^^^^^^^^
  File "C:\Users\g_and\AppData\Local\Programs\Python\Python312\Lib\site-packages\sqlalchemy\orm\session.py", line 1302, in commit
    self._prepare_impl()
  File "<string>", line 2, in _prepare_impl
  File "C:\Users\g_and\AppData\Local\Programs\Python\Python312\Lib\site-packages\sqlalchemy\orm\state_changes.py", line 139, in _go
    ret_value = fn(self, *arg, **kw)
                ^^^^^^^^^^^^^^^^^^^^
  File "C:\Users\g_and\AppData\Local\Programs\Python\Python312\Lib\site-packages\sqlalchemy\orm\session.py", line 1277, in _prepare_impl
    self.session.flush()
  File "C:\Users\g_and\AppData\Local\Programs\Python\Python312\Lib\site-packages\sqlalchemy\orm\session.py", line 4341, in flush
    self._flush(objects)
  File "C:\Users\g_and\AppData\Local\Programs\Python\Python312\Lib\site-packages\sqlalchemy\orm\session.py", line 4476, in _flush
    with util.safe_reraise():
  File "C:\Users\g_and\AppData\Local\Programs\Python\Python312\Lib\site-packages\sqlalchemy\util\langhelpers.py", line 146, in __exit__
    raise exc_value.with_traceback(exc_tb)
  File "C:\Users\g_and\AppData\Local\Programs\Python\Python312\Lib\site-packages\sqlalchemy\orm\session.py", line 4437, in _flush
    flush_context.execute()
  File "C:\Users\g_and\AppData\Local\Programs\Python\Python312\Lib\site-packages\sqlalchemy\orm\unitofwork.py", line 466, in execute
    rec.execute(self)
  File "C:\Users\g_and\AppData\Local\Programs\Python\Python312\Lib\site-packages\sqlalchemy\orm\unitofwork.py", line 642, in execute
    util.preloaded.orm_persistence.save_obj(
  File "C:\Users\g_and\AppData\Local\Programs\Python\Python312\Lib\site-packages\sqlalchemy\orm\persistence.py", line 85, in save_obj
    _emit_update_statements(
  File "C:\Users\g_and\AppData\Local\Programs\Python\Python312\Lib\site-packages\sqlalchemy\orm\persistence.py", line 912, in _emit_update_statements
    c = connection.execute(
        ^^^^^^^^^^^^^^^^^^^
  File "C:\Users\g_and\AppData\Local\Programs\Python\Python312\Lib\site-packages\sqlalchemy\engine\base.py", line 1418, in execute
    return meth(
           ^^^^^
  File "C:\Users\g_and\AppData\Local\Programs\Python\Python312\Lib\site-packages\sqlalchemy\sql\elements.py", line 515, in _execute_on_connection
    return connection._execute_clauseelement(
           ^^^^^^^^^^^^^^^^^^^^^^^^^^^^^^^^^^
  File "C:\Users\g_and\AppData\Local\Programs\Python\Python312\Lib\site-packages\sqlalchemy\engine\base.py", line 1640, in _execute_clauseelement
    ret = self._execute_context(
          ^^^^^^^^^^^^^^^^^^^^^^
  File "C:\Users\g_and\AppData\Local\Programs\Python\Python312\Lib\site-packages\sqlalchemy\engine\base.py", line 1821, in _execute_context
    self._handle_dbapi_exception(
  File "C:\Users\g_and\AppData\Local\Programs\Python\Python312\Lib\site-packages\sqlalchemy\engine\base.py", line 2353, in _handle_dbapi_exception
    raise sqlalchemy_exception.with_traceback(exc_info[2]) from e
  File "C:\Users\g_and\AppData\Local\Programs\Python\Python312\Lib\site-packages\sqlalchemy\engine\base.py", line 1815, in _execute_context
    context = constructor(
              ^^^^^^^^^^^^
  File "C:\Users\g_and\AppData\Local\Programs\Python\Python312\Lib\site-packages\sqlalchemy\engine\default.py", line 1459, in _init_compiled
    flattened_processors[key](compiled_params[key])
  File "C:\Users\g_and\AppData\Local\Programs\Python\Python312\Lib\site-packages\sqlalchemy\dialects\sqlite\base.py", line 1142, in process
    raise TypeError(
sqlalchemy.exc.StatementError: (builtins.TypeError) SQLite Date type only accepts Python date objects as input.
[SQL: UPDATE items SET serial_number=?, bill_no=?, date_of_purchase=? WHERE items.item_id = ?]
[parameters: [{'serial_number': 12346, 'bill_no': 67891, 'date_of_purchase': 'Thu, 01 Feb 2024 00:00:00 GMT', 'items_item_id': 1}]]
2024-06-10 04:09:31,884 [INFO] app.main User newuser added by admins
2024-06-10 04:09:31,921 [INFO] app.main User newadminuser added by admin admins
2024-06-10 04:09:31,951 [INFO] app.main Admin admins accessed admin dashboard
2024-06-10 04:09:32,030 [INFO] app.main Password changed for user: testuser
2024-06-10 04:09:32,063 [INFO] app.main testuser accessed the dashboard
2024-06-10 04:09:32,107 [INFO] app.main User deluser deleted by admin admins
2024-06-10 04:09:32,150 [INFO] app.auth Item 1 deleted by admin admins
2024-06-10 04:09:32,182 [INFO] app.main Employee testuser accessed employee dashboard
2024-06-10 04:09:32,356 [WARNING] app.main Login page has arrived
2024-06-10 04:09:32,402 [INFO] app.auth Item 1 assigned to testuser by admin admins
2024-06-10 04:09:32,431 [WARNING] app.main Failed login attempt for username: wronguser
2024-06-10 04:09:32,472 [INFO] app.main User testuser logged in for the first time
2024-06-10 04:09:32,500 [INFO] app.main User testuser logged out
2024-06-10 04:09:32,571 [ERROR] app.auth Exception (builtins.TypeError) SQLite Date type only accepts Python date objects as input.
[SQL: UPDATE items SET serial_number=?, bill_no=?, date_of_purchase=? WHERE items.item_id = ?]
[parameters: [{'date_of_purchase': 'Thu, 01 Feb 2024 00:00:00 GMT', 'bill_no': 67891, 'serial_number': 12346, 'items_item_id': 1}]] occurred while updating item 1
Traceback (most recent call last):
  File "C:\Users\g_and\AppData\Local\Programs\Python\Python312\Lib\site-packages\sqlalchemy\engine\base.py", line 1815, in _execute_context
    context = constructor(
              ^^^^^^^^^^^^
  File "C:\Users\g_and\AppData\Local\Programs\Python\Python312\Lib\site-packages\sqlalchemy\engine\default.py", line 1459, in _init_compiled
    flattened_processors[key](compiled_params[key])
  File "C:\Users\g_and\AppData\Local\Programs\Python\Python312\Lib\site-packages\sqlalchemy\dialects\sqlite\base.py", line 1142, in process
    raise TypeError(
TypeError: SQLite Date type only accepts Python date objects as input.

The above exception was the direct cause of the following exception:

Traceback (most recent call last):
  File "c:\Users\g_and\Desktop\gihub\learning-documentation\capstone-project\inventory management system(flask)\app\items.py", line 48, in update_item
    db.session.commit()
  File "C:\Users\g_and\AppData\Local\Programs\Python\Python312\Lib\site-packages\sqlalchemy\orm\scoping.py", line 597, in commit
    return self._proxied.commit()
           ^^^^^^^^^^^^^^^^^^^^^^
  File "C:\Users\g_and\AppData\Local\Programs\Python\Python312\Lib\site-packages\sqlalchemy\orm\session.py", line 2017, in commit
    trans.commit(_to_root=True)
  File "<string>", line 2, in commit
  File "C:\Users\g_and\AppData\Local\Programs\Python\Python312\Lib\site-packages\sqlalchemy\orm\state_changes.py", line 139, in _go
    ret_value = fn(self, *arg, **kw)
                ^^^^^^^^^^^^^^^^^^^^
  File "C:\Users\g_and\AppData\Local\Programs\Python\Python312\Lib\site-packages\sqlalchemy\orm\session.py", line 1302, in commit
    self._prepare_impl()
  File "<string>", line 2, in _prepare_impl
  File "C:\Users\g_and\AppData\Local\Programs\Python\Python312\Lib\site-packages\sqlalchemy\orm\state_changes.py", line 139, in _go
    ret_value = fn(self, *arg, **kw)
                ^^^^^^^^^^^^^^^^^^^^
  File "C:\Users\g_and\AppData\Local\Programs\Python\Python312\Lib\site-packages\sqlalchemy\orm\session.py", line 1277, in _prepare_impl
    self.session.flush()
  File "C:\Users\g_and\AppData\Local\Programs\Python\Python312\Lib\site-packages\sqlalchemy\orm\session.py", line 4341, in flush
    self._flush(objects)
  File "C:\Users\g_and\AppData\Local\Programs\Python\Python312\Lib\site-packages\sqlalchemy\orm\session.py", line 4476, in _flush
    with util.safe_reraise():
  File "C:\Users\g_and\AppData\Local\Programs\Python\Python312\Lib\site-packages\sqlalchemy\util\langhelpers.py", line 146, in __exit__
    raise exc_value.with_traceback(exc_tb)
  File "C:\Users\g_and\AppData\Local\Programs\Python\Python312\Lib\site-packages\sqlalchemy\orm\session.py", line 4437, in _flush
    flush_context.execute()
  File "C:\Users\g_and\AppData\Local\Programs\Python\Python312\Lib\site-packages\sqlalchemy\orm\unitofwork.py", line 466, in execute
    rec.execute(self)
  File "C:\Users\g_and\AppData\Local\Programs\Python\Python312\Lib\site-packages\sqlalchemy\orm\unitofwork.py", line 642, in execute
    util.preloaded.orm_persistence.save_obj(
  File "C:\Users\g_and\AppData\Local\Programs\Python\Python312\Lib\site-packages\sqlalchemy\orm\persistence.py", line 85, in save_obj
    _emit_update_statements(
  File "C:\Users\g_and\AppData\Local\Programs\Python\Python312\Lib\site-packages\sqlalchemy\orm\persistence.py", line 912, in _emit_update_statements
    c = connection.execute(
        ^^^^^^^^^^^^^^^^^^^
  File "C:\Users\g_and\AppData\Local\Programs\Python\Python312\Lib\site-packages\sqlalchemy\engine\base.py", line 1418, in execute
    return meth(
           ^^^^^
  File "C:\Users\g_and\AppData\Local\Programs\Python\Python312\Lib\site-packages\sqlalchemy\sql\elements.py", line 515, in _execute_on_connection
    return connection._execute_clauseelement(
           ^^^^^^^^^^^^^^^^^^^^^^^^^^^^^^^^^^
  File "C:\Users\g_and\AppData\Local\Programs\Python\Python312\Lib\site-packages\sqlalchemy\engine\base.py", line 1640, in _execute_clauseelement
    ret = self._execute_context(
          ^^^^^^^^^^^^^^^^^^^^^^
  File "C:\Users\g_and\AppData\Local\Programs\Python\Python312\Lib\site-packages\sqlalchemy\engine\base.py", line 1821, in _execute_context
    self._handle_dbapi_exception(
  File "C:\Users\g_and\AppData\Local\Programs\Python\Python312\Lib\site-packages\sqlalchemy\engine\base.py", line 2353, in _handle_dbapi_exception
    raise sqlalchemy_exception.with_traceback(exc_info[2]) from e
  File "C:\Users\g_and\AppData\Local\Programs\Python\Python312\Lib\site-packages\sqlalchemy\engine\base.py", line 1815, in _execute_context
    context = constructor(
              ^^^^^^^^^^^^
  File "C:\Users\g_and\AppData\Local\Programs\Python\Python312\Lib\site-packages\sqlalchemy\engine\default.py", line 1459, in _init_compiled
    flattened_processors[key](compiled_params[key])
  File "C:\Users\g_and\AppData\Local\Programs\Python\Python312\Lib\site-packages\sqlalchemy\dialects\sqlite\base.py", line 1142, in process
    raise TypeError(
sqlalchemy.exc.StatementError: (builtins.TypeError) SQLite Date type only accepts Python date objects as input.
[SQL: UPDATE items SET serial_number=?, bill_no=?, date_of_purchase=? WHERE items.item_id = ?]
[parameters: [{'date_of_purchase': 'Thu, 01 Feb 2024 00:00:00 GMT', 'bill_no': 67891, 'serial_number': 12346, 'items_item_id': 1}]]
2024-06-10 04:09:42,146 [INFO] app.main User newuser added by admins
2024-06-10 04:09:42,187 [INFO] app.main User newadminuser added by admin admins
2024-06-10 04:09:42,215 [INFO] app.main Admin admins accessed admin dashboard
2024-06-10 04:09:42,300 [INFO] app.main Password changed for user: testuser
2024-06-10 04:09:42,330 [INFO] app.main testuser accessed the dashboard
2024-06-10 04:09:42,369 [INFO] app.main User deluser deleted by admin admins
2024-06-10 04:09:42,420 [INFO] app.auth Item 1 deleted by admin admins
2024-06-10 04:09:42,452 [INFO] app.main Employee testuser accessed employee dashboard
2024-06-10 04:09:42,635 [WARNING] app.main Login page has arrived
2024-06-10 04:09:42,688 [INFO] app.auth Item 1 assigned to testuser by admin admins
2024-06-10 04:09:42,719 [WARNING] app.main Failed login attempt for username: wronguser
2024-06-10 04:09:42,763 [INFO] app.main User testuser logged in for the first time
2024-06-10 04:09:42,899 [INFO] app.main User testuser logged out
2024-06-10 04:09:42,970 [ERROR] app.auth Exception (builtins.TypeError) SQLite Date type only accepts Python date objects as input.
[SQL: UPDATE items SET serial_number=?, bill_no=?, date_of_purchase=? WHERE items.item_id = ?]
[parameters: [{'serial_number': 12346, 'bill_no': 67891, 'date_of_purchase': 'Thu, 01 Feb 2024 00:00:00 GMT', 'items_item_id': 1}]] occurred while updating item 1
Traceback (most recent call last):
  File "C:\Users\g_and\AppData\Local\Programs\Python\Python312\Lib\site-packages\sqlalchemy\engine\base.py", line 1815, in _execute_context
    context = constructor(
              ^^^^^^^^^^^^
  File "C:\Users\g_and\AppData\Local\Programs\Python\Python312\Lib\site-packages\sqlalchemy\engine\default.py", line 1459, in _init_compiled
    flattened_processors[key](compiled_params[key])
  File "C:\Users\g_and\AppData\Local\Programs\Python\Python312\Lib\site-packages\sqlalchemy\dialects\sqlite\base.py", line 1142, in process
    raise TypeError(
TypeError: SQLite Date type only accepts Python date objects as input.

The above exception was the direct cause of the following exception:

Traceback (most recent call last):
  File "c:\Users\g_and\Desktop\gihub\learning-documentation\capstone-project\inventory management system(flask)\app\items.py", line 48, in update_item
    db.session.commit()
  File "C:\Users\g_and\AppData\Local\Programs\Python\Python312\Lib\site-packages\sqlalchemy\orm\scoping.py", line 597, in commit
    return self._proxied.commit()
           ^^^^^^^^^^^^^^^^^^^^^^
  File "C:\Users\g_and\AppData\Local\Programs\Python\Python312\Lib\site-packages\sqlalchemy\orm\session.py", line 2017, in commit
    trans.commit(_to_root=True)
  File "<string>", line 2, in commit
  File "C:\Users\g_and\AppData\Local\Programs\Python\Python312\Lib\site-packages\sqlalchemy\orm\state_changes.py", line 139, in _go
    ret_value = fn(self, *arg, **kw)
                ^^^^^^^^^^^^^^^^^^^^
  File "C:\Users\g_and\AppData\Local\Programs\Python\Python312\Lib\site-packages\sqlalchemy\orm\session.py", line 1302, in commit
    self._prepare_impl()
  File "<string>", line 2, in _prepare_impl
  File "C:\Users\g_and\AppData\Local\Programs\Python\Python312\Lib\site-packages\sqlalchemy\orm\state_changes.py", line 139, in _go
    ret_value = fn(self, *arg, **kw)
                ^^^^^^^^^^^^^^^^^^^^
  File "C:\Users\g_and\AppData\Local\Programs\Python\Python312\Lib\site-packages\sqlalchemy\orm\session.py", line 1277, in _prepare_impl
    self.session.flush()
  File "C:\Users\g_and\AppData\Local\Programs\Python\Python312\Lib\site-packages\sqlalchemy\orm\session.py", line 4341, in flush
    self._flush(objects)
  File "C:\Users\g_and\AppData\Local\Programs\Python\Python312\Lib\site-packages\sqlalchemy\orm\session.py", line 4476, in _flush
    with util.safe_reraise():
  File "C:\Users\g_and\AppData\Local\Programs\Python\Python312\Lib\site-packages\sqlalchemy\util\langhelpers.py", line 146, in __exit__
    raise exc_value.with_traceback(exc_tb)
  File "C:\Users\g_and\AppData\Local\Programs\Python\Python312\Lib\site-packages\sqlalchemy\orm\session.py", line 4437, in _flush
    flush_context.execute()
  File "C:\Users\g_and\AppData\Local\Programs\Python\Python312\Lib\site-packages\sqlalchemy\orm\unitofwork.py", line 466, in execute
    rec.execute(self)
  File "C:\Users\g_and\AppData\Local\Programs\Python\Python312\Lib\site-packages\sqlalchemy\orm\unitofwork.py", line 642, in execute
    util.preloaded.orm_persistence.save_obj(
  File "C:\Users\g_and\AppData\Local\Programs\Python\Python312\Lib\site-packages\sqlalchemy\orm\persistence.py", line 85, in save_obj
    _emit_update_statements(
  File "C:\Users\g_and\AppData\Local\Programs\Python\Python312\Lib\site-packages\sqlalchemy\orm\persistence.py", line 912, in _emit_update_statements
    c = connection.execute(
        ^^^^^^^^^^^^^^^^^^^
  File "C:\Users\g_and\AppData\Local\Programs\Python\Python312\Lib\site-packages\sqlalchemy\engine\base.py", line 1418, in execute
    return meth(
           ^^^^^
  File "C:\Users\g_and\AppData\Local\Programs\Python\Python312\Lib\site-packages\sqlalchemy\sql\elements.py", line 515, in _execute_on_connection
    return connection._execute_clauseelement(
           ^^^^^^^^^^^^^^^^^^^^^^^^^^^^^^^^^^
  File "C:\Users\g_and\AppData\Local\Programs\Python\Python312\Lib\site-packages\sqlalchemy\engine\base.py", line 1640, in _execute_clauseelement
    ret = self._execute_context(
          ^^^^^^^^^^^^^^^^^^^^^^
  File "C:\Users\g_and\AppData\Local\Programs\Python\Python312\Lib\site-packages\sqlalchemy\engine\base.py", line 1821, in _execute_context
    self._handle_dbapi_exception(
  File "C:\Users\g_and\AppData\Local\Programs\Python\Python312\Lib\site-packages\sqlalchemy\engine\base.py", line 2353, in _handle_dbapi_exception
    raise sqlalchemy_exception.with_traceback(exc_info[2]) from e
  File "C:\Users\g_and\AppData\Local\Programs\Python\Python312\Lib\site-packages\sqlalchemy\engine\base.py", line 1815, in _execute_context
    context = constructor(
              ^^^^^^^^^^^^
  File "C:\Users\g_and\AppData\Local\Programs\Python\Python312\Lib\site-packages\sqlalchemy\engine\default.py", line 1459, in _init_compiled
    flattened_processors[key](compiled_params[key])
  File "C:\Users\g_and\AppData\Local\Programs\Python\Python312\Lib\site-packages\sqlalchemy\dialects\sqlite\base.py", line 1142, in process
    raise TypeError(
sqlalchemy.exc.StatementError: (builtins.TypeError) SQLite Date type only accepts Python date objects as input.
[SQL: UPDATE items SET serial_number=?, bill_no=?, date_of_purchase=? WHERE items.item_id = ?]
[parameters: [{'serial_number': 12346, 'bill_no': 67891, 'date_of_purchase': 'Thu, 01 Feb 2024 00:00:00 GMT', 'items_item_id': 1}]]
2024-06-10 04:10:37,633 [INFO] app.main User newuser added by admins
2024-06-10 04:10:37,671 [INFO] app.main User newadminuser added by admin admins
2024-06-10 04:10:37,703 [INFO] app.main Admin admins accessed admin dashboard
2024-06-10 04:10:37,789 [INFO] app.main Password changed for user: testuser
2024-06-10 04:10:37,818 [INFO] app.main testuser accessed the dashboard
2024-06-10 04:10:37,864 [INFO] app.main User deluser deleted by admin admins
2024-06-10 04:10:37,905 [INFO] app.auth Item 1 deleted by admin admins
2024-06-10 04:10:37,939 [INFO] app.main Employee testuser accessed employee dashboard
2024-06-10 04:10:38,120 [WARNING] app.main Login page has arrived
2024-06-10 04:10:38,172 [INFO] app.auth Item 1 assigned to testuser by admin admins
2024-06-10 04:10:38,204 [WARNING] app.main Failed login attempt for username: wronguser
2024-06-10 04:10:38,247 [INFO] app.main User testuser logged in for the first time
2024-06-10 04:10:38,278 [INFO] app.main User testuser logged out
2024-06-10 04:16:50,311 [INFO] app.auth Item 12345 added by admin admins
2024-06-10 04:16:50,345 [INFO] app.main User newuser added by admins
2024-06-10 04:16:50,383 [INFO] app.main User newadminuser added by admin admins
2024-06-10 04:16:50,413 [INFO] app.main Admin admins accessed admin dashboard
2024-06-10 04:16:50,498 [INFO] app.main Password changed for user: testuser
2024-06-10 04:16:50,529 [INFO] app.main testuser accessed the dashboard
2024-06-10 04:16:50,576 [INFO] app.main User deluser deleted by admin admins
2024-06-10 04:16:50,621 [INFO] app.auth Item 1 deleted by admin admins
2024-06-10 04:16:50,652 [INFO] app.main Employee testuser accessed employee dashboard
2024-06-10 04:16:50,848 [WARNING] app.main Login page has arrived
2024-06-10 04:16:50,900 [INFO] app.auth Item 1 assigned to testuser by admin admins
2024-06-10 04:16:50,929 [WARNING] app.main Failed login attempt for username: wronguser
2024-06-10 04:16:50,972 [INFO] app.main User testuser logged in for the first time
2024-06-10 04:16:51,002 [INFO] app.main User testuser logged out
2024-06-10 04:18:01,942 [INFO] app.auth Item 12345 added by admin admins
2024-06-10 04:18:01,979 [INFO] app.main User newuser added by admins
2024-06-10 04:18:02,019 [INFO] app.main User newadminuser added by admin admins
2024-06-10 04:18:02,048 [INFO] app.main Admin admins accessed admin dashboard
2024-06-10 04:18:02,134 [INFO] app.main Password changed for user: testuser
2024-06-10 04:18:02,163 [INFO] app.main testuser accessed the dashboard
2024-06-10 04:18:02,210 [INFO] app.main User deluser deleted by admin admins
2024-06-10 04:18:02,253 [INFO] app.auth Item 1 deleted by admin admins
2024-06-10 04:18:02,283 [INFO] app.main Employee testuser accessed employee dashboard
2024-06-10 04:18:02,470 [WARNING] app.main Login page has arrived
2024-06-10 04:18:02,517 [INFO] app.auth Item 1 assigned to testuser by admin admins
2024-06-10 04:18:02,549 [WARNING] app.main Failed login attempt for username: wronguser
2024-06-10 04:18:02,582 [INFO] app.main User testuser logged in for the first time
2024-06-10 04:18:02,613 [INFO] app.main User testuser logged out
2024-06-10 04:18:02,694 [INFO] app.auth Item 1 updated by admin admins
2024-06-10 04:27:44,869 [WARNING] app.main Login page has arrived
2024-06-10 04:27:50,156 [INFO] app.main User admin logged in for the first time
2024-06-10 04:27:51,062 [INFO] app.main admin accessed the dashboard
2024-06-10 04:27:51,067 [INFO] app.main Admin admin accessed admin dashboard
2024-06-10 04:28:03,823 [ERROR] app.auth Exception (MySQLdb.OperationalError) (1292, "Incorrect date value: '' for column 'date_of_purchase' at row 1")
[SQL: INSERT INTO items (item_name, serial_number, bill_no, date_of_purchase, assigned_to, warranty) VALUES (%s, %s, %s, %s, %s, %s)]
[parameters: ('potato', 123, 123, '', None, '')]
(Background on this error at: https://sqlalche.me/e/20/e3q8) occurred while adding item 123
Traceback (most recent call last):
  File "C:\Users\g_and\AppData\Local\Programs\Python\Python312\Lib\site-packages\sqlalchemy\engine\base.py", line 1967, in _exec_single_context
    self.dialect.do_execute(
  File "C:\Users\g_and\AppData\Local\Programs\Python\Python312\Lib\site-packages\sqlalchemy\engine\default.py", line 924, in do_execute
    cursor.execute(statement, parameters)
  File "C:\Users\g_and\AppData\Local\Programs\Python\Python312\Lib\site-packages\MySQLdb\cursors.py", line 179, in execute
    res = self._query(mogrified_query)
          ^^^^^^^^^^^^^^^^^^^^^^^^^^^^
  File "C:\Users\g_and\AppData\Local\Programs\Python\Python312\Lib\site-packages\MySQLdb\cursors.py", line 330, in _query
    db.query(q)
  File "C:\Users\g_and\AppData\Local\Programs\Python\Python312\Lib\site-packages\MySQLdb\connections.py", line 261, in query
    _mysql.connection.query(self, query)
MySQLdb.OperationalError: (1292, "Incorrect date value: '' for column 'date_of_purchase' at row 1")

The above exception was the direct cause of the following exception:

Traceback (most recent call last):
  File "C:\Users\g_and\Desktop\gihub\learning-documentation\capstone-project\inventory management system(flask)\app\items.py", line 25, in add_item
    db.session.commit()
  File "C:\Users\g_and\AppData\Local\Programs\Python\Python312\Lib\site-packages\sqlalchemy\orm\scoping.py", line 597, in commit
    return self._proxied.commit()
           ^^^^^^^^^^^^^^^^^^^^^^
  File "C:\Users\g_and\AppData\Local\Programs\Python\Python312\Lib\site-packages\sqlalchemy\orm\session.py", line 2017, in commit
    trans.commit(_to_root=True)
  File "<string>", line 2, in commit
  File "C:\Users\g_and\AppData\Local\Programs\Python\Python312\Lib\site-packages\sqlalchemy\orm\state_changes.py", line 139, in _go
    ret_value = fn(self, *arg, **kw)
                ^^^^^^^^^^^^^^^^^^^^
  File "C:\Users\g_and\AppData\Local\Programs\Python\Python312\Lib\site-packages\sqlalchemy\orm\session.py", line 1302, in commit
    self._prepare_impl()
  File "<string>", line 2, in _prepare_impl
  File "C:\Users\g_and\AppData\Local\Programs\Python\Python312\Lib\site-packages\sqlalchemy\orm\state_changes.py", line 139, in _go
    ret_value = fn(self, *arg, **kw)
                ^^^^^^^^^^^^^^^^^^^^
  File "C:\Users\g_and\AppData\Local\Programs\Python\Python312\Lib\site-packages\sqlalchemy\orm\session.py", line 1277, in _prepare_impl
    self.session.flush()
  File "C:\Users\g_and\AppData\Local\Programs\Python\Python312\Lib\site-packages\sqlalchemy\orm\session.py", line 4341, in flush
    self._flush(objects)
  File "C:\Users\g_and\AppData\Local\Programs\Python\Python312\Lib\site-packages\sqlalchemy\orm\session.py", line 4476, in _flush
    with util.safe_reraise():
  File "C:\Users\g_and\AppData\Local\Programs\Python\Python312\Lib\site-packages\sqlalchemy\util\langhelpers.py", line 146, in __exit__
    raise exc_value.with_traceback(exc_tb)
  File "C:\Users\g_and\AppData\Local\Programs\Python\Python312\Lib\site-packages\sqlalchemy\orm\session.py", line 4437, in _flush
    flush_context.execute()
  File "C:\Users\g_and\AppData\Local\Programs\Python\Python312\Lib\site-packages\sqlalchemy\orm\unitofwork.py", line 466, in execute
    rec.execute(self)
  File "C:\Users\g_and\AppData\Local\Programs\Python\Python312\Lib\site-packages\sqlalchemy\orm\unitofwork.py", line 642, in execute
    util.preloaded.orm_persistence.save_obj(
  File "C:\Users\g_and\AppData\Local\Programs\Python\Python312\Lib\site-packages\sqlalchemy\orm\persistence.py", line 93, in save_obj
    _emit_insert_statements(
  File "C:\Users\g_and\AppData\Local\Programs\Python\Python312\Lib\site-packages\sqlalchemy\orm\persistence.py", line 1233, in _emit_insert_statements
    result = connection.execute(
             ^^^^^^^^^^^^^^^^^^^
  File "C:\Users\g_and\AppData\Local\Programs\Python\Python312\Lib\site-packages\sqlalchemy\engine\base.py", line 1418, in execute
    return meth(
           ^^^^^
  File "C:\Users\g_and\AppData\Local\Programs\Python\Python312\Lib\site-packages\sqlalchemy\sql\elements.py", line 515, in _execute_on_connection
    return connection._execute_clauseelement(
           ^^^^^^^^^^^^^^^^^^^^^^^^^^^^^^^^^^
  File "C:\Users\g_and\AppData\Local\Programs\Python\Python312\Lib\site-packages\sqlalchemy\engine\base.py", line 1640, in _execute_clauseelement
    ret = self._execute_context(
          ^^^^^^^^^^^^^^^^^^^^^^
  File "C:\Users\g_and\AppData\Local\Programs\Python\Python312\Lib\site-packages\sqlalchemy\engine\base.py", line 1846, in _execute_context
    return self._exec_single_context(
           ^^^^^^^^^^^^^^^^^^^^^^^^^^
  File "C:\Users\g_and\AppData\Local\Programs\Python\Python312\Lib\site-packages\sqlalchemy\engine\base.py", line 1986, in _exec_single_context
    self._handle_dbapi_exception(
  File "C:\Users\g_and\AppData\Local\Programs\Python\Python312\Lib\site-packages\sqlalchemy\engine\base.py", line 2353, in _handle_dbapi_exception
    raise sqlalchemy_exception.with_traceback(exc_info[2]) from e
  File "C:\Users\g_and\AppData\Local\Programs\Python\Python312\Lib\site-packages\sqlalchemy\engine\base.py", line 1967, in _exec_single_context
    self.dialect.do_execute(
  File "C:\Users\g_and\AppData\Local\Programs\Python\Python312\Lib\site-packages\sqlalchemy\engine\default.py", line 924, in do_execute
    cursor.execute(statement, parameters)
  File "C:\Users\g_and\AppData\Local\Programs\Python\Python312\Lib\site-packages\MySQLdb\cursors.py", line 179, in execute
    res = self._query(mogrified_query)
          ^^^^^^^^^^^^^^^^^^^^^^^^^^^^
  File "C:\Users\g_and\AppData\Local\Programs\Python\Python312\Lib\site-packages\MySQLdb\cursors.py", line 330, in _query
    db.query(q)
  File "C:\Users\g_and\AppData\Local\Programs\Python\Python312\Lib\site-packages\MySQLdb\connections.py", line 261, in query
    _mysql.connection.query(self, query)
sqlalchemy.exc.OperationalError: (MySQLdb.OperationalError) (1292, "Incorrect date value: '' for column 'date_of_purchase' at row 1")
[SQL: INSERT INTO items (item_name, serial_number, bill_no, date_of_purchase, assigned_to, warranty) VALUES (%s, %s, %s, %s, %s, %s)]
[parameters: ('potato', 123, 123, '', None, '')]
(Background on this error at: https://sqlalche.me/e/20/e3q8)
2024-06-10 04:29:29,022 [ERROR] app.auth Exception (MySQLdb.OperationalError) (1292, "Incorrect date value: '' for column 'date_of_purchase' at row 1")
[SQL: INSERT INTO items (item_name, serial_number, bill_no, date_of_purchase, assigned_to, warranty) VALUES (%s, %s, %s, %s, %s, %s)]
[parameters: ('potato', 123, 123, '', None, '')]
(Background on this error at: https://sqlalche.me/e/20/e3q8) occurred while adding item 123
Traceback (most recent call last):
  File "C:\Users\g_and\AppData\Local\Programs\Python\Python312\Lib\site-packages\sqlalchemy\engine\base.py", line 1967, in _exec_single_context
    self.dialect.do_execute(
  File "C:\Users\g_and\AppData\Local\Programs\Python\Python312\Lib\site-packages\sqlalchemy\engine\default.py", line 924, in do_execute
    cursor.execute(statement, parameters)
  File "C:\Users\g_and\AppData\Local\Programs\Python\Python312\Lib\site-packages\MySQLdb\cursors.py", line 179, in execute
    res = self._query(mogrified_query)
          ^^^^^^^^^^^^^^^^^^^^^^^^^^^^
  File "C:\Users\g_and\AppData\Local\Programs\Python\Python312\Lib\site-packages\MySQLdb\cursors.py", line 330, in _query
    db.query(q)
  File "C:\Users\g_and\AppData\Local\Programs\Python\Python312\Lib\site-packages\MySQLdb\connections.py", line 261, in query
    _mysql.connection.query(self, query)
MySQLdb.OperationalError: (1292, "Incorrect date value: '' for column 'date_of_purchase' at row 1")

The above exception was the direct cause of the following exception:

Traceback (most recent call last):
  File "C:\Users\g_and\Desktop\gihub\learning-documentation\capstone-project\inventory management system(flask)\app\items.py", line 26, in add_item
    db.session.commit()
  File "C:\Users\g_and\AppData\Local\Programs\Python\Python312\Lib\site-packages\sqlalchemy\orm\scoping.py", line 597, in commit
    return self._proxied.commit()
           ^^^^^^^^^^^^^^^^^^^^^^
  File "C:\Users\g_and\AppData\Local\Programs\Python\Python312\Lib\site-packages\sqlalchemy\orm\session.py", line 2017, in commit
    trans.commit(_to_root=True)
  File "<string>", line 2, in commit
  File "C:\Users\g_and\AppData\Local\Programs\Python\Python312\Lib\site-packages\sqlalchemy\orm\state_changes.py", line 139, in _go
    ret_value = fn(self, *arg, **kw)
                ^^^^^^^^^^^^^^^^^^^^
  File "C:\Users\g_and\AppData\Local\Programs\Python\Python312\Lib\site-packages\sqlalchemy\orm\session.py", line 1302, in commit
    self._prepare_impl()
  File "<string>", line 2, in _prepare_impl
  File "C:\Users\g_and\AppData\Local\Programs\Python\Python312\Lib\site-packages\sqlalchemy\orm\state_changes.py", line 139, in _go
    ret_value = fn(self, *arg, **kw)
                ^^^^^^^^^^^^^^^^^^^^
  File "C:\Users\g_and\AppData\Local\Programs\Python\Python312\Lib\site-packages\sqlalchemy\orm\session.py", line 1277, in _prepare_impl
    self.session.flush()
  File "C:\Users\g_and\AppData\Local\Programs\Python\Python312\Lib\site-packages\sqlalchemy\orm\session.py", line 4341, in flush
    self._flush(objects)
  File "C:\Users\g_and\AppData\Local\Programs\Python\Python312\Lib\site-packages\sqlalchemy\orm\session.py", line 4476, in _flush
    with util.safe_reraise():
  File "C:\Users\g_and\AppData\Local\Programs\Python\Python312\Lib\site-packages\sqlalchemy\util\langhelpers.py", line 146, in __exit__
    raise exc_value.with_traceback(exc_tb)
  File "C:\Users\g_and\AppData\Local\Programs\Python\Python312\Lib\site-packages\sqlalchemy\orm\session.py", line 4437, in _flush
    flush_context.execute()
  File "C:\Users\g_and\AppData\Local\Programs\Python\Python312\Lib\site-packages\sqlalchemy\orm\unitofwork.py", line 466, in execute
    rec.execute(self)
  File "C:\Users\g_and\AppData\Local\Programs\Python\Python312\Lib\site-packages\sqlalchemy\orm\unitofwork.py", line 642, in execute
    util.preloaded.orm_persistence.save_obj(
  File "C:\Users\g_and\AppData\Local\Programs\Python\Python312\Lib\site-packages\sqlalchemy\orm\persistence.py", line 93, in save_obj
    _emit_insert_statements(
  File "C:\Users\g_and\AppData\Local\Programs\Python\Python312\Lib\site-packages\sqlalchemy\orm\persistence.py", line 1233, in _emit_insert_statements
    result = connection.execute(
             ^^^^^^^^^^^^^^^^^^^
  File "C:\Users\g_and\AppData\Local\Programs\Python\Python312\Lib\site-packages\sqlalchemy\engine\base.py", line 1418, in execute
    return meth(
           ^^^^^
  File "C:\Users\g_and\AppData\Local\Programs\Python\Python312\Lib\site-packages\sqlalchemy\sql\elements.py", line 515, in _execute_on_connection
    return connection._execute_clauseelement(
           ^^^^^^^^^^^^^^^^^^^^^^^^^^^^^^^^^^
  File "C:\Users\g_and\AppData\Local\Programs\Python\Python312\Lib\site-packages\sqlalchemy\engine\base.py", line 1640, in _execute_clauseelement
    ret = self._execute_context(
          ^^^^^^^^^^^^^^^^^^^^^^
  File "C:\Users\g_and\AppData\Local\Programs\Python\Python312\Lib\site-packages\sqlalchemy\engine\base.py", line 1846, in _execute_context
    return self._exec_single_context(
           ^^^^^^^^^^^^^^^^^^^^^^^^^^
  File "C:\Users\g_and\AppData\Local\Programs\Python\Python312\Lib\site-packages\sqlalchemy\engine\base.py", line 1986, in _exec_single_context
    self._handle_dbapi_exception(
  File "C:\Users\g_and\AppData\Local\Programs\Python\Python312\Lib\site-packages\sqlalchemy\engine\base.py", line 2353, in _handle_dbapi_exception
    raise sqlalchemy_exception.with_traceback(exc_info[2]) from e
  File "C:\Users\g_and\AppData\Local\Programs\Python\Python312\Lib\site-packages\sqlalchemy\engine\base.py", line 1967, in _exec_single_context
    self.dialect.do_execute(
  File "C:\Users\g_and\AppData\Local\Programs\Python\Python312\Lib\site-packages\sqlalchemy\engine\default.py", line 924, in do_execute
    cursor.execute(statement, parameters)
  File "C:\Users\g_and\AppData\Local\Programs\Python\Python312\Lib\site-packages\MySQLdb\cursors.py", line 179, in execute
    res = self._query(mogrified_query)
          ^^^^^^^^^^^^^^^^^^^^^^^^^^^^
  File "C:\Users\g_and\AppData\Local\Programs\Python\Python312\Lib\site-packages\MySQLdb\cursors.py", line 330, in _query
    db.query(q)
  File "C:\Users\g_and\AppData\Local\Programs\Python\Python312\Lib\site-packages\MySQLdb\connections.py", line 261, in query
    _mysql.connection.query(self, query)
sqlalchemy.exc.OperationalError: (MySQLdb.OperationalError) (1292, "Incorrect date value: '' for column 'date_of_purchase' at row 1")
[SQL: INSERT INTO items (item_name, serial_number, bill_no, date_of_purchase, assigned_to, warranty) VALUES (%s, %s, %s, %s, %s, %s)]
[parameters: ('potato', 123, 123, '', None, '')]
(Background on this error at: https://sqlalche.me/e/20/e3q8)
2024-06-10 04:31:24,450 [ERROR] app.auth Exception (MySQLdb.OperationalError) (1292, "Incorrect date value: '' for column 'date_of_purchase' at row 1")
[SQL: INSERT INTO items (item_name, serial_number, bill_no, date_of_purchase, assigned_to, warranty) VALUES (%s, %s, %s, %s, %s, %s)]
[parameters: ('potato', 123, 123, '', None, '')]
(Background on this error at: https://sqlalche.me/e/20/e3q8) occurred while adding item 123
Traceback (most recent call last):
  File "C:\Users\g_and\AppData\Local\Programs\Python\Python312\Lib\site-packages\sqlalchemy\engine\base.py", line 1967, in _exec_single_context
    self.dialect.do_execute(
  File "C:\Users\g_and\AppData\Local\Programs\Python\Python312\Lib\site-packages\sqlalchemy\engine\default.py", line 924, in do_execute
    cursor.execute(statement, parameters)
  File "C:\Users\g_and\AppData\Local\Programs\Python\Python312\Lib\site-packages\MySQLdb\cursors.py", line 179, in execute
    res = self._query(mogrified_query)
          ^^^^^^^^^^^^^^^^^^^^^^^^^^^^
  File "C:\Users\g_and\AppData\Local\Programs\Python\Python312\Lib\site-packages\MySQLdb\cursors.py", line 330, in _query
    db.query(q)
  File "C:\Users\g_and\AppData\Local\Programs\Python\Python312\Lib\site-packages\MySQLdb\connections.py", line 261, in query
    _mysql.connection.query(self, query)
MySQLdb.OperationalError: (1292, "Incorrect date value: '' for column 'date_of_purchase' at row 1")

The above exception was the direct cause of the following exception:

Traceback (most recent call last):
  File "C:\Users\g_and\Desktop\gihub\learning-documentation\capstone-project\inventory management system(flask)\app\items.py", line 27, in add_item
    db.session.commit()
  File "C:\Users\g_and\AppData\Local\Programs\Python\Python312\Lib\site-packages\sqlalchemy\orm\scoping.py", line 597, in commit
    return self._proxied.commit()
           ^^^^^^^^^^^^^^^^^^^^^^
  File "C:\Users\g_and\AppData\Local\Programs\Python\Python312\Lib\site-packages\sqlalchemy\orm\session.py", line 2017, in commit
    trans.commit(_to_root=True)
  File "<string>", line 2, in commit
  File "C:\Users\g_and\AppData\Local\Programs\Python\Python312\Lib\site-packages\sqlalchemy\orm\state_changes.py", line 139, in _go
    ret_value = fn(self, *arg, **kw)
                ^^^^^^^^^^^^^^^^^^^^
  File "C:\Users\g_and\AppData\Local\Programs\Python\Python312\Lib\site-packages\sqlalchemy\orm\session.py", line 1302, in commit
    self._prepare_impl()
  File "<string>", line 2, in _prepare_impl
  File "C:\Users\g_and\AppData\Local\Programs\Python\Python312\Lib\site-packages\sqlalchemy\orm\state_changes.py", line 139, in _go
    ret_value = fn(self, *arg, **kw)
                ^^^^^^^^^^^^^^^^^^^^
  File "C:\Users\g_and\AppData\Local\Programs\Python\Python312\Lib\site-packages\sqlalchemy\orm\session.py", line 1277, in _prepare_impl
    self.session.flush()
  File "C:\Users\g_and\AppData\Local\Programs\Python\Python312\Lib\site-packages\sqlalchemy\orm\session.py", line 4341, in flush
    self._flush(objects)
  File "C:\Users\g_and\AppData\Local\Programs\Python\Python312\Lib\site-packages\sqlalchemy\orm\session.py", line 4476, in _flush
    with util.safe_reraise():
  File "C:\Users\g_and\AppData\Local\Programs\Python\Python312\Lib\site-packages\sqlalchemy\util\langhelpers.py", line 146, in __exit__
    raise exc_value.with_traceback(exc_tb)
  File "C:\Users\g_and\AppData\Local\Programs\Python\Python312\Lib\site-packages\sqlalchemy\orm\session.py", line 4437, in _flush
    flush_context.execute()
  File "C:\Users\g_and\AppData\Local\Programs\Python\Python312\Lib\site-packages\sqlalchemy\orm\unitofwork.py", line 466, in execute
    rec.execute(self)
  File "C:\Users\g_and\AppData\Local\Programs\Python\Python312\Lib\site-packages\sqlalchemy\orm\unitofwork.py", line 642, in execute
    util.preloaded.orm_persistence.save_obj(
  File "C:\Users\g_and\AppData\Local\Programs\Python\Python312\Lib\site-packages\sqlalchemy\orm\persistence.py", line 93, in save_obj
    _emit_insert_statements(
  File "C:\Users\g_and\AppData\Local\Programs\Python\Python312\Lib\site-packages\sqlalchemy\orm\persistence.py", line 1233, in _emit_insert_statements
    result = connection.execute(
             ^^^^^^^^^^^^^^^^^^^
  File "C:\Users\g_and\AppData\Local\Programs\Python\Python312\Lib\site-packages\sqlalchemy\engine\base.py", line 1418, in execute
    return meth(
           ^^^^^
  File "C:\Users\g_and\AppData\Local\Programs\Python\Python312\Lib\site-packages\sqlalchemy\sql\elements.py", line 515, in _execute_on_connection
    return connection._execute_clauseelement(
           ^^^^^^^^^^^^^^^^^^^^^^^^^^^^^^^^^^
  File "C:\Users\g_and\AppData\Local\Programs\Python\Python312\Lib\site-packages\sqlalchemy\engine\base.py", line 1640, in _execute_clauseelement
    ret = self._execute_context(
          ^^^^^^^^^^^^^^^^^^^^^^
  File "C:\Users\g_and\AppData\Local\Programs\Python\Python312\Lib\site-packages\sqlalchemy\engine\base.py", line 1846, in _execute_context
    return self._exec_single_context(
           ^^^^^^^^^^^^^^^^^^^^^^^^^^
  File "C:\Users\g_and\AppData\Local\Programs\Python\Python312\Lib\site-packages\sqlalchemy\engine\base.py", line 1986, in _exec_single_context
    self._handle_dbapi_exception(
  File "C:\Users\g_and\AppData\Local\Programs\Python\Python312\Lib\site-packages\sqlalchemy\engine\base.py", line 2353, in _handle_dbapi_exception
    raise sqlalchemy_exception.with_traceback(exc_info[2]) from e
  File "C:\Users\g_and\AppData\Local\Programs\Python\Python312\Lib\site-packages\sqlalchemy\engine\base.py", line 1967, in _exec_single_context
    self.dialect.do_execute(
  File "C:\Users\g_and\AppData\Local\Programs\Python\Python312\Lib\site-packages\sqlalchemy\engine\default.py", line 924, in do_execute
    cursor.execute(statement, parameters)
  File "C:\Users\g_and\AppData\Local\Programs\Python\Python312\Lib\site-packages\MySQLdb\cursors.py", line 179, in execute
    res = self._query(mogrified_query)
          ^^^^^^^^^^^^^^^^^^^^^^^^^^^^
  File "C:\Users\g_and\AppData\Local\Programs\Python\Python312\Lib\site-packages\MySQLdb\cursors.py", line 330, in _query
    db.query(q)
  File "C:\Users\g_and\AppData\Local\Programs\Python\Python312\Lib\site-packages\MySQLdb\connections.py", line 261, in query
    _mysql.connection.query(self, query)
sqlalchemy.exc.OperationalError: (MySQLdb.OperationalError) (1292, "Incorrect date value: '' for column 'date_of_purchase' at row 1")
[SQL: INSERT INTO items (item_name, serial_number, bill_no, date_of_purchase, assigned_to, warranty) VALUES (%s, %s, %s, %s, %s, %s)]
[parameters: ('potato', 123, 123, '', None, '')]
(Background on this error at: https://sqlalche.me/e/20/e3q8)
2024-06-10 04:34:37,125 [ERROR] app.auth Exception (MySQLdb.OperationalError) (1292, "Incorrect date value: '' for column 'date_of_purchase' at row 1")
[SQL: INSERT INTO items (item_name, serial_number, bill_no, date_of_purchase, assigned_to, warranty) VALUES (%s, %s, %s, %s, %s, %s)]
[parameters: ('potato', 123, 123, '', None, '')]
(Background on this error at: https://sqlalche.me/e/20/e3q8) occurred while adding item 123
Traceback (most recent call last):
  File "C:\Users\g_and\AppData\Local\Programs\Python\Python312\Lib\site-packages\sqlalchemy\engine\base.py", line 1967, in _exec_single_context
    self.dialect.do_execute(
  File "C:\Users\g_and\AppData\Local\Programs\Python\Python312\Lib\site-packages\sqlalchemy\engine\default.py", line 924, in do_execute
    cursor.execute(statement, parameters)
  File "C:\Users\g_and\AppData\Local\Programs\Python\Python312\Lib\site-packages\MySQLdb\cursors.py", line 179, in execute
    res = self._query(mogrified_query)
          ^^^^^^^^^^^^^^^^^^^^^^^^^^^^
  File "C:\Users\g_and\AppData\Local\Programs\Python\Python312\Lib\site-packages\MySQLdb\cursors.py", line 330, in _query
    db.query(q)
  File "C:\Users\g_and\AppData\Local\Programs\Python\Python312\Lib\site-packages\MySQLdb\connections.py", line 261, in query
    _mysql.connection.query(self, query)
MySQLdb.OperationalError: (1292, "Incorrect date value: '' for column 'date_of_purchase' at row 1")

The above exception was the direct cause of the following exception:

Traceback (most recent call last):
  File "C:\Users\g_and\Desktop\gihub\learning-documentation\capstone-project\inventory management system(flask)\app\items.py", line 27, in add_item
    db.session.commit()
  File "C:\Users\g_and\AppData\Local\Programs\Python\Python312\Lib\site-packages\sqlalchemy\orm\scoping.py", line 597, in commit
    return self._proxied.commit()
           ^^^^^^^^^^^^^^^^^^^^^^
  File "C:\Users\g_and\AppData\Local\Programs\Python\Python312\Lib\site-packages\sqlalchemy\orm\session.py", line 2017, in commit
    trans.commit(_to_root=True)
  File "<string>", line 2, in commit
  File "C:\Users\g_and\AppData\Local\Programs\Python\Python312\Lib\site-packages\sqlalchemy\orm\state_changes.py", line 139, in _go
    ret_value = fn(self, *arg, **kw)
                ^^^^^^^^^^^^^^^^^^^^
  File "C:\Users\g_and\AppData\Local\Programs\Python\Python312\Lib\site-packages\sqlalchemy\orm\session.py", line 1302, in commit
    self._prepare_impl()
  File "<string>", line 2, in _prepare_impl
  File "C:\Users\g_and\AppData\Local\Programs\Python\Python312\Lib\site-packages\sqlalchemy\orm\state_changes.py", line 139, in _go
    ret_value = fn(self, *arg, **kw)
                ^^^^^^^^^^^^^^^^^^^^
  File "C:\Users\g_and\AppData\Local\Programs\Python\Python312\Lib\site-packages\sqlalchemy\orm\session.py", line 1277, in _prepare_impl
    self.session.flush()
  File "C:\Users\g_and\AppData\Local\Programs\Python\Python312\Lib\site-packages\sqlalchemy\orm\session.py", line 4341, in flush
    self._flush(objects)
  File "C:\Users\g_and\AppData\Local\Programs\Python\Python312\Lib\site-packages\sqlalchemy\orm\session.py", line 4476, in _flush
    with util.safe_reraise():
  File "C:\Users\g_and\AppData\Local\Programs\Python\Python312\Lib\site-packages\sqlalchemy\util\langhelpers.py", line 146, in __exit__
    raise exc_value.with_traceback(exc_tb)
  File "C:\Users\g_and\AppData\Local\Programs\Python\Python312\Lib\site-packages\sqlalchemy\orm\session.py", line 4437, in _flush
    flush_context.execute()
  File "C:\Users\g_and\AppData\Local\Programs\Python\Python312\Lib\site-packages\sqlalchemy\orm\unitofwork.py", line 466, in execute
    rec.execute(self)
  File "C:\Users\g_and\AppData\Local\Programs\Python\Python312\Lib\site-packages\sqlalchemy\orm\unitofwork.py", line 642, in execute
    util.preloaded.orm_persistence.save_obj(
  File "C:\Users\g_and\AppData\Local\Programs\Python\Python312\Lib\site-packages\sqlalchemy\orm\persistence.py", line 93, in save_obj
    _emit_insert_statements(
  File "C:\Users\g_and\AppData\Local\Programs\Python\Python312\Lib\site-packages\sqlalchemy\orm\persistence.py", line 1233, in _emit_insert_statements
    result = connection.execute(
             ^^^^^^^^^^^^^^^^^^^
  File "C:\Users\g_and\AppData\Local\Programs\Python\Python312\Lib\site-packages\sqlalchemy\engine\base.py", line 1418, in execute
    return meth(
           ^^^^^
  File "C:\Users\g_and\AppData\Local\Programs\Python\Python312\Lib\site-packages\sqlalchemy\sql\elements.py", line 515, in _execute_on_connection
    return connection._execute_clauseelement(
           ^^^^^^^^^^^^^^^^^^^^^^^^^^^^^^^^^^
  File "C:\Users\g_and\AppData\Local\Programs\Python\Python312\Lib\site-packages\sqlalchemy\engine\base.py", line 1640, in _execute_clauseelement
    ret = self._execute_context(
          ^^^^^^^^^^^^^^^^^^^^^^
  File "C:\Users\g_and\AppData\Local\Programs\Python\Python312\Lib\site-packages\sqlalchemy\engine\base.py", line 1846, in _execute_context
    return self._exec_single_context(
           ^^^^^^^^^^^^^^^^^^^^^^^^^^
  File "C:\Users\g_and\AppData\Local\Programs\Python\Python312\Lib\site-packages\sqlalchemy\engine\base.py", line 1986, in _exec_single_context
    self._handle_dbapi_exception(
  File "C:\Users\g_and\AppData\Local\Programs\Python\Python312\Lib\site-packages\sqlalchemy\engine\base.py", line 2353, in _handle_dbapi_exception
    raise sqlalchemy_exception.with_traceback(exc_info[2]) from e
  File "C:\Users\g_and\AppData\Local\Programs\Python\Python312\Lib\site-packages\sqlalchemy\engine\base.py", line 1967, in _exec_single_context
    self.dialect.do_execute(
  File "C:\Users\g_and\AppData\Local\Programs\Python\Python312\Lib\site-packages\sqlalchemy\engine\default.py", line 924, in do_execute
    cursor.execute(statement, parameters)
  File "C:\Users\g_and\AppData\Local\Programs\Python\Python312\Lib\site-packages\MySQLdb\cursors.py", line 179, in execute
    res = self._query(mogrified_query)
          ^^^^^^^^^^^^^^^^^^^^^^^^^^^^
  File "C:\Users\g_and\AppData\Local\Programs\Python\Python312\Lib\site-packages\MySQLdb\cursors.py", line 330, in _query
    db.query(q)
  File "C:\Users\g_and\AppData\Local\Programs\Python\Python312\Lib\site-packages\MySQLdb\connections.py", line 261, in query
    _mysql.connection.query(self, query)
sqlalchemy.exc.OperationalError: (MySQLdb.OperationalError) (1292, "Incorrect date value: '' for column 'date_of_purchase' at row 1")
[SQL: INSERT INTO items (item_name, serial_number, bill_no, date_of_purchase, assigned_to, warranty) VALUES (%s, %s, %s, %s, %s, %s)]
[parameters: ('potato', 123, 123, '', None, '')]
(Background on this error at: https://sqlalche.me/e/20/e3q8)
2024-06-10 04:35:30,469 [ERROR] app Exception on /item/add [POST]
Traceback (most recent call last):
  File "C:\Users\g_and\AppData\Local\Programs\Python\Python312\Lib\site-packages\flask\app.py", line 1473, in wsgi_app
    response = self.full_dispatch_request()
               ^^^^^^^^^^^^^^^^^^^^^^^^^^^^
  File "C:\Users\g_and\AppData\Local\Programs\Python\Python312\Lib\site-packages\flask\app.py", line 882, in full_dispatch_request
    rv = self.handle_user_exception(e)
         ^^^^^^^^^^^^^^^^^^^^^^^^^^^^^
  File "C:\Users\g_and\AppData\Local\Programs\Python\Python312\Lib\site-packages\flask\app.py", line 880, in full_dispatch_request
    rv = self.dispatch_request()
         ^^^^^^^^^^^^^^^^^^^^^^^
  File "C:\Users\g_and\AppData\Local\Programs\Python\Python312\Lib\site-packages\flask\app.py", line 865, in dispatch_request
    return self.ensure_sync(self.view_functions[rule.endpoint])(**view_args)  # type: ignore[no-any-return]
           ^^^^^^^^^^^^^^^^^^^^^^^^^^^^^^^^^^^^^^^^^^^^^^^^^^^^^^^^^^^^^^^^^
  File "C:\Users\g_and\Desktop\gihub\learning-documentation\capstone-project\inventory management system(flask)\app\auth.py", line 13, in decorated_function
    return f(*args, **kwargs)
           ^^^^^^^^^^^^^^^^^^
  File "C:\Users\g_and\Desktop\gihub\learning-documentation\capstone-project\inventory management system(flask)\app\items.py", line 14, in add_item
    serial_number = int(data.get('serial_number'))
                    ^^^^^^^^^^^^^^^^^^^^^^^^^^^^^^
ValueError: invalid literal for int() with base 10: ''
2024-06-10 04:35:31,310 [ERROR] app Exception on /item/add [POST]
Traceback (most recent call last):
  File "C:\Users\g_and\AppData\Local\Programs\Python\Python312\Lib\site-packages\flask\app.py", line 1473, in wsgi_app
    response = self.full_dispatch_request()
               ^^^^^^^^^^^^^^^^^^^^^^^^^^^^
  File "C:\Users\g_and\AppData\Local\Programs\Python\Python312\Lib\site-packages\flask\app.py", line 882, in full_dispatch_request
    rv = self.handle_user_exception(e)
         ^^^^^^^^^^^^^^^^^^^^^^^^^^^^^
  File "C:\Users\g_and\AppData\Local\Programs\Python\Python312\Lib\site-packages\flask\app.py", line 880, in full_dispatch_request
    rv = self.dispatch_request()
         ^^^^^^^^^^^^^^^^^^^^^^^
  File "C:\Users\g_and\AppData\Local\Programs\Python\Python312\Lib\site-packages\flask\app.py", line 865, in dispatch_request
    return self.ensure_sync(self.view_functions[rule.endpoint])(**view_args)  # type: ignore[no-any-return]
           ^^^^^^^^^^^^^^^^^^^^^^^^^^^^^^^^^^^^^^^^^^^^^^^^^^^^^^^^^^^^^^^^^
  File "C:\Users\g_and\Desktop\gihub\learning-documentation\capstone-project\inventory management system(flask)\app\auth.py", line 13, in decorated_function
    return f(*args, **kwargs)
           ^^^^^^^^^^^^^^^^^^
  File "C:\Users\g_and\Desktop\gihub\learning-documentation\capstone-project\inventory management system(flask)\app\items.py", line 14, in add_item
    serial_number = int(data.get('serial_number'))
                    ^^^^^^^^^^^^^^^^^^^^^^^^^^^^^^
ValueError: invalid literal for int() with base 10: ''
2024-06-10 04:35:36,726 [ERROR] app Exception on /item/add [POST]
Traceback (most recent call last):
  File "C:\Users\g_and\AppData\Local\Programs\Python\Python312\Lib\site-packages\flask\app.py", line 1473, in wsgi_app
    response = self.full_dispatch_request()
               ^^^^^^^^^^^^^^^^^^^^^^^^^^^^
  File "C:\Users\g_and\AppData\Local\Programs\Python\Python312\Lib\site-packages\flask\app.py", line 882, in full_dispatch_request
    rv = self.handle_user_exception(e)
         ^^^^^^^^^^^^^^^^^^^^^^^^^^^^^
  File "C:\Users\g_and\AppData\Local\Programs\Python\Python312\Lib\site-packages\flask\app.py", line 880, in full_dispatch_request
    rv = self.dispatch_request()
         ^^^^^^^^^^^^^^^^^^^^^^^
  File "C:\Users\g_and\AppData\Local\Programs\Python\Python312\Lib\site-packages\flask\app.py", line 865, in dispatch_request
    return self.ensure_sync(self.view_functions[rule.endpoint])(**view_args)  # type: ignore[no-any-return]
           ^^^^^^^^^^^^^^^^^^^^^^^^^^^^^^^^^^^^^^^^^^^^^^^^^^^^^^^^^^^^^^^^^
  File "C:\Users\g_and\Desktop\gihub\learning-documentation\capstone-project\inventory management system(flask)\app\auth.py", line 13, in decorated_function
    return f(*args, **kwargs)
           ^^^^^^^^^^^^^^^^^^
  File "C:\Users\g_and\Desktop\gihub\learning-documentation\capstone-project\inventory management system(flask)\app\items.py", line 14, in add_item
    serial_number = int(data.get('serial_number'))
                    ^^^^^^^^^^^^^^^^^^^^^^^^^^^^^^
ValueError: invalid literal for int() with base 10: 'nono'
2024-06-10 04:35:36,990 [ERROR] app Exception on /item/add [POST]
Traceback (most recent call last):
  File "C:\Users\g_and\AppData\Local\Programs\Python\Python312\Lib\site-packages\flask\app.py", line 1473, in wsgi_app
    response = self.full_dispatch_request()
               ^^^^^^^^^^^^^^^^^^^^^^^^^^^^
  File "C:\Users\g_and\AppData\Local\Programs\Python\Python312\Lib\site-packages\flask\app.py", line 882, in full_dispatch_request
    rv = self.handle_user_exception(e)
         ^^^^^^^^^^^^^^^^^^^^^^^^^^^^^
  File "C:\Users\g_and\AppData\Local\Programs\Python\Python312\Lib\site-packages\flask\app.py", line 880, in full_dispatch_request
    rv = self.dispatch_request()
         ^^^^^^^^^^^^^^^^^^^^^^^
  File "C:\Users\g_and\AppData\Local\Programs\Python\Python312\Lib\site-packages\flask\app.py", line 865, in dispatch_request
    return self.ensure_sync(self.view_functions[rule.endpoint])(**view_args)  # type: ignore[no-any-return]
           ^^^^^^^^^^^^^^^^^^^^^^^^^^^^^^^^^^^^^^^^^^^^^^^^^^^^^^^^^^^^^^^^^
  File "C:\Users\g_and\Desktop\gihub\learning-documentation\capstone-project\inventory management system(flask)\app\auth.py", line 13, in decorated_function
    return f(*args, **kwargs)
           ^^^^^^^^^^^^^^^^^^
  File "C:\Users\g_and\Desktop\gihub\learning-documentation\capstone-project\inventory management system(flask)\app\items.py", line 14, in add_item
    serial_number = int(data.get('serial_number'))
                    ^^^^^^^^^^^^^^^^^^^^^^^^^^^^^^
ValueError: invalid literal for int() with base 10: 'nono'
2024-06-10 04:35:37,194 [ERROR] app Exception on /item/add [POST]
Traceback (most recent call last):
  File "C:\Users\g_and\AppData\Local\Programs\Python\Python312\Lib\site-packages\flask\app.py", line 1473, in wsgi_app
    response = self.full_dispatch_request()
               ^^^^^^^^^^^^^^^^^^^^^^^^^^^^
  File "C:\Users\g_and\AppData\Local\Programs\Python\Python312\Lib\site-packages\flask\app.py", line 882, in full_dispatch_request
    rv = self.handle_user_exception(e)
         ^^^^^^^^^^^^^^^^^^^^^^^^^^^^^
  File "C:\Users\g_and\AppData\Local\Programs\Python\Python312\Lib\site-packages\flask\app.py", line 880, in full_dispatch_request
    rv = self.dispatch_request()
         ^^^^^^^^^^^^^^^^^^^^^^^
  File "C:\Users\g_and\AppData\Local\Programs\Python\Python312\Lib\site-packages\flask\app.py", line 865, in dispatch_request
    return self.ensure_sync(self.view_functions[rule.endpoint])(**view_args)  # type: ignore[no-any-return]
           ^^^^^^^^^^^^^^^^^^^^^^^^^^^^^^^^^^^^^^^^^^^^^^^^^^^^^^^^^^^^^^^^^
  File "C:\Users\g_and\Desktop\gihub\learning-documentation\capstone-project\inventory management system(flask)\app\auth.py", line 13, in decorated_function
    return f(*args, **kwargs)
           ^^^^^^^^^^^^^^^^^^
  File "C:\Users\g_and\Desktop\gihub\learning-documentation\capstone-project\inventory management system(flask)\app\items.py", line 14, in add_item
    serial_number = int(data.get('serial_number'))
                    ^^^^^^^^^^^^^^^^^^^^^^^^^^^^^^
ValueError: invalid literal for int() with base 10: 'nono'
2024-06-10 04:35:44,251 [ERROR] app.auth Exception (MySQLdb.OperationalError) (1292, "Incorrect date value: '' for column 'date_of_purchase' at row 1")
[SQL: INSERT INTO items (item_name, serial_number, bill_no, date_of_purchase, assigned_to, warranty) VALUES (%s, %s, %s, %s, %s, %s)]
[parameters: ('potaot', 554, 545, '', None, '')]
(Background on this error at: https://sqlalche.me/e/20/e3q8) occurred while adding item 554
Traceback (most recent call last):
  File "C:\Users\g_and\AppData\Local\Programs\Python\Python312\Lib\site-packages\sqlalchemy\engine\base.py", line 1967, in _exec_single_context
    self.dialect.do_execute(
  File "C:\Users\g_and\AppData\Local\Programs\Python\Python312\Lib\site-packages\sqlalchemy\engine\default.py", line 924, in do_execute
    cursor.execute(statement, parameters)
  File "C:\Users\g_and\AppData\Local\Programs\Python\Python312\Lib\site-packages\MySQLdb\cursors.py", line 179, in execute
    res = self._query(mogrified_query)
          ^^^^^^^^^^^^^^^^^^^^^^^^^^^^
  File "C:\Users\g_and\AppData\Local\Programs\Python\Python312\Lib\site-packages\MySQLdb\cursors.py", line 330, in _query
    db.query(q)
  File "C:\Users\g_and\AppData\Local\Programs\Python\Python312\Lib\site-packages\MySQLdb\connections.py", line 261, in query
    _mysql.connection.query(self, query)
MySQLdb.OperationalError: (1292, "Incorrect date value: '' for column 'date_of_purchase' at row 1")

The above exception was the direct cause of the following exception:

Traceback (most recent call last):
  File "C:\Users\g_and\Desktop\gihub\learning-documentation\capstone-project\inventory management system(flask)\app\items.py", line 27, in add_item
    db.session.commit()
  File "C:\Users\g_and\AppData\Local\Programs\Python\Python312\Lib\site-packages\sqlalchemy\orm\scoping.py", line 597, in commit
    return self._proxied.commit()
           ^^^^^^^^^^^^^^^^^^^^^^
  File "C:\Users\g_and\AppData\Local\Programs\Python\Python312\Lib\site-packages\sqlalchemy\orm\session.py", line 2017, in commit
    trans.commit(_to_root=True)
  File "<string>", line 2, in commit
  File "C:\Users\g_and\AppData\Local\Programs\Python\Python312\Lib\site-packages\sqlalchemy\orm\state_changes.py", line 139, in _go
    ret_value = fn(self, *arg, **kw)
                ^^^^^^^^^^^^^^^^^^^^
  File "C:\Users\g_and\AppData\Local\Programs\Python\Python312\Lib\site-packages\sqlalchemy\orm\session.py", line 1302, in commit
    self._prepare_impl()
  File "<string>", line 2, in _prepare_impl
  File "C:\Users\g_and\AppData\Local\Programs\Python\Python312\Lib\site-packages\sqlalchemy\orm\state_changes.py", line 139, in _go
    ret_value = fn(self, *arg, **kw)
                ^^^^^^^^^^^^^^^^^^^^
  File "C:\Users\g_and\AppData\Local\Programs\Python\Python312\Lib\site-packages\sqlalchemy\orm\session.py", line 1277, in _prepare_impl
    self.session.flush()
  File "C:\Users\g_and\AppData\Local\Programs\Python\Python312\Lib\site-packages\sqlalchemy\orm\session.py", line 4341, in flush
    self._flush(objects)
  File "C:\Users\g_and\AppData\Local\Programs\Python\Python312\Lib\site-packages\sqlalchemy\orm\session.py", line 4476, in _flush
    with util.safe_reraise():
  File "C:\Users\g_and\AppData\Local\Programs\Python\Python312\Lib\site-packages\sqlalchemy\util\langhelpers.py", line 146, in __exit__
    raise exc_value.with_traceback(exc_tb)
  File "C:\Users\g_and\AppData\Local\Programs\Python\Python312\Lib\site-packages\sqlalchemy\orm\session.py", line 4437, in _flush
    flush_context.execute()
  File "C:\Users\g_and\AppData\Local\Programs\Python\Python312\Lib\site-packages\sqlalchemy\orm\unitofwork.py", line 466, in execute
    rec.execute(self)
  File "C:\Users\g_and\AppData\Local\Programs\Python\Python312\Lib\site-packages\sqlalchemy\orm\unitofwork.py", line 642, in execute
    util.preloaded.orm_persistence.save_obj(
  File "C:\Users\g_and\AppData\Local\Programs\Python\Python312\Lib\site-packages\sqlalchemy\orm\persistence.py", line 93, in save_obj
    _emit_insert_statements(
  File "C:\Users\g_and\AppData\Local\Programs\Python\Python312\Lib\site-packages\sqlalchemy\orm\persistence.py", line 1233, in _emit_insert_statements
    result = connection.execute(
             ^^^^^^^^^^^^^^^^^^^
  File "C:\Users\g_and\AppData\Local\Programs\Python\Python312\Lib\site-packages\sqlalchemy\engine\base.py", line 1418, in execute
    return meth(
           ^^^^^
  File "C:\Users\g_and\AppData\Local\Programs\Python\Python312\Lib\site-packages\sqlalchemy\sql\elements.py", line 515, in _execute_on_connection
    return connection._execute_clauseelement(
           ^^^^^^^^^^^^^^^^^^^^^^^^^^^^^^^^^^
  File "C:\Users\g_and\AppData\Local\Programs\Python\Python312\Lib\site-packages\sqlalchemy\engine\base.py", line 1640, in _execute_clauseelement
    ret = self._execute_context(
          ^^^^^^^^^^^^^^^^^^^^^^
  File "C:\Users\g_and\AppData\Local\Programs\Python\Python312\Lib\site-packages\sqlalchemy\engine\base.py", line 1846, in _execute_context
    return self._exec_single_context(
           ^^^^^^^^^^^^^^^^^^^^^^^^^^
  File "C:\Users\g_and\AppData\Local\Programs\Python\Python312\Lib\site-packages\sqlalchemy\engine\base.py", line 1986, in _exec_single_context
    self._handle_dbapi_exception(
  File "C:\Users\g_and\AppData\Local\Programs\Python\Python312\Lib\site-packages\sqlalchemy\engine\base.py", line 2353, in _handle_dbapi_exception
    raise sqlalchemy_exception.with_traceback(exc_info[2]) from e
  File "C:\Users\g_and\AppData\Local\Programs\Python\Python312\Lib\site-packages\sqlalchemy\engine\base.py", line 1967, in _exec_single_context
    self.dialect.do_execute(
  File "C:\Users\g_and\AppData\Local\Programs\Python\Python312\Lib\site-packages\sqlalchemy\engine\default.py", line 924, in do_execute
    cursor.execute(statement, parameters)
  File "C:\Users\g_and\AppData\Local\Programs\Python\Python312\Lib\site-packages\MySQLdb\cursors.py", line 179, in execute
    res = self._query(mogrified_query)
          ^^^^^^^^^^^^^^^^^^^^^^^^^^^^
  File "C:\Users\g_and\AppData\Local\Programs\Python\Python312\Lib\site-packages\MySQLdb\cursors.py", line 330, in _query
    db.query(q)
  File "C:\Users\g_and\AppData\Local\Programs\Python\Python312\Lib\site-packages\MySQLdb\connections.py", line 261, in query
    _mysql.connection.query(self, query)
sqlalchemy.exc.OperationalError: (MySQLdb.OperationalError) (1292, "Incorrect date value: '' for column 'date_of_purchase' at row 1")
[SQL: INSERT INTO items (item_name, serial_number, bill_no, date_of_purchase, assigned_to, warranty) VALUES (%s, %s, %s, %s, %s, %s)]
[parameters: ('potaot', 554, 545, '', None, '')]
(Background on this error at: https://sqlalche.me/e/20/e3q8)
2024-06-10 04:38:10,932 [INFO] app.auth Item 12 added by admin admin
